File: documentation/exampledata/Time Sync/250MPa 2Cmin.txt
"Test Method,""3Point_Bending.msm"""
"Sample I. D.,""Sample34.mss"""
"Specimen Number,""2"""

"Time (s),""Load (N)"",""Extension (mm)"",""_COM1 (C)"",""FlexureStress (MPa)"",""FlexureStrain (mm/mm)"""

"0.400,-4.395,-0.003,105.000,-0.330,****"
"0.800,-10.650,-0.007,105.000,-0.799,****"
"1.200,-17.185,-0.011,105.000,-1.289,****"
"1.600,-23.127,-0.015,105.000,-1.735,****"
"2.000,-29.990,-0.019,105.000,-2.249,****"
"2.400,-36.609,-0.023,105.000,-2.746,****"
"2.800,-43.967,-0.027,105.000,-3.298,****"
"3.200,-50.846,-0.031,105.000,-3.813,****"
"3.600,-57.928,-0.035,105.000,-4.345,****"
"4.000,-64.639,-0.039,105.000,-4.848,****"
"4.400,-71.915,-0.043,105.000,-5.394,****"
"4.800,-79.005,-0.047,105.000,-5.925,****"
"5.200,-86.211,-0.051,105.000,-6.466,****"
"5.600,-92.970,-0.055,105.000,-6.973,****"
"6.000,-100.349,-0.059,105.000,-7.526,****"
"6.400,-107.925,-0.063,105.000,-8.094,****"
"6.800,-115.208,-0.067,105.000,-8.641,****"
"7.200,-122.112,-0.071,105.000,-9.158,****"
"7.600,-129.771,-0.075,105.000,-9.733,****"
"8.000,-136.809,-0.079,105.000,-10.261,****"
"8.400,-144.506,-0.083,105.000,-10.838,****"
"8.800,-151.907,-0.087,105.000,-11.393,****"
"9.200,-159.373,-0.091,105.000,-11.953,****"
"9.600,-167.315,-0.095,105.000,-12.549,****"
"10.000,-174.550,-0.099,105.000,-13.091,****"
"10.400,-182.319,-0.103,105.000,-13.674,****"
"10.800,-190.084,-0.107,105.000,-14.256,****"
"11.200,-198.441,-0.111,105.000,-14.883,****"
"11.600,-206.497,-0.115,105.000,-15.487,****"
"12.000,-214.377,-0.119,105.000,-16.078,****"
"12.400,-222.696,-0.123,105.000,-16.702,****"
"12.800,-231.201,-0.127,105.000,-17.340,****"
"13.200,-238.723,-0.131,105.000,-17.904,****"
"13.600,-246.805,-0.135,105.000,-18.510,****"
"14.000,-255.585,-0.139,105.000,-19.169,****"
"14.400,-263.763,-0.143,105.000,-19.782,****"
"14.800,-272.410,-0.147,105.000,-20.431,****"
"15.200,-281.674,-0.151,105.000,-21.126,****"
"15.600,-289.954,-0.155,105.000,-21.747,****"
"16.000,-298.778,-0.159,105.000,-22.408,****"
"16.400,-306.989,-0.163,105.000,-23.024,****"
"16.800,-316.033,-0.167,105.000,-23.702,****"
"17.200,-324.834,-0.171,105.000,-24.363,****"
"17.600,-333.781,-0.175,105.000,-25.034,****"
"18.000,-342.883,-0.179,105.000,-25.716,****"
"18.400,-350.991,-0.182,105.000,-26.324,****"
"18.800,-360.215,-0.186,105.100,-27.016,****"
"19.200,-370.205,-0.190,105.100,-27.765,****"
"19.600,-378.924,-0.194,105.100,-28.419,****"
"20.000,-388.335,-0.198,105.100,-29.125,****"
"20.400,-398.145,-0.203,105.000,-29.861,****"
"20.800,-408.075,-0.207,105.000,-30.606,****"
"21.200,-417.584,-0.211,105.000,-31.319,****"
"21.600,-427.630,-0.215,105.000,-32.072,****"
"22.000,-437.384,-0.219,105.000,-32.804,****"
"22.400,-447.037,-0.223,105.000,-33.528,****"
"22.800,-458.936,-0.227,105.000,-34.420,****"
"23.200,-471.958,-0.231,105.000,-35.397,****"
"23.600,-486.210,-0.235,105.000,-36.466,****"
"24.000,-500.115,-0.239,105.000,-37.509,****"
"24.400,-514.201,-0.243,105.000,-38.565,****"
"24.800,-528.652,-0.247,105.000,-39.649,****"
"25.200,-542.790,-0.251,105.000,-40.709,****"
"25.600,-558.150,-0.255,105.000,-41.861,****"
"26.000,-572.628,-0.259,105.000,-42.947,****"
"26.400,-587.340,-0.263,105.000,-44.050,****"
"26.800,-603.334,-0.267,105.000,-45.250,****"
"27.200,-619.427,-0.271,105.000,-46.457,****"
"27.600,-634.827,-0.275,105.000,-47.612,****"
"28.000,-650.786,-0.279,105.000,-48.809,****"
"28.380,-666.045,-0.282,105.000,-49.953,****"
"29.000,-658.388,-0.280,105.000,-49.379,****"
"29.400,-646.911,-0.282,105.100,-48.518,****"
"29.800,-665.328,-0.287,105.100,-49.900,****"
"30.200,-681.530,-0.289,105.100,-51.115,****"
"30.600,-691.355,-0.287,105.100,-51.852,****"
"31.000,-679.950,-0.283,105.000,-50.996,****"
"31.400,-662.405,-0.279,105.000,-49.680,****"
"31.800,-646.808,-0.279,105.000,-48.511,****"
"32.200,-642.226,-0.282,105.000,-48.167,****"
"32.600,-657.191,-0.285,105.000,-49.289,****"
"33.000,-675.749,-0.289,105.000,-50.681,****"
"33.400,-690.035,-0.288,105.000,-51.753,****"
"33.800,-684.825,-0.284,105.000,-51.362,****"
"34.100,-689.848,-0.288,105.000,-51.739,****"
"34.600,-685.287,-0.288,105.000,-51.397,****"
"35.000,-703.810,-0.292,105.000,-52.786,****"
"35.400,-720.853,-0.296,105.000,-54.064,****"
"35.800,-738.588,-0.300,105.000,-55.394,****"
"36.200,-755.463,-0.304,105.000,-56.660,****"
"36.600,-772.880,-0.308,105.000,-57.966,****"
"37.000,-789.953,-0.312,105.000,-59.246,****"
"37.400,-806.916,-0.316,105.000,-60.519,****"
"37.800,-824.231,-0.320,105.000,-61.817,****"
"38.200,-841.557,-0.324,105.000,-63.117,****"
"38.600,-859.337,-0.328,105.000,-64.450,****"
"39.000,-877.173,-0.332,105.000,-65.788,****"
"39.400,-894.519,-0.336,105.000,-67.089,****"
"39.800,-912.747,-0.340,105.000,-68.456,****"
"40.200,-930.705,-0.344,105.000,-69.803,****"
"40.600,-947.970,-0.348,105.000,-71.098,****"
"41.000,-967.356,-0.352,105.000,-72.552,****"
"41.400,-986.150,-0.356,105.000,-73.961,****"
"41.800,-1004.525,-0.360,105.000,-75.339,****"
"42.200,-1023.104,-0.364,105.000,-76.733,****"
"42.600,-1042.772,-0.368,105.000,-78.208,****"
"43.000,-1062.430,-0.372,105.100,-79.682,****"
"43.400,-1082.299,-0.376,105.100,-81.172,****"
"43.800,-1102.487,-0.380,105.100,-82.687,****"
"44.200,-1122.974,-0.384,105.100,-84.223,****"
"44.600,-1144.177,-0.388,105.100,-85.813,****"
"45.000,-1165.833,-0.392,105.100,-87.437,****"
"45.400,-1187.457,-0.396,105.100,-89.059,****"
"45.800,-1208.628,-0.400,105.100,-90.647,****"
"46.200,-1231.052,-0.404,105.100,-92.329,****"
"46.600,-1252.380,-0.408,105.100,-93.928,****"
"47.000,-1274.408,-0.412,105.100,-95.581,****"
"47.400,-1296.313,-0.416,105.100,-97.223,****"
"47.800,-1318.687,-0.420,105.100,-98.902,****"
"48.010,-1330.334,-0.422,105.100,-99.775,****"
"48.600,-1294.218,-0.418,105.100,-97.066,****"
"49.000,-1310.354,-0.423,105.000,-98.277,****"
"49.400,-1340.118,-0.428,105.000,-100.509,****"
"49.800,-1361.972,-0.425,105.000,-102.148,****"
"50.200,-1335.508,-0.420,105.000,-100.163,****"
"50.600,-1301.783,-0.418,104.900,-97.634,****"
"51.000,-1309.501,-0.423,104.900,-98.213,****"
"51.400,-1364.180,-0.428,104.900,-102.313,****"
"51.800,-1388.513,-0.432,104.900,-104.139,****"
"52.200,-1412.891,-0.436,104.900,-105.967,****"
"52.600,-1436.766,-0.440,104.900,-107.757,****"
"53.000,-1460.938,-0.444,104.900,-109.570,****"
"53.400,-1484.856,-0.448,104.900,-111.364,****"
"53.800,-1509.241,-0.452,104.900,-113.193,****"
"54.200,-1533.645,-0.456,104.900,-115.023,****"
"54.600,-1558.836,-0.460,104.900,-116.913,****"
"55.000,-1582.841,-0.464,104.900,-118.713,****"
"55.400,-1607.334,-0.468,104.900,-120.550,****"
"55.800,-1632.922,-0.472,104.900,-122.469,****"
"56.200,-1657.900,-0.476,104.900,-124.343,****"
"56.600,-1683.305,-0.480,104.900,-126.248,****"
"57.000,-1707.708,-0.484,104.900,-128.078,****"
"57.400,-1733.003,-0.488,104.900,-129.975,****"
"57.800,-1758.691,-0.492,104.900,-131.902,****"
"58.200,-1783.711,-0.496,105.000,-133.778,****"
"58.600,-1809.149,-0.500,105.000,-135.686,****"
"59.000,-1835.477,-0.504,105.000,-137.661,****"
"59.400,-1861.407,-0.508,105.000,-139.605,****"
"59.800,-1887.092,-0.512,105.000,-141.532,****"
"60.200,-1914.191,-0.516,105.000,-143.564,****"
"60.600,-1939.702,-0.520,105.000,-145.478,****"
"61.000,-1966.790,-0.524,104.900,-147.509,****"
"61.400,-1993.364,-0.529,104.900,-149.502,****"
"61.800,-2019.564,-0.532,104.900,-151.467,****"
"62.200,-2046.613,-0.536,104.900,-153.496,****"
"62.600,-2073.119,-0.540,105.000,-155.484,****"
"63.000,-2099.562,-0.544,105.000,-157.467,****"
"63.400,-2127.825,-0.548,105.000,-159.587,****"
"63.800,-2153.668,-0.552,105.000,-161.525,****"
"64.200,-2180.856,-0.556,104.900,-163.564,****"
"64.600,-2208.373,-0.560,104.900,-165.628,****"
"65.000,-2235.354,-0.564,104.900,-167.652,****"
"65.400,-2263.197,-0.568,104.900,-169.740,****"
"65.800,-2290.754,-0.572,104.900,-171.807,****"
"66.200,-2318.360,-0.576,104.900,-173.877,****"
"66.600,-2345.738,-0.580,104.900,-175.930,****"
"67.000,-2372.622,-0.584,104.900,-177.947,****"
"67.400,-2400.666,-0.588,104.900,-180.050,****"
"67.800,-2428.552,-0.592,104.900,-182.141,****"
"68.200,-2456.683,-0.596,104.900,-184.251,****"
"68.600,-2484.750,-0.600,104.800,-186.356,****"
"69.000,-2512.911,-0.604,104.800,-188.468,****"
"69.400,-2540.662,-0.608,104.800,-190.550,****"
"69.800,-2568.971,-0.612,104.800,-192.673,****"
"70.200,-2596.906,-0.616,104.800,-194.768,****"
"70.600,-2625.197,-0.620,104.800,-196.890,****"
"71.000,-2653.744,-0.624,104.800,-199.031,****"
"71.240,-2670.087,-0.627,104.800,-200.256,****"
"71.800,-2634.036,-0.621,104.800,-197.553,****"
"72.200,-2629.949,-0.626,104.800,-197.246,****"
"72.600,-2665.868,-0.630,104.800,-199.940,****"
"73.000,-2695.348,-0.633,104.800,-202.151,****"
"73.400,-2712.662,-0.630,104.800,-203.450,****"
"73.800,-2677.696,-0.625,104.800,-200.827,****"
"74.200,-2645.788,-0.622,104.800,-198.434,****"
"74.600,-2626.122,-0.625,104.700,-196.959,****"
"75.000,-2659.039,-0.630,104.700,-199.428,****"
"75.400,-2690.534,-0.633,104.700,-201.790,****"
"75.800,-2714.249,-0.630,104.700,-203.569,****"
"76.200,-2684.378,-0.626,104.700,-201.328,****"
"76.600,-2650.600,-0.622,104.700,-198.795,****"
"77.000,-2625.932,-0.625,104.700,-196.945,****"
"77.400,-2652.401,-0.629,104.700,-198.930,****"
"77.800,-2683.657,-0.633,104.700,-201.274,****"
"78.200,-2713.067,-0.631,104.700,-203.480,****"
"78.600,-2693.996,-0.627,104.700,-202.050,****"
"79.000,-2657.128,-0.623,104.700,-199.285,****"
"79.400,-2627.311,-0.624,104.700,-197.048,****"
"79.800,-2643.072,-0.628,104.700,-198.230,****"
"80.200,-2681.778,-0.633,104.700,-201.133,****"
"80.600,-2712.000,-0.632,104.700,-203.400,****"
"81.000,-2696.055,-0.628,104.700,-202.204,****"
"81.400,-2658.257,-0.623,104.700,-199.369,****"
"81.800,-2628.239,-0.624,104.700,-197.118,****"
"82.200,-2643.141,-0.628,104.700,-198.236,****"
"82.600,-2682.028,-0.633,104.700,-201.152,****"
"83.000,-2712.510,-0.632,104.700,-203.438,****"
"83.400,-2696.161,-0.628,104.700,-202.212,****"
"83.800,-2659.477,-0.623,104.700,-199.461,****"
"84.200,-2628.840,-0.623,104.700,-197.163,****"
"84.600,-2637.979,-0.627,104.700,-197.848,****"
"85.000,-2666.360,-0.631,104.700,-199.977,****"
"85.400,-2696.337,-0.634,104.700,-202.225,****"
"85.800,-2714.553,-0.630,104.700,-203.591,****"
"86.400,-2692.002,-0.631,104.700,-201.900,****"
"86.800,-2722.725,-0.635,104.700,-204.204,****"
"87.200,-2754.015,-0.639,104.700,-206.551,****"
"87.600,-2783.439,-0.643,104.700,-208.758,****"
"88.000,-2813.268,-0.647,104.700,-210.995,****"
"88.400,-2842.623,-0.651,104.700,-213.197,****"
"88.800,-2870.664,-0.655,104.700,-215.300,****"
"89.200,-2900.937,-0.659,104.700,-217.570,****"
"89.600,-2929.638,-0.663,104.700,-219.723,****"
"90.000,-2958.987,-0.667,104.700,-221.924,****"
"90.400,-2988.221,-0.671,104.700,-224.117,****"
"90.800,-3016.892,-0.675,104.700,-226.267,****"
"91.200,-3046.299,-0.679,104.700,-228.472,****"
"91.600,-3075.220,-0.683,104.700,-230.642,****"
"92.000,-3103.536,-0.687,104.700,-232.765,****"
"92.400,-3132.498,-0.690,104.700,-234.937,****"
"92.800,-3161.850,-0.695,104.700,-237.139,****"
"93.200,-3190.490,-0.698,104.700,-239.287,****"
"93.600,-3220.365,-0.703,104.700,-241.527,****"
"94.000,-3249.316,-0.706,104.700,-243.699,****"
"94.400,-3277.937,-0.710,104.600,-245.845,****"
"94.800,-3308.059,-0.714,104.600,-248.104,****"
"95.160,-3333.127,-0.718,104.600,-249.985,****"
"120.800,-3378.550,-0.721,104.500,-253.391,****"
"146.400,-3333.014,-0.718,104.600,-249.976,****"
"172.000,-3333.202,-0.717,104.700,-249.990,****"
"197.600,-3333.027,-0.716,104.600,-249.977,****"
"223.200,-3332.840,-0.716,103.600,-249.963,****"
"248.800,-3333.126,-0.715,102.800,-249.984,****"
"274.400,-3333.673,-0.715,101.900,-250.026,****"
"300.000,-3332.199,-0.715,101.200,-249.915,****"
"325.600,-3332.503,-0.716,100.300,-249.938,****"
"351.200,-3333.178,-0.716,99.400,-249.988,****"
"376.800,-3332.981,-0.717,98.600,-249.974,****"
"402.400,-3333.090,-0.718,97.600,-249.982,****"
"428.000,-3332.623,-0.719,96.800,-249.947,****"
"453.600,-3333.458,-0.720,95.900,-250.009,****"
"479.200,-3333.312,-0.722,95.100,-249.998,****"
"504.800,-3332.867,-0.723,94.200,-249.965,****"
"530.400,-3332.663,-0.725,93.400,-249.950,****"
"556.000,-3333.227,-0.727,92.500,-249.992,****"
"581.600,-3332.935,-0.729,91.600,-249.970,****"
"607.200,-3333.374,-0.731,90.700,-250.003,****"
"632.800,-3332.908,-0.733,90.000,-249.968,****"
"658.400,-3332.801,-0.736,89.300,-249.960,****"
"684.000,-3333.510,-0.738,88.300,-250.013,****"
"709.600,-3332.944,-0.741,87.500,-249.971,****"
"735.200,-3332.864,-0.744,86.500,-249.965,****"
"760.800,-3332.911,-0.747,85.800,-249.968,****"
"786.400,-3332.843,-0.750,85.000,-249.963,****"
"812.000,-3333.693,-0.753,84.000,-250.027,****"
"837.600,-3333.157,-0.756,82.800,-249.987,****"
"863.200,-3333.064,-0.759,82.100,-249.980,****"
"888.800,-3333.194,-0.763,81.200,-249.990,****"
"914.400,-3332.989,-0.766,80.520,-249.974,****"
"940.000,-3333.398,-0.770,79.600,-250.005,****"
"965.600,-3332.500,-0.774,78.700,-249.938,****"
"991.200,-3332.564,-0.778,78.000,-249.942,****"
"1016.800,-3333.071,-0.781,77.300,-249.980,****"
"1042.400,-3333.199,-0.785,76.400,-249.990,****"
"1068.000,-3332.838,-0.790,75.400,-249.963,****"
"1093.600,-3333.289,-0.793,74.700,-249.997,****"
"1119.200,-3333.233,-0.798,73.800,-249.993,****"
"1144.800,-3334.065,-0.803,72.900,-250.055,****"
"1170.400,-3332.864,-0.807,65.600,-249.965,****"
"1196.000,-3332.976,-0.810,69.000,-249.973,****"
"1221.600,-3332.667,-0.813,73.300,-249.950,****"
"1247.200,-3332.842,-0.816,73.800,-249.963,****"
"1272.800,-3332.820,-0.819,73.500,-249.962,****"
"1298.400,-3332.344,-0.822,73.500,-249.926,****"
"1324.000,-3331.650,-0.826,73.700,-249.874,****"
"1349.600,-3333.274,-0.829,73.600,-249.996,****"
"1375.200,-3332.671,-0.832,73.500,-249.950,****"
"1400.800,-3332.841,-0.835,73.400,-249.963,****"
"1426.400,-3332.923,-0.837,73.400,-249.969,****"
"1452.000,-3332.943,-0.840,73.400,-249.971,****"
"1477.600,-3333.408,-0.843,72.200,-250.006,****"
"1503.200,-3333.022,-0.846,71.600,-249.977,****"
"1528.800,-3332.723,-0.849,71.100,-249.954,****"
"1554.400,-3332.782,-0.853,69.900,-249.959,****"
"1580.000,-3332.972,-0.856,69.400,-249.973,****"
"1605.600,-3333.204,-0.860,68.700,-249.990,****"
"1631.200,-3332.320,-0.864,67.800,-249.924,****"
"1656.800,-3333.332,-0.868,66.800,-250.000,****"
"1682.400,-3333.528,-0.872,66.100,-250.015,****"
"1708.000,-3332.553,-0.876,65.100,-249.942,****"
"1733.600,-3333.307,-0.880,64.300,-249.998,****"
"1759.200,-3332.922,-0.884,63.200,-249.969,****"
"1784.800,-3333.265,-0.889,62.400,-249.995,****"
"1810.400,-3332.691,-0.893,61.400,-249.952,****"
"1836.000,-3332.071,-0.898,60.400,-249.905,****"
"1861.600,-3332.780,-0.903,59.700,-249.959,****"
"1887.200,-3333.120,-0.908,59.200,-249.984,****"
"1912.800,-3332.865,-0.912,57.800,-249.965,****"
"1938.400,-3332.944,-0.918,56.700,-249.971,****"
"1964.000,-3333.594,-0.923,56.500,-250.020,****"
"1989.600,-3332.510,-0.927,55.900,-249.938,****"
"2015.200,-3333.209,-0.933,54.800,-249.991,****"
"2040.800,-3333.300,-0.938,54.100,-249.998,****"
"2066.400,-3332.972,-0.944,52.500,-249.973,****"
"2092.000,-3333.308,-0.949,51.600,-249.998,****"
"2117.600,-3332.515,-0.955,51.400,-249.939,****"
"2143.200,-3332.505,-0.960,49.800,-249.938,****"
"2168.800,-3333.519,-0.966,50.100,-250.014,****"
"2194.400,-3332.371,-0.972,49.000,-249.928,****"
"2220.000,-3332.362,-0.977,48.300,-249.927,****"
"2245.600,-3332.100,-0.983,47.400,-249.908,****"
"2271.200,-3332.699,-0.989,46.600,-249.952,****"
"2296.800,-3332.826,-0.996,44.700,-249.962,****"
"2322.400,-3333.109,-1.002,43.800,-249.983,****"
"2348.000,-3331.259,-1.008,43.700,-249.844,****"
"2373.600,-3332.907,-1.014,42.900,-249.968,****"
"2399.200,-3332.690,-1.022,42.000,-249.952,****"
"2424.800,-3332.965,-1.028,41.500,-249.972,****"
"2450.400,-3332.370,-1.035,39.500,-249.928,****"
"2476.000,-3332.322,-1.042,39.700,-249.924,****"
"2501.600,-3332.540,-1.049,38.100,-249.940,****"
"2527.200,-3332.671,-1.056,37.000,-249.950,****"
"2552.800,-3332.240,-1.063,37.000,-249.918,****"
"2578.400,-3332.726,-1.070,35.800,-249.954,****"
"2604.000,-3331.975,-1.078,35.400,-249.898,****"
"2629.600,-3333.342,-1.086,34.600,-250.001,****"
"2655.200,-3332.666,-1.094,33.100,-249.950,****"
"2680.800,-3332.656,-1.103,32.600,-249.949,****"
"2706.400,-3332.549,-1.111,32.100,-249.941,****"
"2732.000,-3332.648,-1.120,30.800,-249.949,****"
"2757.600,-3332.703,-1.130,29.900,-249.953,****"
"2783.200,-3332.059,-1.139,29.500,-249.904,****"
"2808.800,-3332.745,-1.150,28.500,-249.956,****"
"2834.400,-3332.469,-1.161,27.600,-249.935,****"
"2860.000,-3331.774,-1.172,26.900,-249.883,****"
"2885.600,-3332.252,-1.184,25.900,-249.919,****"
"2911.200,-3332.227,-1.198,25.000,-249.917,****"
"2936.800,-3332.503,-1.214,24.000,-249.938,****"
"2962.400,-3332.493,-1.229,23.300,-249.937,****"
"2988.000,-3332.308,-1.248,22.100,-249.923,****"
"3013.600,-3331.964,-1.263,21.800,-249.897,****"
"3039.200,-3332.646,-1.287,20.800,-249.948,****"
"3064.800,-3332.564,-1.308,19.800,-249.942,****"
"3090.400,-3332.188,-1.330,19.300,-249.914,****"
"3116.000,-3331.800,-1.361,17.700,-249.885,****"
"3141.600,-3332.280,-1.392,17.600,-249.921,****"
"3167.200,-3331.995,-1.427,16.000,-249.900,****"
"3192.800,-3332.387,-1.463,15.500,-249.929,****"
"3218.400,-3331.810,-1.503,14.700,-249.886,****"
"3244.000,-3331.310,-1.548,13.700,-249.848,****"
"3269.600,-3331.554,-1.587,13.100,-249.867,****"
"3295.200,-3331.918,-1.632,12.000,-249.894,****"
"3320.800,-3331.781,-1.674,11.000,-249.884,****"
"3346.400,-3331.192,-1.720,10.100,-249.839,****"
"3372.000,-3330.291,-1.763,10.100,-249.772,****"
"3397.600,-3331.613,-1.811,8.600,-249.871,****"
"3423.200,-3331.447,-1.854,7.900,-249.859,****"
"3448.800,-3331.501,-1.900,6.500,-249.863,****"
"3474.400,-3331.460,-1.943,5.600,-249.859,****"
"3500.000,-3331.340,-1.983,5.700,-249.851,****"
"3525.600,-3330.747,-2.030,4.900,-249.806,****"
"3551.200,-3331.166,-2.079,3.000,-249.837,****"
"3576.800,-3331.528,-2.127,3.200,-249.865,****"
"3602.400,-3330.014,-2.186,1.400,-249.751,****"
"3628.000,-3330.622,-2.244,0.400,-249.797,****"
"3653.600,-3331.339,-2.300,0.500,-249.850,****"
"3679.200,-3330.076,-2.362,-0.400,-249.756,****"
"3704.800,-3329.729,-2.422,-1.800,-249.730,****"
"3730.400,-3330.684,-2.485,-1.900,-249.801,****"
"3756.000,-3329.940,-2.551,-2.800,-249.745,****"
"3781.600,-3330.246,-2.614,-4.100,-249.768,****"
"3807.200,-3330.994,-2.676,-4.500,-249.825,****"
"3832.800,-3330.143,-2.737,-6.200,-249.761,****"
"3858.400,-3331.062,-2.799,-6.200,-249.830,****"
"3884.000,-3330.395,-2.861,-7.100,-249.780,****"
"3909.600,-3329.749,-2.928,-8.500,-249.731,****"
"3935.200,-3329.635,-2.998,-9.800,-249.723,****"
"3960.800,-3330.461,-3.079,-9.700,-249.785,****"
"3986.400,-3329.810,-3.154,-10.500,-249.736,****"
"4012.000,-3330.041,-3.228,-11.700,-249.753,****"
"4037.600,-3331.132,-3.293,-12.000,-249.835,****"
"4063.200,-3328.992,-3.369,-13.400,-249.674,****"
"4088.800,-3329.205,-3.447,-14.300,-249.690,****"
"4114.400,-3329.793,-3.513,-15.100,-249.734,****"
"4140.000,-3331.071,-3.577,-15.600,-249.830,****"
"4165.600,-3329.673,-3.644,-16.400,-249.725,****"
"4191.200,-3329.280,-3.715,-17.900,-249.696,****"
"4216.800,-3330.144,-3.779,-19.100,-249.761,****"
"4242.400,-3330.976,-3.841,-18.900,-249.823,****"
"4268.000,-3330.942,-3.902,-19.800,-249.821,****"
"4293.600,-3330.819,-3.957,-20.700,-249.811,****"
"4319.200,-3330.856,-4.007,-21.700,-249.814,****"
"4344.800,-3330.456,-4.054,-22.800,-249.784,****"
"4370.400,-3330.722,-4.100,-23.300,-249.804,****"
"4396.000,-3331.141,-4.152,-24.800,-249.836,****"
"4421.600,-3331.757,-4.202,-24.900,-249.882,****"
"4447.200,-3331.644,-4.244,-26.000,-249.873,****"
"4472.800,-3330.796,-4.281,-27.100,-249.810,****"
"4498.400,-3331.537,-4.321,-27.600,-249.865,****"
"4524.000,-3331.760,-4.361,-28.500,-249.882,****"
"4549.600,-3331.891,-4.402,-29.900,-249.892,****"
"4575.200,-3331.685,-4.437,-30.700,-249.876,****"
"4600.800,-3331.451,-4.470,-31.100,-249.859,****"
"4626.400,-3331.195,-4.504,-32.300,-249.840,****"
"4652.000,-3330.914,-4.542,-32.900,-249.819,****"
"4677.600,-3331.682,-4.586,-33.700,-249.876,****"
"4703.200,-3332.071,-4.620,-34.300,-249.905,****"
"4728.800,-3331.860,-4.649,-35.300,-249.890,****"
"4754.400,-3331.712,-4.681,-36.000,-249.878,****"
"4780.000,-3331.810,-4.710,-37.000,-249.886,****"
"4805.600,-3331.903,-4.743,-37.900,-249.893,****"
"4831.200,-3331.822,-4.771,-38.600,-249.887,****"
"4856.800,-3332.062,-4.799,-39.500,-249.905,****"
"4882.400,-3332.035,-4.825,-39.800,-249.903,****"
"4908.000,-3332.117,-4.849,-40.000,-249.909,****"
"4933.600,-3332.092,-4.873,-39.600,-249.907,****"
"4959.200,-3331.835,-4.894,-39.600,-249.888,****"
"4984.800,-3332.111,-4.915,-39.800,-249.908,****"
"5010.400,-3332.534,-4.936,-39.600,-249.940,****"
"5036.000,-3331.917,-4.956,-40.100,-249.894,****"
"5061.600,-3331.479,-4.973,-39.900,-249.861,****"
"5087.200,-3332.424,-4.990,-39.600,-249.932,****"
"5112.800,-3332.542,-5.007,-40.100,-249.941,****"
"5138.400,-3332.161,-5.023,-40.400,-249.912,****"
"5164.000,-3332.582,-5.038,-40.200,-249.944,****"
"5189.600,-3332.419,-5.053,-39.700,-249.931,****"
"5215.200,-3332.573,-5.068,-40.200,-249.943,****"
"5240.800,-3332.748,-5.081,-40.200,-249.956,****"
"5266.400,-3332.767,-5.093,-39.800,-249.958,****"
"5292.000,-3332.581,-5.105,-39.700,-249.944,****"
"5317.600,-3332.454,-5.117,-40.200,-249.934,****"
"5343.200,-3332.647,-5.129,-40.400,-249.949,****"
"5368.800,-3332.890,-5.140,-40.300,-249.967,****"
"5394.400,-3332.256,-5.150,-39.900,-249.919,****"
"5420.000,-3333.111,-5.161,-40.100,-249.983,****"
"5445.600,-3332.776,-5.171,-40.000,-249.958,****"
"5471.200,-3332.879,-5.180,-39.800,-249.966,****"
"5496.800,-3333.020,-5.190,-39.900,-249.977,****"
"5522.400,-3332.885,-5.199,-39.800,-249.966,****"
"5548.000,-3332.791,-5.208,-39.800,-249.959,****"
"5573.600,-3332.910,-5.216,-40.000,-249.968,****"
"5599.200,-3332.880,-5.224,-40.100,-249.966,****"
"5624.800,-3333.014,-5.232,-40.000,-249.976,****"
"5650.400,-3333.085,-5.239,-40.000,-249.981,****"
"5676.000,-3332.966,-5.247,-40.100,-249.972,****"
"5701.600,-3332.677,-5.254,-40.100,-249.951,****"
"5727.200,-3332.603,-5.261,-40.000,-249.945,****"
"5752.800,-3332.636,-5.268,-39.800,-249.948,****"
"5778.400,-3332.527,-5.274,-39.400,-249.939,****"
"5804.000,-3333.220,-5.279,-38.500,-249.992,****"
"5829.600,-3333.099,-5.283,-37.800,-249.982,****"
"5855.200,-3332.645,-5.286,-36.900,-249.948,****"
"5880.800,-3332.916,-5.289,-35.900,-249.969,****"
"5906.400,-3332.634,-5.291,-35.100,-249.948,****"
"5932.000,-3332.722,-5.292,-34.400,-249.954,****"
"5957.600,-3333.135,-5.293,-33.600,-249.985,****"
"5983.200,-3333.221,-5.293,-32.700,-249.992,****"
"6008.800,-3333.055,-5.293,-31.800,-249.979,****"
"6034.400,-3333.609,-5.292,-30.900,-250.021,****"
"6060.000,-3332.908,-5.291,-30.200,-249.968,****"
"6085.600,-3332.883,-5.290,-29.200,-249.966,****"
"6111.200,-3333.818,-5.288,-28.400,-250.036,****"
"6136.800,-3332.422,-5.286,-27.400,-249.932,****"
"6162.400,-3332.490,-5.285,-26.700,-249.937,****"
"6188.000,-3333.516,-5.283,-25.800,-250.014,****"
"6213.600,-3332.996,-5.280,-25.000,-249.975,****"
"6239.200,-3332.866,-5.277,-24.000,-249.965,****"
"6264.800,-3333.063,-5.274,-23.200,-249.980,****"
"6290.400,-3333.011,-5.271,-22.400,-249.976,****"
"6316.000,-3333.477,-5.267,-21.500,-250.011,****"
"6341.600,-3333.274,-5.263,-20.700,-249.996,****"
"6367.200,-3333.066,-5.260,-19.800,-249.980,****"
"6392.800,-3333.243,-5.255,-19.100,-249.993,****"
"6418.400,-3333.293,-5.251,-18.400,-249.997,****"
"6444.000,-3333.487,-5.247,-17.700,-250.012,****"
"6469.600,-3333.706,-5.243,-17.000,-250.028,****"
"6495.200,-3332.970,-5.238,-16.300,-249.973,****"
"6520.800,-3333.375,-5.234,-15.500,-250.003,****"
"6546.400,-3333.071,-5.229,-14.800,-249.980,****"
"6572.000,-3332.793,-5.224,-14.000,-249.959,****"
"6597.600,-3333.256,-5.219,-13.200,-249.994,****"
"6623.200,-3333.170,-5.214,-12.300,-249.988,****"
"6648.800,-3333.194,-5.208,-11.500,-249.990,****"
"6674.400,-3333.247,-5.203,-10.600,-249.994,****"
"6700.000,-3333.204,-5.197,-9.700,-249.990,****"
"6725.600,-3333.314,-5.191,-8.900,-249.999,****"
"6751.200,-3333.082,-5.185,-8.000,-249.981,****"
"6776.800,-3333.094,-5.178,-7.200,-249.982,****"
"6802.400,-3333.415,-5.172,-6.300,-250.006,****"
"6828.000,-3333.422,-5.165,-5.500,-250.007,****"
"6853.600,-3333.159,-5.158,-4.600,-249.987,****"
"6879.200,-3333.098,-5.152,-3.800,-249.982,****"
"6904.800,-3333.331,-5.145,-3.000,-250.000,****"
"6930.400,-3333.227,-5.138,-2.100,-249.992,****"
"6956.000,-3333.283,-5.131,-1.200,-249.996,****"
"6981.600,-3333.440,-5.123,0.000,-250.008,****"
"7007.200,-3333.178,-5.116,0.500,-249.988,****"
"7032.800,-3333.046,-5.108,1.300,-249.978,****"
"7058.400,-3333.338,-5.101,2.200,-250.000,****"
"7084.000,-3332.801,-5.093,3.100,-249.960,****"
"7109.600,-3333.469,-5.085,4.000,-250.010,****"
"7135.200,-3333.326,-5.078,4.900,-249.999,****"
"7160.800,-3333.318,-5.070,5.600,-249.999,****"
"7186.400,-3333.246,-5.062,6.500,-249.993,****"
"7212.000,-3333.413,-5.054,7.300,-250.006,****"
"7237.600,-3333.276,-5.047,8.200,-249.996,****"
"7263.200,-3333.422,-5.039,9.100,-250.007,****"
"7288.800,-3333.217,-5.030,9.900,-249.991,****"
"7314.400,-3333.432,-5.022,10.700,-250.007,****"
"7340.000,-3333.247,-5.014,11.600,-249.994,****"
"7365.600,-3333.549,-5.007,12.400,-250.016,****"
"7391.200,-3333.246,-4.999,13.300,-249.993,****"
"7416.800,-3333.309,-4.990,14.200,-249.998,****"
"7442.400,-3333.339,-4.981,15.000,-250.000,****"
"7468.000,-3333.427,-4.971,15.800,-250.007,****"
"7493.600,-3333.169,-4.962,16.700,-249.988,****"
"7519.200,-3333.073,-4.953,17.500,-249.980,****"
"7544.800,-3333.300,-4.944,18.400,-249.998,****"
"7570.400,-3333.287,-4.936,19.300,-249.996,****"
"7596.000,-3333.148,-4.928,20.200,-249.986,****"
"7621.600,-3333.331,-4.920,21.000,-250.000,****"
"7647.200,-3333.406,-4.911,21.900,-250.005,****"
"7672.800,-3333.542,-4.903,22.800,-250.016,****"
"7698.400,-3333.075,-4.894,23.600,-249.981,****"
"7724.000,-3333.605,-4.886,24.500,-250.020,****"
"7749.600,-3333.415,-4.877,25.300,-250.006,****"
"7775.200,-3333.138,-4.868,26.100,-249.985,****"
"7800.800,-3333.389,-4.858,26.900,-250.004,****"
"7826.400,-3333.826,-4.847,27.700,-250.037,****"
"7852.000,-3333.272,-4.836,28.700,-249.995,****"
"7877.600,-3333.502,-4.827,29.600,-250.013,****"
"7903.200,-3333.180,-4.818,30.400,-249.988,****"
"7928.800,-3333.431,-4.808,31.200,-250.007,****"
"7954.400,-3333.519,-4.797,32.100,-250.014,****"
"7980.000,-3333.781,-4.786,32.900,-250.034,****"
"8005.600,-3333.346,-4.775,33.800,-250.001,****"
"8031.200,-3333.284,-4.763,34.700,-249.996,****"
"8056.800,-3333.685,-4.750,35.500,-250.026,****"
"8082.400,-3333.707,-4.737,36.300,-250.028,****"
"8108.000,-3333.587,-4.724,37.200,-250.019,****"
"8133.600,-3333.502,-4.709,38.100,-250.013,****"
"8159.200,-3333.613,-4.694,38.900,-250.021,****"
"8184.800,-3333.714,-4.678,39.700,-250.029,****"
"8210.400,-3333.742,-4.661,40.600,-250.031,****"
"8236.000,-3333.726,-4.643,41.500,-250.029,****"
"8261.600,-3333.554,-4.624,42.300,-250.017,****"
"8287.200,-3333.852,-4.601,43.200,-250.039,****"
"8312.800,-3333.750,-4.577,44.100,-250.031,****"
"8338.400,-3334.127,-4.552,44.900,-250.060,****"
"8364.000,-3334.043,-4.524,45.800,-250.053,****"
"8389.600,-3334.118,-4.494,46.600,-250.059,****"
"8415.200,-3334.524,-4.460,47.400,-250.089,****"
"8440.800,-3334.570,-4.423,48.300,-250.093,****"
"8466.400,-3334.555,-4.382,49.100,-250.092,****"
"8492.000,-3334.709,-4.337,50.000,-250.103,****"
"8517.600,-3335.264,-4.284,50.900,-250.145,****"
"8543.200,-3335.358,-4.224,51.700,-250.152,****"
"8568.800,-3336.005,-4.158,52.600,-250.200,****"
"8594.400,-3335.824,-4.083,53.400,-250.187,****"
"8620.000,-3336.419,-3.998,54.300,-250.231,****"
"8645.600,-3336.993,-3.904,55.100,-250.274,****"
"8671.200,-3336.946,-3.804,56.000,-250.271,****"
"8696.800,-3337.339,-3.697,56.800,-250.300,****"
"8722.400,-3337.123,-3.584,57.700,-250.284,****"
"8748.000,-3338.175,-3.462,58.500,-250.363,****"
"8773.600,-3338.408,-3.328,59.400,-250.381,****"
"8799.200,-3338.275,-3.186,60.300,-250.371,****"
"8824.800,-3339.023,-3.034,61.100,-250.427,****"
"8850.400,-3339.398,-2.867,62.000,-250.455,****"
"8876.000,-3339.622,-2.693,62.800,-250.472,****"
"8901.600,-3340.120,-2.519,63.700,-250.509,****"
"8927.200,-3340.140,-2.346,64.500,-250.510,****"
"8952.800,-3339.301,-2.178,65.400,-250.448,****"
"8978.400,-3338.522,-2.017,66.200,-250.389,****"
"9004.000,-3338.316,-1.877,67.000,-250.374,****"
"9029.600,-3337.103,-1.757,68.000,-250.283,****"
"9055.200,-3336.268,-1.664,68.800,-250.220,****"
"9080.800,-3335.646,-1.591,69.600,-250.173,****"
"9106.400,-3334.907,-1.536,70.500,-250.118,****"
"9132.000,-3334.690,-1.491,71.400,-250.102,****"
"9157.600,-3334.314,-1.455,72.200,-250.074,****"
"9183.200,-3333.992,-1.424,73.000,-250.049,****"
"9208.800,-3333.763,-1.398,73.900,-250.032,****"
"9234.400,-3334.021,-1.375,74.800,-250.052,****"
"9260.000,-3333.791,-1.355,75.600,-250.034,****"
"9285.600,-3333.761,-1.336,76.500,-250.032,****"
"9311.200,-3333.372,-1.319,77.400,-250.003,****"
"9336.800,-3333.504,-1.303,78.200,-250.013,****"
"9362.400,-3333.366,-1.288,79.000,-250.002,****"
"9388.000,-3333.704,-1.274,79.900,-250.028,****"
"9413.600,-3333.269,-1.261,80.800,-249.995,****"
"9439.200,-3333.333,-1.248,81.600,-250.000,****"
"9464.800,-3333.572,-1.235,82.400,-250.018,****"
"9490.400,-3333.191,-1.223,83.300,-249.989,****"
"9516.000,-3333.479,-1.211,84.200,-250.011,****"
"9541.600,-3333.526,-1.200,85.000,-250.014,****"
"9567.200,-3333.777,-1.189,85.800,-250.033,****"
"9592.800,-3333.326,-1.178,86.800,-249.999,****"
"9618.400,-3333.434,-1.167,87.600,-250.008,****"
"9644.000,-3333.461,-1.156,88.400,-250.010,****"
"9669.600,-3330.367,-1.146,89.300,-249.778,****"
"9695.200,-3333.409,-1.136,90.100,-250.006,****"
"9720.800,-3333.023,-1.126,90.900,-249.977,****"
"9746.400,-3333.430,-1.117,91.800,-250.007,****"
"9772.000,-3333.376,-1.107,92.700,-250.003,****"
"9797.600,-3333.583,-1.098,93.500,-250.019,****"
"9823.200,-3333.441,-1.088,94.400,-250.008,****"
"9848.800,-3333.473,-1.079,95.300,-250.010,****"
"9874.400,-3333.412,-1.070,96.100,-250.006,****"
"9900.000,-3333.505,-1.061,97.000,-250.013,****"
"9925.600,-3333.239,-1.052,97.800,-249.993,****"
"9951.200,-3333.613,-1.044,98.700,-250.021,****"
"9976.800,-3333.620,-1.035,99.500,-250.021,****"
"10002.400,-3333.393,-1.027,100.400,-250.004,****"
"10028.000,-3332.829,-1.018,101.200,-249.962,****"
"10053.600,-3333.254,-1.010,102.100,-249.994,****"
"10079.200,-3333.537,-1.002,102.900,-250.015,****"
"10104.800,-3333.149,-0.994,103.800,-249.986,****"
"10130.400,-3333.384,-0.986,104.600,-250.004,****"
"10156.000,-3332.909,-0.978,105.100,-249.968,****"
"10181.600,-3333.303,-0.970,105.200,-249.998,****"
"10207.200,-3333.265,-0.963,105.300,-249.995,****"
"10232.800,-3333.314,-0.956,105.300,-249.999,****"
"10258.400,-3333.263,-0.950,105.300,-249.995,****"
"10284.000,-3333.602,-0.943,105.200,-250.020,****"
"10309.600,-3333.243,-0.937,105.200,-249.993,****"
"10335.200,-3333.233,-0.931,105.200,-249.992,****"
"10360.800,-3333.120,-0.925,105.100,-249.984,****"
"10386.400,-3333.539,-0.920,105.100,-250.015,****"
"10412.000,-3333.276,-0.914,105.100,-249.996,****"
"10437.600,-3333.221,-0.909,105.100,-249.992,****"
"10463.200,-3333.415,-0.904,105.100,-250.006,****"
"10488.800,-3333.501,-0.898,105.000,-250.013,****"
"10514.400,-3332.960,-0.894,105.100,-249.972,****"
"10540.000,-3333.307,-0.889,105.000,-249.998,****"
"10565.600,-3333.500,-0.884,105.000,-250.012,****"
"10591.200,-3333.539,-0.880,105.000,-250.015,****"
"10616.800,-3332.631,-0.875,105.100,-249.947,****"
"10642.400,-3333.369,-0.871,105.000,-250.003,****"
"10668.000,-3333.181,-0.867,105.000,-249.989,****"
"10693.600,-3333.304,-0.863,105.000,-249.998,****"
"10719.200,-3333.200,-0.859,105.000,-249.990,****"
"10744.800,-3333.440,-0.855,105.000,-250.008,****"
"10770.400,-3332.668,-0.851,105.000,-249.950,****"
"10796.000,-3333.244,-0.848,105.100,-249.993,****"
"10821.600,-3332.912,-0.844,105.000,-249.968,****"
"10847.200,-3333.207,-0.840,105.000,-249.991,****"
"10872.800,-3332.795,-0.837,105.000,-249.960,****"
"10898.400,-3332.956,-0.834,105.000,-249.972,****"
"10924.000,-3333.184,-0.831,105.000,-249.989,****"
"10949.600,-3333.235,-0.828,105.000,-249.993,****"
"10975.200,-3333.070,-0.824,105.000,-249.980,****"
"11000.800,-3333.502,-0.822,105.000,-250.013,****"
"11026.400,-3333.369,-0.819,105.000,-250.003,****"
"11052.000,-3333.729,-0.816,105.000,-250.030,****"
"11077.600,-3333.131,-0.813,105.000,-249.985,****"
"11103.200,-3333.111,-0.810,105.000,-249.983,****"
"11128.800,-3332.870,-0.808,105.000,-249.965,****"
"11154.400,-3333.289,-0.805,105.000,-249.997,****"
"11180.000,-3333.405,-0.803,105.000,-250.005,****"
"11205.600,-3333.237,-0.800,105.000,-249.993,****"
"11231.200,-3332.968,-0.798,105.000,-249.973,****"
"11256.800,-3333.031,-0.796,105.000,-249.977,****"
"11282.400,-3333.504,-0.793,105.000,-250.013,****"
"11308.000,-3332.768,-0.791,105.000,-249.958,****"
"11333.600,-3332.967,-0.789,105.000,-249.973,****"
"11359.200,-3332.418,-0.787,105.000,-249.931,****"
"11384.800,-3333.151,-0.785,105.000,-249.986,****"
"11410.400,-3332.556,-0.783,105.100,-249.942,****"
"11436.000,-3332.982,-0.781,105.000,-249.974,****"
"11461.600,-3332.805,-0.779,105.000,-249.960,****"
"11487.200,-3333.747,-0.777,105.000,-250.031,****"
"11512.800,-3332.730,-0.775,105.000,-249.955,****"
"11538.400,-3333.137,-0.774,105.000,-249.985,****"
"11564.000,-3333.116,-0.772,105.000,-249.984,****"
"11589.600,-3332.616,-0.770,105.000,-249.946,****"
"11614.990,-3332.961,-0.769,105.000,-249.972,****"