File: documentation/exampledata/Time Sync/50MPa 2Cmin.txt
"Test Method:,""3Point_Bending.msm"""

"Sample,""Spcmn"",""Width"",""Thickness"",""Peak Load"",""Peak Stress"",""Strain At Break"",""Modulus"",""Stress At Yield"",""Strain At Yield"",""Load At Yield"",""Elongation At Break"",""Elongation at Peak"",""Adjusted Gage Length"",""FlexuralStress"",""FlexuralStrain"""
"I. D.,""No."",""mm"",""mm"",""N"",""MPa"",""mm/mm"",""MPa"",""MPa"",""mm/mm"",""N"",""mm"",""mm"",""mm"",""MPa"",""mm/mm"""

"Sample34.mss,""1"",""40.000"",""5.000"",""-1.761"",""-0.0"",""****"",""****"",""-0.024"",""-0.009"",""-4.836"",""****"",""-0.003"",""3.175"",""-198.98"",""-0.013"""
"Sample34.mss,""2"",""40.000"",""5.000"",""-4.395"",""-0.0"",""****"",""****"",""-3.327"",""-0.090"",""-665.328"",""****"",""-0.003"",""3.175"",""-249.97"",""-0.009"""
"Sample34.mss,""3"",""40.000"",""5.000"",""-17.235"",""-0.1"",""****"",""****"",""-3.328"",""-0.081"",""-665.624"",""****"",""-0.003"",""3.175"",""-49.94"",""-0.005"""


"Test Method,""3Point_Bending.msm"""
"Sample I. D.,""Sample34.mss"""
"Specimen Number,""3"""

"Time (s),""Load (N)"",""Extension (mm)"",""_COM1 (C)"",""FlexureStress (MPa)"",""FlexureStrain (mm/mm)"""

"0.400,-17.235,-0.003,105.000,-1.293,****"
"0.600,-20.825,-0.005,105.000,-1.562,****"
"0.800,-24.024,-0.007,105.000,-1.802,****"
"1.000,-27.716,-0.009,105.000,-2.079,****"
"1.200,-31.062,-0.011,105.000,-2.330,****"
"1.400,-34.696,-0.013,105.000,-2.602,****"
"1.600,-38.342,-0.015,105.000,-2.876,****"
"1.800,-42.125,-0.016,105.000,-3.159,****"
"2.000,-45.438,-0.019,105.000,-3.408,****"
"2.200,-48.970,-0.020,105.000,-3.673,****"
"2.400,-52.488,-0.023,105.000,-3.937,****"
"2.600,-56.256,-0.025,105.000,-4.219,****"
"2.800,-59.832,-0.027,105.000,-4.487,****"
"3.000,-63.380,-0.029,105.000,-4.754,****"
"3.200,-66.826,-0.031,105.000,-5.012,****"
"3.400,-70.521,-0.033,105.000,-5.289,****"
"3.600,-74.231,-0.035,105.000,-5.567,****"
"3.800,-77.812,-0.037,105.000,-5.836,****"
"4.000,-81.457,-0.039,105.000,-6.109,****"
"4.200,-85.342,-0.041,105.000,-6.401,****"
"4.400,-89.481,-0.043,105.000,-6.711,****"
"4.600,-92.900,-0.045,105.000,-6.967,****"
"4.800,-97.163,-0.047,105.000,-7.287,****"
"5.000,-100.620,-0.049,105.000,-7.546,****"
"5.200,-104.638,-0.051,105.000,-7.848,****"
"5.400,-108.131,-0.053,105.000,-8.110,****"
"5.600,-112.110,-0.055,105.000,-8.408,****"
"5.800,-116.067,-0.057,105.000,-8.705,****"
"6.000,-119.548,-0.059,105.000,-8.966,****"
"6.200,-123.486,-0.061,105.000,-9.261,****"
"6.400,-127.056,-0.063,105.000,-9.529,****"
"6.600,-131.465,-0.065,105.000,-9.860,****"
"6.800,-134.927,-0.067,105.000,-10.120,****"
"7.000,-138.816,-0.069,105.000,-10.411,****"
"7.200,-142.973,-0.071,105.000,-10.723,****"
"7.400,-146.482,-0.073,105.000,-10.986,****"
"7.600,-150.470,-0.075,105.000,-11.285,****"
"7.800,-154.562,-0.077,105.000,-11.592,****"
"8.000,-158.315,-0.079,105.000,-11.874,****"
"8.200,-162.294,-0.081,105.000,-12.172,****"
"8.400,-166.133,-0.083,105.000,-12.460,****"
"8.600,-170.167,-0.085,105.000,-12.763,****"
"8.800,-174.423,-0.087,105.000,-13.082,****"
"9.000,-178.782,-0.089,105.000,-13.409,****"
"9.200,-182.819,-0.091,105.000,-13.711,****"
"9.400,-186.400,-0.093,105.000,-13.980,****"
"9.600,-190.390,-0.095,105.000,-14.279,****"
"9.800,-195.480,-0.097,105.000,-14.661,****"
"10.000,-199.062,-0.099,105.000,-14.930,****"
"10.200,-202.997,-0.101,105.000,-15.225,****"
"10.400,-207.565,-0.103,105.000,-15.567,****"
"10.600,-211.590,-0.105,105.000,-15.869,****"
"10.800,-215.384,-0.107,105.000,-16.154,****"
"11.000,-220.268,-0.109,105.000,-16.520,****"
"11.200,-224.355,-0.111,105.000,-16.827,****"
"11.400,-228.755,-0.113,105.000,-17.157,****"
"11.600,-233.245,-0.115,105.000,-17.493,****"
"11.800,-237.280,-0.117,105.000,-17.796,****"
"12.000,-241.214,-0.119,105.000,-18.091,****"
"12.200,-246.002,-0.121,105.000,-18.450,****"
"12.400,-250.435,-0.123,105.000,-18.783,****"
"12.600,-255.204,-0.125,105.000,-19.140,****"
"12.800,-259.278,-0.127,105.000,-19.446,****"
"13.000,-263.623,-0.129,105.000,-19.772,****"
"13.200,-268.064,-0.131,105.000,-20.105,****"
"13.400,-271.706,-0.132,105.000,-20.378,****"
"13.600,-276.807,-0.135,105.000,-20.761,****"
"13.800,-281.094,-0.137,105.000,-21.082,****"
"14.000,-285.522,-0.139,105.000,-21.414,****"
"14.200,-290.158,-0.141,105.000,-21.762,****"
"14.400,-294.551,-0.143,105.000,-22.091,****"
"14.600,-299.062,-0.145,105.000,-22.430,****"
"14.800,-304.129,-0.147,105.000,-22.810,****"
"15.000,-308.454,-0.149,105.000,-23.134,****"
"15.200,-312.488,-0.150,105.000,-23.437,****"
"15.400,-316.870,-0.152,105.000,-23.765,****"
"15.600,-321.772,-0.154,105.000,-24.133,****"
"15.800,-326.227,-0.156,105.000,-24.467,****"
"16.000,-330.405,-0.158,105.000,-24.780,****"
"16.200,-335.272,-0.160,105.000,-25.145,****"
"16.400,-339.758,-0.162,105.000,-25.482,****"
"16.600,-344.023,-0.164,105.000,-25.802,****"
"16.800,-348.439,-0.166,105.000,-26.133,****"
"17.000,-353.516,-0.168,105.000,-26.514,****"
"17.200,-358.059,-0.170,105.000,-26.854,****"
"17.400,-362.545,-0.172,105.000,-27.191,****"
"17.600,-367.591,-0.174,105.000,-27.569,****"
"17.800,-372.046,-0.176,105.000,-27.903,****"
"18.000,-376.564,-0.179,105.000,-28.242,****"
"18.200,-381.511,-0.181,105.000,-28.613,****"
"18.400,-386.207,-0.182,105.000,-28.966,****"
"18.600,-390.746,-0.184,105.000,-29.306,****"
"18.800,-396.009,-0.187,105.000,-29.701,****"
"19.000,-400.681,-0.188,105.000,-30.051,****"
"19.200,-405.883,-0.190,105.000,-30.441,****"
"19.400,-410.702,-0.193,105.000,-30.803,****"
"19.600,-415.253,-0.195,105.000,-31.144,****"
"19.800,-420.281,-0.197,105.000,-31.521,****"
"20.000,-425.884,-0.199,105.000,-31.941,****"
"20.200,-432.098,-0.201,105.000,-32.407,****"
"20.400,-438.429,-0.203,105.000,-32.882,****"
"20.600,-445.794,-0.205,105.000,-33.435,****"
"20.800,-452.089,-0.207,105.000,-33.907,****"
"21.000,-458.536,-0.209,105.000,-34.390,****"
"21.200,-465.499,-0.211,105.000,-34.912,****"
"21.400,-472.726,-0.213,105.000,-35.454,****"
"21.600,-479.401,-0.215,105.000,-35.955,****"
"21.800,-486.087,-0.217,105.000,-36.457,****"
"22.000,-493.355,-0.219,105.000,-37.002,****"
"22.200,-500.679,-0.221,105.000,-37.551,****"
"22.400,-507.840,-0.222,105.000,-38.088,****"
"22.600,-514.769,-0.225,105.000,-38.608,****"
"22.800,-521.718,-0.226,105.000,-39.129,****"
"23.000,-528.997,-0.228,105.000,-39.675,****"
"23.200,-536.277,-0.231,105.000,-40.221,****"
"23.400,-544.270,-0.233,105.000,-40.820,****"
"23.600,-551.257,-0.235,105.000,-41.344,****"
"23.800,-558.513,-0.237,105.000,-41.889,****"
"24.000,-566.458,-0.239,105.000,-42.484,****"
"24.200,-573.421,-0.240,105.000,-43.007,****"
"24.400,-580.907,-0.243,105.000,-43.568,****"
"24.600,-588.760,-0.245,105.000,-44.157,****"
"24.800,-596.736,-0.247,105.000,-44.755,****"
"25.000,-603.634,-0.249,105.000,-45.273,****"
"25.200,-611.489,-0.251,105.000,-45.862,****"
"25.400,-619.130,-0.253,105.000,-46.435,****"
"25.600,-627.205,-0.255,105.000,-47.040,****"
"25.800,-635.181,-0.257,105.000,-47.639,****"
"26.000,-642.909,-0.258,105.000,-48.218,****"
"26.200,-650.710,-0.260,105.000,-48.803,****"
"26.400,-659.001,-0.263,105.000,-49.425,****"
"26.580,-666.026,-0.264,105.000,-49.952,****"
"39.400,-666.109,-0.264,105.000,-49.958,****"
"52.200,-666.156,-0.264,105.000,-49.962,****"
"65.000,-665.733,-0.263,105.000,-49.930,****"
"77.800,-666.309,-0.263,105.000,-49.973,****"
"90.600,-666.276,-0.262,105.000,-49.971,****"
"103.400,-666.375,-0.262,105.000,-49.978,****"
"116.200,-665.811,-0.262,105.000,-49.936,****"
"129.000,-665.708,-0.261,105.000,-49.928,****"
"141.800,-666.553,-0.261,105.000,-49.991,****"
"154.600,-666.049,-0.261,105.000,-49.954,****"
"167.400,-666.046,-0.260,105.000,-49.953,****"
"180.200,-665.972,-0.260,105.000,-49.948,****"
"193.000,-666.279,-0.260,105.000,-49.971,****"
"205.800,-665.982,-0.259,105.000,-49.949,****"
"218.600,-665.488,-0.259,105.000,-49.912,****"
"231.400,-665.814,-0.258,105.000,-49.936,****"
"244.200,-666.112,-0.258,105.000,-49.958,****"
"257.000,-666.441,-0.258,105.000,-49.983,****"
"269.800,-666.296,-0.258,105.000,-49.972,****"
"282.600,-665.633,-0.257,105.000,-49.922,****"
"295.400,-665.624,-0.257,105.000,-49.922,****"
"308.200,-665.912,-0.256,105.000,-49.943,****"
"321.000,-665.820,-0.256,105.000,-49.937,****"
"333.800,-665.750,-0.256,104.900,-49.931,****"
"346.600,-666.238,-0.256,104.600,-49.968,****"
"359.400,-666.143,-0.256,104.300,-49.961,****"
"372.200,-665.991,-0.256,104.000,-49.949,****"
"385.000,-666.213,-0.256,103.600,-49.966,****"
"397.800,-665.726,-0.256,103.200,-49.929,****"
"410.600,-665.843,-0.256,102.800,-49.938,****"
"423.400,-665.823,-0.256,102.400,-49.937,****"
"436.200,-666.216,-0.257,102.000,-49.966,****"
"449.000,-666.061,-0.257,101.500,-49.955,****"
"461.800,-665.925,-0.257,101.100,-49.944,****"
"474.600,-666.332,-0.258,100.700,-49.975,****"
"487.400,-666.143,-0.258,100.300,-49.961,****"
"500.200,-666.106,-0.259,99.900,-49.958,****"
"513.000,-665.778,-0.259,99.500,-49.933,****"
"525.800,-666.120,-0.260,99.000,-49.959,****"
"538.600,-666.082,-0.260,98.700,-49.956,****"
"551.400,-666.115,-0.260,98.200,-49.959,****"
"564.200,-666.380,-0.261,97.800,-49.979,****"
"577.000,-666.052,-0.262,97.400,-49.954,****"
"589.800,-665.851,-0.262,97.000,-49.939,****"
"602.600,-665.963,-0.263,96.600,-49.947,****"
"615.400,-666.122,-0.264,96.100,-49.959,****"
"628.200,-666.302,-0.264,95.700,-49.973,****"
"641.000,-665.867,-0.265,95.200,-49.940,****"
"653.800,-666.119,-0.266,94.800,-49.959,****"
"666.600,-666.203,-0.266,94.300,-49.965,****"
"679.400,-665.839,-0.267,93.900,-49.938,****"
"692.200,-665.692,-0.268,93.300,-49.927,****"
"705.000,-665.869,-0.269,92.900,-49.940,****"
"717.800,-666.247,-0.270,92.300,-49.968,****"
"730.600,-665.896,-0.271,91.800,-49.942,****"
"743.400,-665.782,-0.272,91.300,-49.934,****"
"756.200,-665.615,-0.273,90.700,-49.921,****"
"769.000,-665.687,-0.274,90.200,-49.927,****"
"781.800,-665.930,-0.275,89.600,-49.945,****"
"794.600,-665.746,-0.276,89.100,-49.931,****"
"807.400,-666.085,-0.278,88.500,-49.956,****"
"820.200,-666.076,-0.279,88.100,-49.956,****"
"833.000,-666.240,-0.280,87.600,-49.968,****"
"845.800,-666.055,-0.282,87.200,-49.954,****"
"858.600,-666.160,-0.283,86.800,-49.962,****"
"871.400,-665.789,-0.285,86.300,-49.934,****"
"884.200,-665.959,-0.286,86.000,-49.947,****"
"897.000,-665.572,-0.288,85.500,-49.918,****"
"909.800,-665.898,-0.289,85.200,-49.942,****"
"922.600,-665.723,-0.291,84.700,-49.929,****"
"935.400,-665.750,-0.292,84.300,-49.931,****"
"948.200,-665.765,-0.294,83.800,-49.932,****"
"961.000,-666.037,-0.296,83.300,-49.953,****"
"973.800,-666.069,-0.297,83.000,-49.955,****"
"986.600,-665.976,-0.299,82.600,-49.948,****"
"999.400,-665.914,-0.301,82.100,-49.944,****"
"1012.200,-665.996,-0.302,81.800,-49.950,****"
"1025.000,-665.761,-0.304,81.200,-49.932,****"
"1037.800,-665.869,-0.306,80.800,-49.940,****"
"1050.600,-665.684,-0.308,80.400,-49.926,****"
"1063.400,-666.014,-0.310,80.000,-49.951,****"
"1076.200,-665.848,-0.312,79.500,-49.939,****"
"1089.000,-665.894,-0.314,79.200,-49.942,****"
"1101.800,-665.963,-0.316,78.600,-49.947,****"
"1114.600,-665.908,-0.318,78.400,-49.943,****"
"1127.400,-666.164,-0.320,77.800,-49.962,****"
"1140.200,-665.870,-0.322,77.500,-49.940,****"
"1153.000,-665.430,-0.323,77.000,-49.907,****"
"1165.800,-666.011,-0.326,76.500,-49.951,****"
"1178.600,-665.894,-0.328,76.200,-49.942,****"
"1191.400,-665.893,-0.330,75.600,-49.942,****"
"1204.200,-665.878,-0.332,75.400,-49.941,****"
"1217.000,-665.830,-0.334,74.800,-49.937,****"
"1229.800,-665.728,-0.336,74.500,-49.930,****"
"1242.600,-666.268,-0.338,73.900,-49.970,****"
"1255.400,-665.815,-0.341,73.700,-49.936,****"
"1268.200,-665.994,-0.343,73.100,-49.950,****"
"1281.000,-666.014,-0.345,72.700,-49.951,****"
"1293.800,-665.806,-0.347,72.400,-49.935,****"
"1306.600,-666.194,-0.350,71.900,-49.965,****"
"1319.400,-665.860,-0.352,71.400,-49.939,****"
"1332.200,-665.925,-0.354,71.100,-49.944,****"
"1345.000,-665.839,-0.356,70.600,-49.938,****"
"1357.800,-666.210,-0.359,70.100,-49.966,****"
"1370.600,-665.871,-0.361,69.800,-49.940,****"
"1383.400,-665.937,-0.363,69.300,-49.945,****"
"1396.200,-666.082,-0.366,69.000,-49.956,****"
"1409.000,-665.822,-0.368,68.300,-49.937,****"
"1421.800,-665.579,-0.370,68.100,-49.918,****"
"1434.600,-665.952,-0.373,67.500,-49.946,****"
"1447.400,-665.586,-0.375,67.100,-49.919,****"
"1460.200,-666.112,-0.378,66.600,-49.958,****"
"1473.000,-665.832,-0.380,66.400,-49.937,****"
"1485.800,-665.869,-0.383,65.800,-49.940,****"
"1498.600,-665.974,-0.385,65.600,-49.948,****"
"1511.400,-665.874,-0.388,65.000,-49.941,****"
"1524.200,-665.551,-0.390,64.700,-49.916,****"
"1537.000,-666.126,-0.393,64.000,-49.959,****"
"1549.800,-666.132,-0.396,63.900,-49.960,****"
"1562.600,-665.444,-0.398,63.300,-49.908,****"
"1575.400,-666.057,-0.401,62.800,-49.954,****"
"1588.200,-665.813,-0.404,62.600,-49.936,****"
"1601.000,-665.754,-0.406,62.100,-49.932,****"
"1613.800,-665.658,-0.409,61.600,-49.924,****"
"1626.600,-665.648,-0.411,61.300,-49.924,****"
"1639.400,-665.884,-0.414,60.800,-49.941,****"
"1652.200,-665.439,-0.417,60.300,-49.908,****"
"1665.000,-666.117,-0.419,60.000,-49.959,****"
"1677.800,-665.794,-0.422,59.500,-49.935,****"
"1690.600,-665.522,-0.425,59.000,-49.914,****"
"1703.400,-665.863,-0.428,58.700,-49.940,****"
"1716.200,-665.949,-0.430,58.200,-49.946,****"
"1729.000,-665.808,-0.433,57.900,-49.936,****"
"1741.800,-665.579,-0.436,57.400,-49.918,****"
"1754.600,-665.731,-0.439,57.000,-49.930,****"
"1767.400,-666.004,-0.442,56.600,-49.950,****"
"1780.200,-665.895,-0.445,56.100,-49.942,****"
"1793.000,-665.748,-0.448,55.600,-49.931,****"
"1805.800,-666.248,-0.451,55.200,-49.969,****"
"1818.600,-665.767,-0.453,54.800,-49.933,****"
"1831.400,-665.759,-0.456,54.300,-49.932,****"
"1844.200,-665.772,-0.460,54.100,-49.933,****"
"1857.000,-666.269,-0.462,53.400,-49.970,****"
"1869.800,-665.981,-0.465,53.100,-49.949,****"
"1882.600,-665.547,-0.468,52.700,-49.916,****"
"1895.400,-665.982,-0.471,52.300,-49.949,****"
"1908.200,-665.787,-0.474,51.800,-49.934,****"
"1921.000,-665.427,-0.477,51.300,-49.907,****"
"1933.800,-665.833,-0.480,50.900,-49.937,****"
"1946.600,-665.628,-0.483,50.500,-49.922,****"
"1959.400,-665.791,-0.486,50.200,-49.934,****"
"1972.200,-665.722,-0.489,49.600,-49.929,****"
"1985.000,-665.441,-0.492,49.000,-49.908,****"
"1997.800,-665.956,-0.495,48.900,-49.947,****"
"2010.600,-665.892,-0.498,48.200,-49.942,****"
"2023.400,-665.853,-0.501,48.000,-49.939,****"
"2036.200,-665.562,-0.504,47.500,-49.917,****"
"2049.000,-665.750,-0.507,47.200,-49.931,****"
"2061.800,-665.847,-0.511,46.500,-49.939,****"
"2074.600,-665.529,-0.514,46.400,-49.915,****"
"2087.400,-665.817,-0.517,45.800,-49.936,****"
"2100.200,-666.106,-0.520,45.500,-49.958,****"
"2113.000,-665.812,-0.523,44.900,-49.936,****"
"2125.800,-665.477,-0.526,44.800,-49.911,****"
"2138.600,-665.648,-0.529,43.900,-49.924,****"
"2151.400,-665.791,-0.532,43.800,-49.934,****"
"2164.200,-665.739,-0.536,43.200,-49.930,****"
"2177.000,-665.974,-0.539,42.800,-49.948,****"
"2189.800,-665.863,-0.542,42.600,-49.940,****"
"2202.600,-665.961,-0.546,41.600,-49.947,****"
"2215.400,-665.695,-0.549,41.700,-49.927,****"
"2228.200,-665.964,-0.552,41.200,-49.947,****"
"2241.000,-665.634,-0.555,40.600,-49.923,****"
"2253.800,-665.825,-0.559,40.200,-49.937,****"
"2266.600,-665.576,-0.562,40.100,-49.918,****"
"2279.400,-665.834,-0.565,39.000,-49.938,****"
"2292.200,-665.725,-0.569,38.900,-49.929,****"
"2305.000,-665.913,-0.572,38.800,-49.943,****"
"2317.800,-665.342,-0.575,38.400,-49.901,****"
"2330.600,-665.630,-0.579,37.800,-49.922,****"
"2343.400,-665.813,-0.582,37.300,-49.936,****"
"2356.200,-665.756,-0.585,37.000,-49.932,****"
"2369.000,-665.783,-0.589,36.400,-49.934,****"
"2381.800,-665.873,-0.592,36.200,-49.940,****"
"2394.600,-665.678,-0.595,35.600,-49.926,****"
"2407.400,-665.911,-0.599,34.900,-49.943,****"
"2420.200,-666.001,-0.603,34.900,-49.950,****"
"2433.000,-665.792,-0.606,34.300,-49.934,****"
"2445.800,-665.625,-0.610,33.900,-49.922,****"
"2458.600,-665.757,-0.614,33.500,-49.932,****"
"2471.400,-665.925,-0.617,32.600,-49.944,****"
"2484.200,-665.956,-0.621,32.800,-49.947,****"
"2497.000,-665.708,-0.624,32.200,-49.928,****"
"2509.800,-665.644,-0.628,31.800,-49.923,****"
"2522.600,-665.648,-0.632,31.400,-49.924,****"
"2535.400,-665.832,-0.635,30.800,-49.937,****"
"2548.200,-665.844,-0.639,30.600,-49.938,****"
"2561.000,-665.758,-0.643,30.100,-49.932,****"
"2573.800,-665.503,-0.647,29.700,-49.913,****"
"2586.600,-665.969,-0.651,29.200,-49.948,****"
"2599.400,-665.393,-0.655,28.700,-49.904,****"
"2612.200,-665.829,-0.659,28.500,-49.937,****"
"2625.000,-665.586,-0.664,28.100,-49.919,****"
"2637.800,-665.724,-0.668,27.400,-49.929,****"
"2650.600,-665.481,-0.673,26.900,-49.911,****"
"2663.400,-665.427,-0.677,26.800,-49.907,****"
"2676.200,-665.757,-0.681,26.500,-49.932,****"
"2689.000,-665.518,-0.686,26.100,-49.914,****"
"2701.800,-665.654,-0.691,25.200,-49.924,****"
"2714.600,-665.555,-0.696,25.000,-49.917,****"
"2727.400,-665.867,-0.701,24.500,-49.940,****"
"2740.200,-665.513,-0.706,24.300,-49.913,****"
"2753.000,-665.656,-0.711,23.400,-49.924,****"
"2765.800,-665.668,-0.716,23.400,-49.925,****"
"2778.600,-665.783,-0.721,22.800,-49.934,****"
"2791.400,-665.342,-0.727,22.400,-49.901,****"
"2804.200,-665.230,-0.732,22.200,-49.892,****"
"2817.000,-665.705,-0.738,21.600,-49.928,****"
"2829.800,-665.414,-0.744,21.000,-49.906,****"
"2842.600,-665.230,-0.750,20.600,-49.892,****"
"2855.400,-665.557,-0.756,20.500,-49.917,****"
"2868.200,-665.977,-0.762,20.000,-49.948,****"
"2881.000,-664.866,-0.769,19.500,-49.865,****"
"2893.800,-665.683,-0.775,19.000,-49.926,****"
"2906.600,-665.457,-0.783,18.300,-49.909,****"
"2919.400,-665.534,-0.790,18.400,-49.915,****"
"2932.200,-665.697,-0.797,17.800,-49.927,****"
"2945.000,-665.460,-0.805,17.500,-49.909,****"
"2957.800,-665.416,-0.812,16.900,-49.906,****"
"2970.600,-665.329,-0.822,16.100,-49.900,****"
"2983.400,-665.202,-0.829,16.200,-49.890,****"
"2996.200,-665.213,-0.836,15.700,-49.891,****"
"3009.000,-665.277,-0.846,15.100,-49.896,****"
"3021.800,-664.836,-0.855,14.800,-49.863,****"
"3034.600,-665.358,-0.865,14.100,-49.902,****"
"3047.400,-665.158,-0.875,14.100,-49.887,****"
"3060.200,-665.279,-0.884,13.500,-49.896,****"
"3073.000,-665.228,-0.896,13.200,-49.892,****"
"3085.800,-665.278,-0.906,12.700,-49.896,****"
"3098.600,-665.064,-0.917,12.200,-49.880,****"
"3111.400,-665.371,-0.927,11.800,-49.903,****"
"3124.200,-665.054,-0.938,11.400,-49.879,****"
"3137.000,-664.938,-0.950,10.600,-49.870,****"
"3149.800,-665.220,-0.961,10.600,-49.892,****"
"3162.600,-665.340,-0.973,10.000,-49.900,****"
"3175.400,-665.038,-0.983,9.600,-49.878,****"
"3188.200,-665.213,-0.993,9.200,-49.891,****"
"3201.000,-665.082,-1.003,8.900,-49.881,****"
"3213.800,-665.008,-1.013,8.400,-49.876,****"
"3226.600,-665.060,-1.022,7.900,-49.879,****"
"3239.400,-665.558,-1.032,7.400,-49.917,****"
"3252.200,-665.476,-1.040,7.000,-49.911,****"
"3265.000,-665.526,-1.048,6.600,-49.914,****"
"3277.800,-665.194,-1.057,6.200,-49.890,****"
"3290.600,-665.296,-1.065,6.000,-49.897,****"
"3303.400,-665.293,-1.073,5.400,-49.897,****"
"3316.200,-665.527,-1.081,5.100,-49.915,****"
"3329.000,-665.549,-1.088,4.600,-49.916,****"
"3341.800,-665.521,-1.096,3.900,-49.914,****"
"3354.600,-665.376,-1.103,3.600,-49.903,****"
"3367.400,-665.384,-1.111,3.200,-49.904,****"
"3380.200,-665.243,-1.118,2.800,-49.893,****"
"3393.000,-665.295,-1.125,2.400,-49.897,****"
"3405.800,-665.065,-1.132,1.900,-49.880,****"
"3418.600,-665.271,-1.139,1.800,-49.895,****"
"3431.400,-665.606,-1.147,0.800,-49.920,****"
"3444.200,-665.489,-1.154,0.800,-49.912,****"
"3457.000,-665.701,-1.161,0.100,-49.928,****"
"3469.800,-665.415,-1.168,-0.200,-49.906,****"
"3482.600,-665.755,-1.176,-0.500,-49.932,****"
"3495.400,-665.166,-1.183,-1.100,-49.887,****"
"3508.200,-665.532,-1.190,0.000,-49.915,****"
"3521.000,-665.392,-1.198,-2.000,-49.904,****"
"3533.800,-665.248,-1.205,-2.100,-49.894,****"
"3546.600,-665.576,-1.213,-2.900,-49.918,****"
"3559.400,-665.857,-1.219,-2.900,-49.939,****"
"3572.200,-665.697,-1.227,-3.700,-49.927,****"
"3585.000,-665.323,-1.234,0.000,-49.899,****"
"3597.800,-665.455,-1.241,-4.700,-49.909,****"
"3610.600,-665.440,-1.248,-4.600,-49.908,****"
"3623.400,-665.456,-1.256,-5.500,-49.909,****"
"3636.200,-665.440,-1.264,-5.500,-49.908,****"
"3649.000,-665.236,-1.271,-5.900,-49.893,****"
"3661.800,-665.518,-1.279,-6.500,-49.914,****"
"3674.600,-665.346,-1.286,-6.800,-49.901,****"
"3687.400,-665.254,-1.293,-7.300,-49.894,****"
"3700.200,-665.450,-1.300,-7.800,-49.909,****"
"3713.000,-665.428,-1.307,-8.100,-49.907,****"
"3725.800,-665.349,-1.315,-8.400,-49.901,****"
"3738.600,-665.587,-1.322,-8.900,-49.919,****"
"3751.400,-665.289,-1.330,-9.400,-49.897,****"
"3764.200,-665.478,-1.338,-9.700,-49.911,****"
"3777.000,-665.343,-1.347,-10.300,-49.901,****"
"3789.800,-665.399,-1.355,-10.700,-49.905,****"
"3802.600,-665.336,-1.363,-11.300,-49.900,****"
"3815.400,-665.251,-1.370,-11.600,-49.894,****"
"3828.200,-665.313,-1.379,-12.300,-49.898,****"
"3841.000,-665.234,-1.387,-12.600,-49.893,****"
"3853.800,-665.837,-1.396,-13.100,-49.938,****"
"3866.600,-665.232,-1.404,-13.400,-49.892,****"
"3879.400,-665.535,-1.411,-13.800,-49.915,****"
"3892.200,-665.230,-1.419,-14.100,-49.892,****"
"3905.000,-665.574,-1.426,-14.800,-49.918,****"
"3917.800,-665.372,-1.434,-15.200,-49.903,****"
"3930.600,-665.495,-1.442,-15.600,-49.912,****"
"3943.400,-665.407,-1.450,-15.800,-49.906,****"
"3956.200,-665.420,-1.458,-16.200,-49.907,****"
"3969.000,-665.274,-1.466,-16.600,-49.896,****"
"3981.800,-665.421,-1.473,-17.000,-49.907,****"
"3994.600,-665.928,-1.480,-17.400,-49.945,****"
"4007.400,-665.342,-1.487,-17.900,-49.901,****"
"4020.200,-665.187,-1.493,-18.300,-49.889,****"
"4033.000,-665.578,-1.500,-18.700,-49.918,****"
"4045.800,-665.732,-1.507,-19.200,-49.930,****"
"4058.600,-665.401,-1.514,-20.000,-49.905,****"
"4071.400,-665.176,-1.521,-20.100,-49.888,****"
"4084.200,-665.540,-1.529,-20.900,-49.916,****"
"4097.000,-665.687,-1.535,-20.800,-49.927,****"
"4109.800,-665.183,-1.543,-21.500,-49.889,****"
"4122.600,-665.345,-1.551,-21.700,-49.901,****"
"4135.400,-665.325,-1.559,-22.500,-49.899,****"
"4148.200,-665.468,-1.566,-22.900,-49.910,****"
"4161.000,-665.601,-1.572,-23.200,-49.920,****"
"4173.800,-665.466,-1.578,-23.500,-49.910,****"
"4186.600,-665.244,-1.587,-24.200,-49.893,****"
"4199.400,-665.347,-1.595,-24.400,-49.901,****"
"4212.200,-665.153,-1.604,-25.100,-49.887,****"
"4225.000,-665.416,-1.612,-25.200,-49.906,****"
"4237.800,-665.382,-1.622,-25.800,-49.904,****"
"4250.600,-665.131,-1.631,-26.000,-49.885,****"
"4263.400,-665.465,-1.640,-26.700,-49.910,****"
"4276.200,-665.465,-1.648,-26.900,-49.910,****"
"4289.000,-665.236,-1.656,-27.600,-49.893,****"
"4301.800,-665.243,-1.664,-27.800,-49.893,****"
"4314.600,-665.265,-1.672,-28.400,-49.895,****"
"4327.400,-665.313,-1.679,-29.000,-49.898,****"
"4340.200,-665.387,-1.685,-28.700,-49.904,****"
"4353.000,-665.632,-1.692,-29.400,-49.922,****"
"4365.800,-665.582,-1.699,-30.300,-49.919,****"
"4378.600,-665.320,-1.706,-30.200,-49.899,****"
"4391.400,-665.051,-1.713,-31.000,-49.879,****"
"4404.200,-665.221,-1.723,-31.200,-49.892,****"
"4417.000,-665.494,-1.732,-31.900,-49.912,****"
"4429.800,-665.423,-1.739,-31.800,-49.907,****"
"4442.600,-665.540,-1.748,-32.400,-49.915,****"
"4455.400,-665.702,-1.756,-32.800,-49.928,****"
"4468.200,-665.576,-1.763,-33.100,-49.918,****"
"4481.000,-665.447,-1.772,-33.800,-49.909,****"
"4493.800,-665.320,-1.779,-34.400,-49.899,****"
"4506.600,-665.529,-1.787,-34.700,-49.915,****"
"4519.400,-665.216,-1.795,-35.300,-49.891,****"
"4532.200,-665.552,-1.802,-35.600,-49.916,****"
"4545.000,-665.441,-1.809,-36.200,-49.908,****"
"4557.800,-665.488,-1.815,-36.100,-49.912,****"
"4570.600,-665.349,-1.824,-36.900,-49.901,****"
"4583.400,-665.360,-1.831,-37.000,-49.902,****"
"4596.200,-665.290,-1.839,-37.600,-49.897,****"
"4609.000,-664.950,-1.848,-37.900,-49.871,****"
"4621.800,-665.218,-1.857,-38.300,-49.891,****"
"4634.600,-665.510,-1.864,-38.700,-49.913,****"
"4647.400,-665.442,-1.872,-39.400,-49.908,****"
"4660.200,-664.999,-1.880,-39.900,-49.875,****"
"4673.000,-665.496,-1.888,-40.000,-49.912,****"
"4685.800,-665.418,-1.895,-40.100,-49.906,****"
"4698.600,-665.604,-1.902,-39.700,-49.920,****"
"4711.400,-665.568,-1.908,-39.900,-49.918,****"
"4724.200,-665.627,-1.915,-39.600,-49.922,****"
"4737.000,-665.743,-1.921,-39.800,-49.931,****"
"4749.800,-665.431,-1.927,-39.700,-49.907,****"
"4762.600,-665.490,-1.933,-39.700,-49.912,****"
"4775.400,-665.440,-1.939,-39.900,-49.908,****"
"4788.200,-665.651,-1.945,-39.740,-49.924,****"
"4801.000,-665.451,-1.951,-40.000,-49.909,****"
"4813.800,-665.290,-1.957,-40.300,-49.897,****"
"4826.600,-665.326,-1.963,-39.800,-49.899,****"
"4839.400,-665.328,-1.968,-39.800,-49.900,****"
"4852.200,-665.493,-1.974,-39.800,-49.912,****"
"4865.000,-665.554,-1.980,-40.200,-49.917,****"
"4877.800,-665.643,-1.986,-39.900,-49.923,****"
"4890.600,-665.283,-1.992,-40.000,-49.896,****"
"4903.400,-665.499,-1.997,-39.800,-49.912,****"
"4916.200,-665.532,-2.002,-39.800,-49.915,****"
"4929.000,-665.414,-2.007,-40.300,-49.906,****"
"4941.800,-665.645,-2.012,-39.900,-49.923,****"
"4954.600,-665.501,-2.017,-40.100,-49.913,****"
"4967.400,-665.437,-2.022,-39.700,-49.908,****"
"4980.200,-665.168,-2.026,-39.800,-49.888,****"
"4993.000,-665.756,-2.032,-40.100,-49.932,****"
"5005.800,-665.462,-2.036,-39.900,-49.910,****"
"5018.600,-665.683,-2.041,-39.700,-49.926,****"
"5031.400,-665.724,-2.045,-39.800,-49.929,****"
"5044.200,-665.495,-2.050,-40.200,-49.912,****"
"5057.000,-665.728,-2.054,-39.900,-49.930,****"
"5069.800,-665.886,-2.059,-40.200,-49.941,****"
"5082.600,-665.826,-2.063,-39.800,-49.937,****"
"5095.400,-666.146,-2.067,-39.800,-49.961,****"
"5108.200,-665.900,-2.071,-39.900,-49.943,****"
"5121.000,-665.632,-2.075,-39.900,-49.922,****"
"5133.800,-665.800,-2.079,-40.000,-49.935,****"
"5146.600,-665.854,-2.083,-39.700,-49.939,****"
"5159.400,-665.570,-2.087,-40.200,-49.918,****"
"5172.200,-665.631,-2.091,-40.100,-49.922,****"
"5185.000,-665.598,-2.095,-40.200,-49.920,****"
"5197.800,-665.604,-2.099,-40.000,-49.920,****"
"5210.600,-665.555,-2.102,-40.000,-49.917,****"
"5223.400,-665.967,-2.106,-40.000,-49.948,****"
"5236.200,-665.856,-2.110,-39.900,-49.939,****"
"5249.000,-665.821,-2.113,-40.100,-49.937,****"
"5261.800,-666.127,-2.117,-40.000,-49.960,****"
"5274.600,-665.723,-2.120,-39.800,-49.929,****"
"5287.400,-665.799,-2.124,-40.000,-49.935,****"
"5300.200,-665.557,-2.127,-40.300,-49.917,****"
"5313.000,-665.723,-2.130,-39.900,-49.929,****"
"5325.800,-665.523,-2.134,-40.300,-49.914,****"
"5338.600,-665.906,-2.137,-40.100,-49.943,****"
"5351.400,-665.796,-2.140,-39.700,-49.935,****"
"5364.200,-665.598,-2.143,-40.100,-49.920,****"
"5377.000,-665.859,-2.146,-39.800,-49.939,****"
"5389.800,-665.751,-2.149,-40.100,-49.931,****"
"5402.600,-666.014,-2.152,-40.000,-49.951,****"
"5415.400,-665.307,-2.155,-40.000,-49.898,****"
"5428.200,-665.839,-2.158,-39.800,-49.938,****"
"5441.000,-665.761,-2.161,-40.200,-49.932,****"
"5453.800,-665.849,-2.164,-40.000,-49.939,****"
"5466.600,-665.761,-2.167,-40.100,-49.932,****"
"5479.400,-666.056,-2.169,-39.800,-49.954,****"
"5492.200,-665.908,-2.172,-39.800,-49.943,****"
"5505.000,-665.664,-2.175,-39.800,-49.925,****"
"5517.800,-666.183,-2.178,-40.000,-49.964,****"
"5530.600,-665.805,-2.180,-39.900,-49.935,****"
"5543.400,-665.771,-2.183,-40.200,-49.933,****"
"5556.200,-666.103,-2.185,-39.800,-49.958,****"
"5569.000,-666.066,-2.188,-40.000,-49.955,****"
"5581.800,-665.581,-2.190,-39.300,-49.919,****"
"5594.600,-665.853,-2.192,-38.800,-49.939,****"
"5607.400,-665.701,-2.194,-38.500,-49.928,****"
"5620.200,-665.601,-2.196,-38.300,-49.920,****"
"5633.000,-665.891,-2.197,-37.600,-49.942,****"
"5645.800,-666.507,-2.198,-37.100,-49.988,****"
"5658.600,-665.557,-2.200,-36.800,-49.917,****"
"5671.400,-666.070,-2.201,-36.300,-49.955,****"
"5684.200,-666.078,-2.202,-35.900,-49.956,****"
"5697.000,-666.478,-2.203,-35.600,-49.986,****"
"5709.800,-666.067,-2.203,-35.000,-49.955,****"
"5722.600,-665.982,-2.204,-34.700,-49.949,****"
"5735.400,-665.756,-2.204,-34.200,-49.932,****"
"5748.200,-666.253,-2.205,-33.800,-49.969,****"
"5761.000,-665.623,-2.205,-33.300,-49.922,****"
"5773.800,-665.828,-2.205,-33.000,-49.937,****"
"5786.600,-665.713,-2.205,-32.500,-49.928,****"
"5799.400,-666.103,-2.206,-32.200,-49.958,****"
"5812.200,-665.714,-2.206,-31.700,-49.929,****"
"5825.000,-665.723,-2.205,-31.200,-49.929,****"
"5837.800,-666.240,-2.205,-30.900,-49.968,****"
"5850.600,-666.024,-2.205,-30.400,-49.952,****"
"5863.400,-666.399,-2.205,-30.000,-49.980,****"
"5876.200,-666.100,-2.204,-29.600,-49.957,****"
"5889.000,-666.039,-2.204,-29.200,-49.953,****"
"5901.800,-665.774,-2.203,-28.700,-49.933,****"
"5914.600,-666.102,-2.203,-28.300,-49.958,****"
"5927.400,-666.103,-2.202,-27.900,-49.958,****"
"5940.200,-665.846,-2.202,-27.400,-49.938,****"
"5953.000,-666.234,-2.201,-27.100,-49.968,****"
"5965.800,-665.811,-2.200,-26.600,-49.936,****"
"5978.600,-665.814,-2.200,-26.200,-49.936,****"
"5991.400,-665.921,-2.199,-25.800,-49.944,****"
"6004.200,-666.528,-2.198,-25.300,-49.990,****"
"6017.000,-665.975,-2.197,-24.900,-49.948,****"
"6029.800,-666.306,-2.196,-24.400,-49.973,****"
"6042.600,-665.867,-2.195,-24.000,-49.940,****"
"6055.400,-666.164,-2.194,-23.600,-49.962,****"
"6068.200,-665.947,-2.193,-23.200,-49.946,****"
"6081.000,-665.732,-2.191,-22.800,-49.930,****"
"6093.800,-666.249,-2.190,-22.400,-49.969,****"
"6106.600,-665.962,-2.189,-22.000,-49.947,****"
"6119.400,-666.611,-2.188,-21.600,-49.996,****"
"6132.200,-666.187,-2.186,-21.200,-49.964,****"
"6145.000,-666.295,-2.185,-20.900,-49.972,****"
"6157.800,-666.005,-2.184,-20.600,-49.950,****"
"6170.600,-665.626,-2.182,-20.200,-49.922,****"
"6183.400,-666.332,-2.181,-19.900,-49.975,****"
"6196.200,-666.460,-2.180,-19.500,-49.984,****"
"6209.000,-665.719,-2.178,-19.200,-49.929,****"
"6221.800,-666.065,-2.177,-18.800,-49.955,****"
"6234.600,-665.938,-2.175,-18.400,-49.945,****"
"6247.400,-666.392,-2.174,-18.000,-49.979,****"
"6260.200,-665.858,-2.172,-17.700,-49.939,****"
"6273.000,-665.933,-2.170,-17.200,-49.945,****"
"6285.800,-666.336,-2.169,-16.900,-49.975,****"
"6298.600,-665.867,-2.167,-16.400,-49.940,****"
"6311.400,-666.334,-2.165,-16.100,-49.975,****"
"6324.200,-665.994,-2.164,-15.600,-49.950,****"
"6337.000,-665.814,-2.162,-15.200,-49.936,****"
"6349.800,-666.290,-2.160,-14.800,-49.972,****"
"6362.600,-666.083,-2.158,-14.400,-49.956,****"
"6375.400,-666.170,-2.156,-14.000,-49.963,****"
"6388.200,-666.574,-2.154,-13.600,-49.993,****"
"6401.000,-665.911,-2.152,-13.100,-49.943,****"
"6413.800,-666.333,-2.150,-12.700,-49.975,****"
"6426.600,-666.046,-2.148,-12.300,-49.953,****"
"6439.400,-666.393,-2.146,-11.800,-49.979,****"
"6452.200,-666.273,-2.144,-11.400,-49.970,****"
"6465.000,-666.181,-2.141,-11.000,-49.964,****"
"6477.800,-666.195,-2.139,-10.600,-49.965,****"
"6490.600,-665.752,-2.137,-10.100,-49.931,****"
"6503.400,-666.327,-2.135,-9.700,-49.975,****"
"6516.200,-666.282,-2.132,-9.300,-49.971,****"
"6529.000,-666.052,-2.130,-8.900,-49.954,****"
"6541.800,-666.198,-2.128,-8.400,-49.965,****"
"6554.600,-666.020,-2.125,-8.000,-49.951,****"
"6567.400,-666.349,-2.123,-7.600,-49.976,****"
"6580.200,-666.069,-2.120,-7.100,-49.955,****"
"6593.000,-665.974,-2.118,-6.700,-49.948,****"
"6605.800,-666.037,-2.115,-6.300,-49.953,****"
"6618.600,-666.290,-2.112,-5.800,-49.972,****"
"6631.400,-666.181,-2.110,-5.400,-49.964,****"
"6644.200,-666.391,-2.107,-5.000,-49.979,****"
"6657.000,-666.348,-2.105,-4.570,-49.976,****"
"6669.800,-666.411,-2.102,-4.100,-49.981,****"
"6682.600,-666.357,-2.099,0.000,-49.977,****"
"6695.400,-666.593,-2.097,-3.200,-49.994,****"
"6708.200,-666.364,-2.094,-2.900,-49.977,****"
"6721.000,-666.490,-2.091,-2.400,-49.987,****"
"6733.800,-665.902,-2.088,-2.000,-49.943,****"
"6746.600,-666.087,-2.086,-1.600,-49.957,****"
"6759.400,-666.672,-2.083,-1.200,-50.000,****"
"6772.200,-665.636,-2.080,-0.700,-49.923,****"
"6785.000,-666.560,-2.077,0.000,-49.992,****"
"6797.800,-666.266,-2.074,0.100,-49.970,****"
"6810.600,-666.000,-2.071,0.600,-49.950,****"
"6823.400,-666.322,-2.068,1.000,-49.974,****"
"6836.200,-666.196,-2.065,1.400,-49.965,****"
"6849.000,-666.650,-2.062,1.800,-49.999,****"
"6861.800,-665.748,-2.059,2.200,-49.931,****"
"6874.600,-666.523,-2.056,2.700,-49.989,****"
"6887.400,-666.470,-2.053,3.100,-49.985,****"
"6900.200,-665.791,-2.050,3.500,-49.934,****"
"6913.000,-666.041,-2.047,4.000,-49.953,****"
"6925.800,-666.303,-2.044,4.400,-49.973,****"
"6938.600,-666.382,-2.041,4.800,-49.979,****"
"6951.400,-666.477,-2.038,5.300,-49.986,****"
"6964.200,-666.107,-2.035,5.800,-49.958,****"
"6977.000,-666.404,-2.032,6.100,-49.980,****"
"6989.800,-666.302,-2.029,6.500,-49.973,****"
"7002.600,-666.057,-2.026,7.000,-49.954,****"
"7015.400,-666.141,-2.022,7.400,-49.961,****"
"7028.200,-666.357,-2.020,7.800,-49.977,****"
"7041.000,-666.031,-2.016,8.300,-49.952,****"
"7053.800,-666.125,-2.013,8.700,-49.959,****"
"7066.600,-666.112,-2.010,9.100,-49.958,****"
"7079.400,-666.359,-2.007,9.500,-49.977,****"
"7092.200,-665.884,-2.004,10.000,-49.941,****"
"7105.000,-665.953,-2.000,10.400,-49.946,****"
"7117.800,-665.837,-1.997,10.800,-49.938,****"
"7130.600,-666.244,-1.994,11.200,-49.968,****"
"7143.400,-666.290,-1.991,11.600,-49.972,****"
"7156.200,-666.041,-1.988,12.100,-49.953,****"
"7169.000,-666.224,-1.985,12.500,-49.967,****"
"7181.800,-666.426,-1.982,12.900,-49.982,****"
"7194.600,-666.465,-1.978,13.400,-49.985,****"
"7207.400,-666.101,-1.975,13.800,-49.958,****"
"7220.200,-666.112,-1.971,14.200,-49.958,****"
"7233.000,-665.910,-1.968,14.600,-49.943,****"
"7245.800,-666.159,-1.964,15.100,-49.962,****"
"7258.600,-666.289,-1.960,15.500,-49.972,****"
"7271.400,-666.220,-1.957,15.900,-49.966,****"
"7284.200,-665.992,-1.953,16.300,-49.949,****"
"7297.000,-666.139,-1.950,16.700,-49.960,****"
"7309.800,-666.180,-1.947,17.200,-49.964,****"
"7322.600,-666.294,-1.944,17.600,-49.972,****"
"7335.400,-666.594,-1.940,18.000,-49.995,****"
"7348.200,-666.336,-1.937,18.400,-49.975,****"
"7361.000,-666.419,-1.933,18.900,-49.981,****"
"7373.800,-666.216,-1.930,19.300,-49.966,****"
"7386.600,-666.187,-1.927,19.800,-49.964,****"
"7399.400,-666.198,-1.924,20.200,-49.965,****"
"7412.200,-666.541,-1.920,20.700,-49.991,****"
"7425.000,-666.848,-1.917,21.100,-50.014,****"
"7437.800,-666.268,-1.913,21.500,-49.970,****"
"7450.600,-666.354,-1.910,21.900,-49.977,****"
"7463.400,-666.698,-1.906,22.300,-50.002,****"
"7476.200,-666.547,-1.903,22.800,-49.991,****"
"7489.000,-665.834,-1.899,23.200,-49.938,****"
"7501.800,-666.019,-1.896,23.600,-49.951,****"
"7514.600,-666.372,-1.893,24.000,-49.978,****"
"7527.400,-665.853,-1.889,24.500,-49.939,****"
"7540.200,-666.343,-1.886,24.900,-49.976,****"
"7553.000,-666.169,-1.883,25.400,-49.963,****"
"7565.800,-666.265,-1.879,25.800,-49.970,****"
"7578.600,-666.594,-1.876,26.200,-49.995,****"
"7591.400,-666.056,-1.872,26.600,-49.954,****"
"7604.200,-666.414,-1.869,27.000,-49.981,****"
"7617.000,-666.308,-1.866,27.500,-49.973,****"
"7629.800,-666.179,-1.862,27.900,-49.963,****"
"7642.600,-666.266,-1.859,28.300,-49.970,****"
"7655.400,-666.267,-1.855,28.700,-49.970,****"
"7668.200,-666.250,-1.852,29.200,-49.969,****"
"7681.000,-666.539,-1.848,29.600,-49.990,****"
"7693.800,-666.406,-1.845,30.000,-49.980,****"
"7706.600,-666.439,-1.841,30.400,-49.983,****"
"7719.400,-665.886,-1.837,30.900,-49.941,****"
"7732.200,-666.259,-1.834,31.300,-49.969,****"
"7745.000,-666.011,-1.830,31.700,-49.951,****"
"7757.800,-666.255,-1.826,32.100,-49.969,****"
"7770.600,-666.059,-1.822,32.600,-49.954,****"
"7783.400,-666.120,-1.818,33.000,-49.959,****"
"7796.200,-666.380,-1.815,33.400,-49.979,****"
"7809.000,-666.241,-1.811,33.800,-49.968,****"
"7821.800,-666.454,-1.806,34.300,-49.984,****"
"7834.600,-666.055,-1.802,34.800,-49.954,****"
"7847.400,-666.077,-1.798,35.100,-49.956,****"
"7860.200,-666.498,-1.794,35.600,-49.987,****"
"7873.000,-666.488,-1.789,36.000,-49.987,****"
"7885.800,-666.252,-1.784,36.400,-49.969,****"
"7898.600,-666.534,-1.780,36.800,-49.990,****"
"7911.400,-666.316,-1.775,37.300,-49.974,****"
"7924.200,-666.312,-1.770,37.700,-49.973,****"
"7937.000,-666.475,-1.764,38.100,-49.986,****"
"7949.800,-666.599,-1.759,38.500,-49.995,****"
"7962.600,-666.456,-1.753,38.900,-49.984,****"
"7975.400,-666.550,-1.746,39.400,-49.991,****"
"7988.200,-666.447,-1.740,39.800,-49.984,****"
"8001.000,-666.549,-1.733,40.300,-49.991,****"
"8013.800,-666.761,-1.726,40.700,-50.007,****"
"8026.600,-666.475,-1.719,41.100,-49.986,****"
"8039.400,-666.272,-1.711,41.500,-49.970,****"
"8052.200,-666.378,-1.704,42.000,-49.978,****"
"8065.000,-667.032,-1.696,42.400,-50.027,****"
"8077.800,-666.664,-1.688,42.800,-50.000,****"
"8090.600,-667.160,-1.679,43.200,-50.037,****"
"8103.400,-666.799,-1.670,43.700,-50.010,****"
"8116.200,-666.751,-1.660,44.100,-50.006,****"
"8129.000,-666.815,-1.650,44.500,-50.011,****"
"8141.800,-666.879,-1.638,45.000,-50.016,****"
"8154.600,-666.502,-1.625,45.400,-49.988,****"
"8167.400,-667.020,-1.611,45.800,-50.026,****"
"8180.200,-667.155,-1.598,46.200,-50.037,****"
"8193.000,-667.186,-1.584,46.700,-50.039,****"
"8205.800,-667.125,-1.570,47.100,-50.034,****"
"8218.600,-666.629,-1.556,47.500,-49.997,****"
"8231.400,-667.382,-1.541,48.000,-50.054,****"
"8244.200,-667.437,-1.526,48.400,-50.058,****"
"8257.000,-666.968,-1.510,48.800,-50.023,****"
"8269.800,-667.317,-1.495,49.200,-50.049,****"
"8282.600,-667.459,-1.479,49.700,-50.059,****"
"8295.400,-667.437,-1.462,50.100,-50.058,****"
"8308.200,-667.502,-1.445,50.500,-50.063,****"
"8321.000,-667.508,-1.428,50.900,-50.063,****"
"8333.800,-667.179,-1.410,51.400,-50.038,****"
"8346.600,-667.409,-1.391,51.800,-50.056,****"
"8359.400,-667.469,-1.373,52.200,-50.060,****"
"8372.200,-667.174,-1.354,52.600,-50.038,****"
"8385.000,-667.556,-1.336,53.000,-50.067,****"
"8397.800,-667.631,-1.316,53.500,-50.072,****"
"8410.600,-667.637,-1.297,53.900,-50.073,****"
"8423.400,-667.616,-1.277,54.300,-50.071,****"
"8436.200,-667.465,-1.256,54.800,-50.060,****"
"8449.000,-667.829,-1.235,55.200,-50.087,****"
"8461.800,-667.483,-1.214,55.600,-50.061,****"
"8474.600,-667.376,-1.192,56.100,-50.053,****"
"8487.400,-667.913,-1.171,56.500,-50.093,****"
"8500.200,-667.328,-1.150,56.900,-50.050,****"
"8513.000,-667.596,-1.129,57.300,-50.070,****"
"8525.800,-667.723,-1.109,57.700,-50.079,****"
"8538.600,-667.601,-1.090,58.200,-50.070,****"
"8551.400,-667.485,-1.071,58.600,-50.061,****"
"8564.200,-667.111,-1.054,59.000,-50.033,****"
"8577.000,-666.959,-1.037,59.400,-50.022,****"
"8589.800,-667.040,-1.021,59.900,-50.028,****"
"8602.600,-666.870,-1.006,60.300,-50.015,****"
"8615.400,-667.229,-0.992,60.700,-50.042,****"
"8628.200,-667.052,-0.979,61.200,-50.029,****"
"8641.000,-666.722,-0.966,61.600,-50.004,****"
"8653.800,-666.687,-0.955,62.000,-50.002,****"
"8666.600,-666.723,-0.944,62.500,-50.004,****"
"8679.400,-666.986,-0.934,62.900,-50.024,****"
"8692.200,-666.719,-0.925,63.300,-50.004,****"
"8705.000,-666.506,-0.916,63.700,-49.988,****"
"8717.800,-666.609,-0.908,64.200,-49.996,****"
"8730.600,-666.512,-0.901,64.600,-49.988,****"
"8743.400,-666.143,-0.894,65.000,-49.961,****"
"8756.200,-666.407,-0.887,65.500,-49.981,****"
"8769.000,-665.900,-0.881,65.800,-49.942,****"
"8781.800,-666.415,-0.875,66.300,-49.981,****"
"8794.600,-666.267,-0.869,66.700,-49.970,****"
"8807.400,-666.229,-0.864,67.200,-49.967,****"
"8820.200,-666.228,-0.858,67.600,-49.967,****"
"8833.000,-666.502,-0.853,68.000,-49.988,****"
"8845.800,-666.376,-0.848,68.400,-49.978,****"
"8858.600,-666.393,-0.843,68.800,-49.979,****"
"8871.400,-665.873,-0.838,69.300,-49.940,****"
"8884.200,-666.261,-0.833,69.700,-49.970,****"
"8897.000,-666.575,-0.829,70.100,-49.993,****"
"8909.800,-666.418,-0.824,70.500,-49.981,****"
"8922.600,-666.142,-0.820,71.000,-49.961,****"
"8935.400,-666.517,-0.815,71.400,-49.989,****"
"8948.200,-666.449,-0.811,71.900,-49.984,****"
[...]
"6439.400,-666.393,-2.146,-11.800,-49.979,****"
"6452.200,-666.273,-2.144,-11.400,-49.970,****"
"6465.000,-666.181,-2.141,-11.000,-49.964,****"
"6477.800,-666.195,-2.139,-10.600,-49.965,****"
"6490.600,-665.752,-2.137,-10.100,-49.931,****"
"6503.400,-666.327,-2.135,-9.700,-49.975,****"
"6516.200,-666.282,-2.132,-9.300,-49.971,****"
"6529.000,-666.052,-2.130,-8.900,-49.954,****"
"6541.800,-666.198,-2.128,-8.400,-49.965,****"
"6554.600,-666.020,-2.125,-8.000,-49.951,****"
"6567.400,-666.349,-2.123,-7.600,-49.976,****"
"6580.200,-666.069,-2.120,-7.100,-49.955,****"
"6593.000,-665.974,-2.118,-6.700,-49.948,****"
"6605.800,-666.037,-2.115,-6.300,-49.953,****"
"6618.600,-666.290,-2.112,-5.800,-49.972,****"
"6631.400,-666.181,-2.110,-5.400,-49.964,****"
"6644.200,-666.391,-2.107,-5.000,-49.979,****"
"6657.000,-666.348,-2.105,-4.570,-49.976,****"
"6669.800,-666.411,-2.102,-4.100,-49.981,****"
"6682.600,-666.357,-2.099,0.000,-49.977,****"
"6695.400,-666.593,-2.097,-3.200,-49.994,****"
"6708.200,-666.364,-2.094,-2.900,-49.977,****"
"6721.000,-666.490,-2.091,-2.400,-49.987,****"
"6733.800,-665.902,-2.088,-2.000,-49.943,****"
"6746.600,-666.087,-2.086,-1.600,-49.957,****"
"6759.400,-666.672,-2.083,-1.200,-50.000,****"
"6772.200,-665.636,-2.080,-0.700,-49.923,****"
"6785.000,-666.560,-2.077,0.000,-49.992,****"
"6797.800,-666.266,-2.074,0.100,-49.970,****"
"6810.600,-666.000,-2.071,0.600,-49.950,****"
"6823.400,-666.322,-2.068,1.000,-49.974,****"
"6836.200,-666.196,-2.065,1.400,-49.965,****"
"6849.000,-666.650,-2.062,1.800,-49.999,****"
"6861.800,-665.748,-2.059,2.200,-49.931,****"
"6874.600,-666.523,-2.056,2.700,-49.989,****"
"6887.400,-666.470,-2.053,3.100,-49.985,****"
"6900.200,-665.791,-2.050,3.500,-49.934,****"
"6913.000,-666.041,-2.047,4.000,-49.953,****"
"6925.800,-666.303,-2.044,4.400,-49.973,****"
"6938.600,-666.382,-2.041,4.800,-49.979,****"
"6951.400,-666.477,-2.038,5.300,-49.986,****"
"6964.200,-666.107,-2.035,5.800,-49.958,****"
"6977.000,-666.404,-2.032,6.100,-49.980,****"
"6989.800,-666.302,-2.029,6.500,-49.973,****"
"7002.600,-666.057,-2.026,7.000,-49.954,****"
"7015.400,-666.141,-2.022,7.400,-49.961,****"
"7028.200,-666.357,-2.020,7.800,-49.977,****"
"7041.000,-666.031,-2.016,8.300,-49.952,****"
"7053.800,-666.125,-2.013,8.700,-49.959,****"
"7066.600,-666.112,-2.010,9.100,-49.958,****"
"7079.400,-666.359,-2.007,9.500,-49.977,****"
"7092.200,-665.884,-2.004,10.000,-49.941,****"
"7105.000,-665.953,-2.000,10.400,-49.946,****"
"7117.800,-665.837,-1.997,10.800,-49.938,****"
"7130.600,-666.244,-1.994,11.200,-49.968,****"
"7143.400,-666.290,-1.991,11.600,-49.972,****"
"7156.200,-666.041,-1.988,12.100,-49.953,****"
"7169.000,-666.224,-1.985,12.500,-49.967,****"
"7181.800,-666.426,-1.982,12.900,-49.982,****"
"7194.600,-666.465,-1.978,13.400,-49.985,****"
"7207.400,-666.101,-1.975,13.800,-49.958,****"
"7220.200,-666.112,-1.971,14.200,-49.958,****"
"7233.000,-665.910,-1.968,14.600,-49.943,****"
"7245.800,-666.159,-1.964,15.100,-49.962,****"
"7258.600,-666.289,-1.960,15.500,-49.972,****"
"7271.400,-666.220,-1.957,15.900,-49.966,****"
"7284.200,-665.992,-1.953,16.300,-49.949,****"
"7297.000,-666.139,-1.950,16.700,-49.960,****"
"7309.800,-666.180,-1.947,17.200,-49.964,****"
"7322.600,-666.294,-1.944,17.600,-49.972,****"
"7335.400,-666.594,-1.940,18.000,-49.995,****"
"7348.200,-666.336,-1.937,18.400,-49.975,****"
"7361.000,-666.419,-1.933,18.900,-49.981,****"
"7373.800,-666.216,-1.930,19.300,-49.966,****"
"7386.600,-666.187,-1.927,19.800,-49.964,****"
"7399.400,-666.198,-1.924,20.200,-49.965,****"
"7412.200,-666.541,-1.920,20.700,-49.991,****"
"7425.000,-666.848,-1.917,21.100,-50.014,****"
"7437.800,-666.268,-1.913,21.500,-49.970,****"
"7450.600,-666.354,-1.910,21.900,-49.977,****"
"7463.400,-666.698,-1.906,22.300,-50.002,****"
"7476.200,-666.547,-1.903,22.800,-49.991,****"
"7489.000,-665.834,-1.899,23.200,-49.938,****"
"7501.800,-666.019,-1.896,23.600,-49.951,****"
"7514.600,-666.372,-1.893,24.000,-49.978,****"
"7527.400,-665.853,-1.889,24.500,-49.939,****"
"7540.200,-666.343,-1.886,24.900,-49.976,****"
"7553.000,-666.169,-1.883,25.400,-49.963,****"
"7565.800,-666.265,-1.879,25.800,-49.970,****"
"7578.600,-666.594,-1.876,26.200,-49.995,****"
"7591.400,-666.056,-1.872,26.600,-49.954,****"
"7604.200,-666.414,-1.869,27.000,-49.981,****"
"7617.000,-666.308,-1.866,27.500,-49.973,****"
"7629.800,-666.179,-1.862,27.900,-49.963,****"
"7642.600,-666.266,-1.859,28.300,-49.970,****"
"7655.400,-666.267,-1.855,28.700,-49.970,****"
"7668.200,-666.250,-1.852,29.200,-49.969,****"
"7681.000,-666.539,-1.848,29.600,-49.990,****"
"7693.800,-666.406,-1.845,30.000,-49.980,****"
"7706.600,-666.439,-1.841,30.400,-49.983,****"
"7719.400,-665.886,-1.837,30.900,-49.941,****"
"7732.200,-666.259,-1.834,31.300,-49.969,****"
"7745.000,-666.011,-1.830,31.700,-49.951,****"
"7757.800,-666.255,-1.826,32.100,-49.969,****"
"7770.600,-666.059,-1.822,32.600,-49.954,****"
"7783.400,-666.120,-1.818,33.000,-49.959,****"
"7796.200,-666.380,-1.815,33.400,-49.979,****"
"7809.000,-666.241,-1.811,33.800,-49.968,****"
"7821.800,-666.454,-1.806,34.300,-49.984,****"
"7834.600,-666.055,-1.802,34.800,-49.954,****"
"7847.400,-666.077,-1.798,35.100,-49.956,****"
"7860.200,-666.498,-1.794,35.600,-49.987,****"
"7873.000,-666.488,-1.789,36.000,-49.987,****"
"7885.800,-666.252,-1.784,36.400,-49.969,****"
"7898.600,-666.534,-1.780,36.800,-49.990,****"
"7911.400,-666.316,-1.775,37.300,-49.974,****"
"7924.200,-666.312,-1.770,37.700,-49.973,****"
"7937.000,-666.475,-1.764,38.100,-49.986,****"
"7949.800,-666.599,-1.759,38.500,-49.995,****"
"7962.600,-666.456,-1.753,38.900,-49.984,****"
"7975.400,-666.550,-1.746,39.400,-49.991,****"
"7988.200,-666.447,-1.740,39.800,-49.984,****"
"8001.000,-666.549,-1.733,40.300,-49.991,****"
"8013.800,-666.761,-1.726,40.700,-50.007,****"
"8026.600,-666.475,-1.719,41.100,-49.986,****"
"8039.400,-666.272,-1.711,41.500,-49.970,****"
"8052.200,-666.378,-1.704,42.000,-49.978,****"
"8065.000,-667.032,-1.696,42.400,-50.027,****"
"8077.800,-666.664,-1.688,42.800,-50.000,****"
"8090.600,-667.160,-1.679,43.200,-50.037,****"
"8103.400,-666.799,-1.670,43.700,-50.010,****"
"8116.200,-666.751,-1.660,44.100,-50.006,****"
"8129.000,-666.815,-1.650,44.500,-50.011,****"
"8141.800,-666.879,-1.638,45.000,-50.016,****"
"8154.600,-666.502,-1.625,45.400,-49.988,****"
"8167.400,-667.020,-1.611,45.800,-50.026,****"
"8180.200,-667.155,-1.598,46.200,-50.037,****"
"8193.000,-667.186,-1.584,46.700,-50.039,****"
"8205.800,-667.125,-1.570,47.100,-50.034,****"
"8218.600,-666.629,-1.556,47.500,-49.997,****"
"8231.400,-667.382,-1.541,48.000,-50.054,****"
"8244.200,-667.437,-1.526,48.400,-50.058,****"
"8257.000,-666.968,-1.510,48.800,-50.023,****"
"8269.800,-667.317,-1.495,49.200,-50.049,****"
"8282.600,-667.459,-1.479,49.700,-50.059,****"
"8295.400,-667.437,-1.462,50.100,-50.058,****"
"8308.200,-667.502,-1.445,50.500,-50.063,****"
"8321.000,-667.508,-1.428,50.900,-50.063,****"
"8333.800,-667.179,-1.410,51.400,-50.038,****"
"8346.600,-667.409,-1.391,51.800,-50.056,****"
"8359.400,-667.469,-1.373,52.200,-50.060,****"
"8372.200,-667.174,-1.354,52.600,-50.038,****"
"8385.000,-667.556,-1.336,53.000,-50.067,****"
"8397.800,-667.631,-1.316,53.500,-50.072,****"
"8410.600,-667.637,-1.297,53.900,-50.073,****"
"8423.400,-667.616,-1.277,54.300,-50.071,****"
"8436.200,-667.465,-1.256,54.800,-50.060,****"
"8449.000,-667.829,-1.235,55.200,-50.087,****"
"8461.800,-667.483,-1.214,55.600,-50.061,****"
"8474.600,-667.376,-1.192,56.100,-50.053,****"
"8487.400,-667.913,-1.171,56.500,-50.093,****"
"8500.200,-667.328,-1.150,56.900,-50.050,****"
"8513.000,-667.596,-1.129,57.300,-50.070,****"
"8525.800,-667.723,-1.109,57.700,-50.079,****"
"8538.600,-667.601,-1.090,58.200,-50.070,****"
"8551.400,-667.485,-1.071,58.600,-50.061,****"
"8564.200,-667.111,-1.054,59.000,-50.033,****"
"8577.000,-666.959,-1.037,59.400,-50.022,****"
"8589.800,-667.040,-1.021,59.900,-50.028,****"
"8602.600,-666.870,-1.006,60.300,-50.015,****"
"8615.400,-667.229,-0.992,60.700,-50.042,****"
"8628.200,-667.052,-0.979,61.200,-50.029,****"
"8641.000,-666.722,-0.966,61.600,-50.004,****"
"8653.800,-666.687,-0.955,62.000,-50.002,****"
"8666.600,-666.723,-0.944,62.500,-50.004,****"
"8679.400,-666.986,-0.934,62.900,-50.024,****"
"8692.200,-666.719,-0.925,63.300,-50.004,****"
"8705.000,-666.506,-0.916,63.700,-49.988,****"
"8717.800,-666.609,-0.908,64.200,-49.996,****"
"8730.600,-666.512,-0.901,64.600,-49.988,****"
"8743.400,-666.143,-0.894,65.000,-49.961,****"
"8756.200,-666.407,-0.887,65.500,-49.981,****"
"8769.000,-665.900,-0.881,65.800,-49.942,****"
"8781.800,-666.415,-0.875,66.300,-49.981,****"
"8794.600,-666.267,-0.869,66.700,-49.970,****"
"8807.400,-666.229,-0.864,67.200,-49.967,****"
"8820.200,-666.228,-0.858,67.600,-49.967,****"
"8833.000,-666.502,-0.853,68.000,-49.988,****"
"8845.800,-666.376,-0.848,68.400,-49.978,****"
"8858.600,-666.393,-0.843,68.800,-49.979,****"
"8871.400,-665.873,-0.838,69.300,-49.940,****"
"8884.200,-666.261,-0.833,69.700,-49.970,****"
"8897.000,-666.575,-0.829,70.100,-49.993,****"
"8909.800,-666.418,-0.824,70.500,-49.981,****"
"8922.600,-666.142,-0.820,71.000,-49.961,****"
"8935.400,-666.517,-0.815,71.400,-49.989,****"
"8948.200,-666.449,-0.811,71.900,-49.984,****"
"8961.000,-666.174,-0.806,72.200,-49.963,****"
"8973.800,-666.262,-0.802,72.700,-49.970,****"
"8986.600,-666.097,-0.798,73.100,-49.957,****"
"8999.400,-666.335,-0.794,73.500,-49.975,****"
"9012.200,-666.448,-0.789,74.000,-49.984,****"
"9025.000,-666.144,-0.785,74.400,-49.961,****"
"9037.800,-666.304,-0.781,74.900,-49.973,****"
"9050.600,-665.902,-0.777,75.300,-49.943,****"
"9063.400,-666.576,-0.773,75.700,-49.993,****"
"9076.200,-666.218,-0.769,76.100,-49.966,****"
"9089.000,-666.201,-0.765,76.500,-49.965,****"
"9101.800,-666.102,-0.761,77.000,-49.958,****"
"9114.600,-666.179,-0.757,77.400,-49.963,****"
"9127.400,-666.283,-0.753,77.800,-49.971,****"
"9140.200,-666.044,-0.749,78.200,-49.953,****"
"9153.000,-665.932,-0.745,78.700,-49.945,****"
"9165.800,-666.179,-0.741,79.100,-49.963,****"
"9178.600,-666.313,-0.737,79.500,-49.974,****"
"9191.400,-666.215,-0.733,79.900,-49.966,****"
"9204.200,-666.163,-0.729,80.400,-49.962,****"
"9217.000,-665.974,-0.725,80.800,-49.948,****"
"9229.800,-666.424,-0.721,81.200,-49.982,****"
"9242.600,-666.204,-0.717,81.600,-49.965,****"
"9255.400,-666.407,-0.713,82.100,-49.981,****"
"9268.200,-666.262,-0.709,82.400,-49.970,****"
"9281.000,-666.089,-0.705,83.000,-49.957,****"
"9293.800,-666.206,-0.702,83.400,-49.965,****"
"9306.600,-666.216,-0.698,83.800,-49.966,****"
"9319.400,-666.247,-0.694,84.200,-49.969,****"
"9332.200,-666.235,-0.690,84.600,-49.968,****"
"9345.000,-666.629,-0.686,85.000,-49.997,****"
"9357.800,-666.332,-0.682,85.400,-49.975,****"
"9370.600,-666.279,-0.678,85.900,-49.971,****"
"9383.400,-666.015,-0.674,86.400,-49.951,****"
"9396.200,-666.692,-0.671,86.800,-50.002,****"
"9409.000,-666.406,-0.667,87.200,-49.980,****"
"9421.800,-666.595,-0.663,87.600,-49.995,****"
"9434.600,-666.112,-0.659,88.100,-49.958,****"
"9447.400,-666.031,-0.655,88.500,-49.952,****"
"9460.200,-666.225,-0.651,88.900,-49.967,****"
"9473.000,-666.478,-0.648,89.300,-49.986,****"
"9485.800,-666.157,-0.644,89.700,-49.962,****"
"9498.600,-666.346,-0.640,90.200,-49.976,****"
"9511.400,-666.489,-0.636,90.600,-49.987,****"
"9524.200,-666.432,-0.633,91.000,-49.982,****"
"9537.000,-666.318,-0.629,91.500,-49.974,****"
"9549.800,-666.347,-0.625,91.900,-49.976,****"
"9562.600,-666.217,-0.621,92.300,-49.966,****"
"9575.400,-666.379,-0.617,92.700,-49.978,****"
"9588.200,-666.165,-0.614,93.200,-49.962,****"
"9601.000,-667.020,-0.610,93.600,-50.027,****"
"9613.800,-666.141,-0.606,94.000,-49.961,****"
"9626.600,-666.588,-0.602,94.400,-49.994,****"
"9639.400,-666.350,-0.598,94.800,-49.976,****"
"9652.200,-666.292,-0.595,95.300,-49.972,****"
"9665.000,-665.986,-0.591,95.700,-49.949,****"
"9677.800,-666.124,-0.587,96.200,-49.959,****"
"9690.600,-666.570,-0.583,96.600,-49.993,****"
"9703.400,-666.483,-0.580,97.000,-49.986,****"
"9716.200,-666.200,-0.576,97.400,-49.965,****"
"9729.000,-666.424,-0.572,97.900,-49.982,****"
"9741.800,-666.440,-0.568,98.300,-49.983,****"
"9754.600,-666.409,-0.564,98.700,-49.981,****"
"9767.400,-666.726,-0.561,99.100,-50.004,****"
"9780.200,-666.383,-0.557,99.500,-49.979,****"
"9793.000,-666.360,-0.553,100.000,-49.977,****"
"9805.800,-666.354,-0.550,100.400,-49.977,****"
"9818.600,-666.142,-0.546,100.800,-49.961,****"
"9831.400,-666.049,-0.542,101.200,-49.954,****"
"9844.200,-666.581,-0.538,101.700,-49.994,****"
"9857.000,-666.329,-0.534,102.100,-49.975,****"
"9869.800,-665.887,-0.531,102.600,-49.942,****"
"9882.600,-666.394,-0.527,103.000,-49.980,****"
"9895.400,-665.949,-0.523,103.400,-49.946,****"
"9908.200,-666.234,-0.520,103.800,-49.968,****"
"9921.000,-666.423,-0.516,104.200,-49.982,****"
"9933.800,-666.107,-0.512,104.600,-49.958,****"
"9946.600,-666.440,-0.508,104.900,-49.983,****"
"9959.400,-666.220,-0.505,105.100,-49.967,****"
"9972.200,-665.931,-0.501,105.200,-49.945,****"
"9985.000,-666.152,-0.498,105.300,-49.961,****"
"9997.800,-666.299,-0.495,105.300,-49.972,****"
"10010.600,-665.963,-0.491,105.300,-49.947,****"
"10023.400,-665.945,-0.488,105.300,-49.946,****"
"10036.200,-666.324,-0.485,105.300,-49.974,****"
"10049.000,-666.347,-0.481,105.300,-49.976,****"
"10061.800,-666.084,-0.478,105.300,-49.956,****"
"10074.600,-666.106,-0.475,105.300,-49.958,****"
"10087.400,-666.759,-0.472,105.200,-50.007,****"
"10100.200,-666.175,-0.469,105.200,-49.963,****"
"10113.000,-666.290,-0.466,105.200,-49.972,****"
"10125.800,-665.880,-0.463,105.200,-49.941,****"
"10138.600,-665.967,-0.460,105.100,-49.948,****"
"10151.400,-666.013,-0.458,105.100,-49.951,****"
"10164.200,-665.973,-0.455,105.200,-49.948,****"
"10177.000,-666.085,-0.452,105.100,-49.956,****"
"10189.800,-666.095,-0.449,105.100,-49.957,****"
"10202.600,-666.511,-0.447,105.100,-49.988,****"
"10215.400,-666.072,-0.444,105.100,-49.955,****"
"10228.200,-666.546,-0.442,105.100,-49.991,****"
"10241.000,-666.180,-0.439,105.100,-49.964,****"
"10253.800,-666.140,-0.436,105.000,-49.960,****"
"10266.600,-666.074,-0.434,105.000,-49.956,****"
"10279.400,-666.408,-0.432,105.000,-49.981,****"
"10292.200,-666.143,-0.429,105.100,-49.961,****"
"10305.000,-666.468,-0.427,105.100,-49.985,****"
"10317.800,-666.176,-0.424,105.000,-49.963,****"
"10330.600,-666.157,-0.422,105.000,-49.962,****"
"10343.400,-665.891,-0.420,105.000,-49.942,****"
"10356.200,-666.293,-0.417,105.100,-49.972,****"
"10369.000,-666.135,-0.415,105.100,-49.960,****"
"10381.800,-666.506,-0.413,105.000,-49.988,****"
"10394.600,-666.199,-0.411,105.000,-49.965,****"
"10407.400,-665.565,-0.409,105.000,-49.917,****"
"10420.200,-666.210,-0.406,105.100,-49.966,****"
"10433.000,-666.188,-0.404,105.000,-49.964,****"
"10445.800,-666.187,-0.402,105.000,-49.964,****"
"10458.600,-665.532,-0.400,105.000,-49.915,****"
"10471.400,-666.196,-0.398,105.000,-49.965,****"
"10484.200,-665.873,-0.396,105.000,-49.941,****"
"10497.000,-666.443,-0.394,105.000,-49.983,****"
"10509.800,-666.378,-0.392,105.000,-49.978,****"
"10522.600,-666.200,-0.390,105.000,-49.965,****"
"10535.400,-666.210,-0.388,105.000,-49.966,****"
"10548.200,-666.377,-0.387,105.000,-49.978,****"
"10561.000,-666.469,-0.385,105.000,-49.985,****"
"10573.800,-666.073,-0.383,105.000,-49.955,****"
"10586.600,-666.190,-0.381,105.000,-49.964,****"
"10599.400,-666.382,-0.379,105.000,-49.979,****"
"10612.200,-666.456,-0.378,105.000,-49.984,****"
"10625.000,-666.170,-0.376,105.000,-49.963,****"
"10637.800,-665.677,-0.374,105.000,-49.926,****"
"10650.600,-666.724,-0.372,105.000,-50.004,****"
"10663.400,-665.685,-0.371,105.000,-49.926,****"
"10676.200,-665.741,-0.369,105.000,-49.931,****"
"10689.000,-666.125,-0.368,105.000,-49.959,****"
"10701.800,-666.558,-0.366,105.000,-49.992,****"
"10714.600,-666.164,-0.364,105.000,-49.962,****"
"10727.400,-666.057,-0.363,105.000,-49.954,****"
"10740.200,-665.986,-0.361,105.000,-49.949,****"
"10753.000,-665.992,-0.360,105.000,-49.949,****"
"10765.800,-666.613,-0.358,105.000,-49.996,****"
"10778.600,-666.624,-0.357,105.000,-49.997,****"
"10791.400,-665.996,-0.355,105.000,-49.950,****"
"10804.200,-666.102,-0.354,105.100,-49.958,****"
"10817.000,-666.171,-0.353,105.100,-49.963,****"
"10829.800,-666.362,-0.351,105.000,-49.977,****"
"10842.600,-666.095,-0.350,104.800,-49.957,****"
"10855.400,-666.000,-0.349,104.400,-49.950,****"
"10868.200,-665.834,-0.348,104.000,-49.938,****"
"10881.000,-666.526,-0.348,103.500,-49.989,****"
"10893.800,-666.344,-0.347,103.000,-49.976,****"
"10906.600,-665.888,-0.346,102.400,-49.942,****"
"10919.400,-665.764,-0.346,101.900,-49.932,****"
"10932.200,-665.610,-0.345,101.300,-49.921,****"
"10945.000,-665.720,-0.345,100.800,-49.929,****"
"10957.800,-665.833,-0.344,100.200,-49.938,****"
"10970.600,-665.825,-0.344,99.700,-49.937,****"
"10983.400,-666.344,-0.344,99.300,-49.976,****"
"10996.200,-665.910,-0.343,98.900,-49.943,****"
"11009.000,-666.154,-0.343,98.500,-49.962,****"
"11021.800,-665.841,-0.342,98.000,-49.938,****"
"11034.600,-665.795,-0.342,97.600,-49.935,****"
"11047.400,-665.686,-0.342,97.100,-49.926,****"
"11060.200,-665.878,-0.342,96.800,-49.941,****"
"11073.000,-665.966,-0.342,96.400,-49.947,****"
"11085.800,-666.013,-0.342,95.900,-49.951,****"
"11098.600,-665.841,-0.342,95.400,-49.938,****"
"11111.400,-666.061,-0.342,95.000,-49.955,****"
"11124.200,-666.520,-0.342,94.600,-49.989,****"
"11137.000,-666.088,-0.342,94.200,-49.957,****"
"11149.800,-666.254,-0.342,93.700,-49.969,****"
"11162.600,-666.071,-0.343,93.400,-49.955,****"
"11175.400,-666.147,-0.343,92.900,-49.961,****"
"11188.200,-665.983,-0.343,92.500,-49.949,****"
"11201.000,-665.590,-0.344,92.100,-49.919,****"
"11213.800,-665.826,-0.344,91.600,-49.937,****"
"11226.600,-666.325,-0.345,91.200,-49.974,****"
"11239.400,-665.652,-0.345,90.800,-49.924,****"
"11252.200,-665.631,-0.345,90.400,-49.922,****"
"11265.000,-665.811,-0.346,89.900,-49.936,****"
"11277.800,-665.792,-0.346,89.500,-49.934,****"
"11290.600,-665.943,-0.347,89.000,-49.946,****"
"11303.400,-665.964,-0.348,88.600,-49.947,****"
"11316.200,-665.470,-0.348,88.200,-49.910,****"
"11329.000,-665.600,-0.349,87.800,-49.920,****"
"11341.800,-665.983,-0.349,87.500,-49.949,****"
"11354.600,-666.141,-0.350,87.000,-49.961,****"
"11367.400,-665.792,-0.351,86.500,-49.934,****"
"11380.200,-666.085,-0.352,86.200,-49.956,****"
"11393.000,-665.846,-0.352,85.700,-49.938,****"
"11405.800,-666.029,-0.353,85.300,-49.952,****"
"11418.600,-665.911,-0.354,84.900,-49.943,****"
"11431.400,-666.398,-0.355,84.400,-49.980,****"
"11444.200,-665.982,-0.356,84.000,-49.949,****"
"11457.000,-665.846,-0.357,83.500,-49.938,****"
"11469.800,-665.851,-0.358,83.200,-49.939,****"
"11482.600,-665.914,-0.359,82.700,-49.944,****"
"11495.400,-665.884,-0.360,82.300,-49.941,****"
"11508.200,-665.853,-0.361,81.900,-49.939,****"
"11521.000,-666.134,-0.362,81.400,-49.960,****"
"11533.800,-665.954,-0.363,81.000,-49.947,****"
"11546.600,-666.370,-0.364,80.600,-49.978,****"
"11559.400,-666.358,-0.365,80.100,-49.977,****"
"11572.200,-665.820,-0.367,79.700,-49.937,****"
"11585.000,-665.969,-0.368,79.400,-49.948,****"
"11597.800,-665.944,-0.369,78.800,-49.946,****"
"11610.600,-665.884,-0.370,78.400,-49.941,****"
"11623.400,-665.808,-0.372,78.000,-49.936,****"
"11636.200,-666.366,-0.373,77.600,-49.977,****"
"11649.000,-666.327,-0.374,77.300,-49.975,****"
"11661.800,-665.882,-0.376,76.700,-49.941,****"
"11674.600,-665.718,-0.377,76.200,-49.929,****"
"11687.400,-666.094,-0.379,75.800,-49.957,****"
"11700.200,-665.566,-0.380,75.500,-49.917,****"
"11713.000,-665.458,-0.382,75.000,-49.909,****"
"11725.800,-665.610,-0.383,74.500,-49.921,****"
"11738.600,-665.895,-0.385,74.200,-49.942,****"
"11751.400,-666.122,-0.387,73.700,-49.959,****"
"11764.200,-665.938,-0.388,73.400,-49.945,****"
"11777.000,-665.723,-0.390,72.900,-49.929,****"
"11789.800,-665.698,-0.392,72.300,-49.927,****"
"11792.590,-665.909,-0.392,72.400,-49.943,****"