File: documentation/exampledata/MingearLMSMA.txt
Column1	Column2	Column3	Column4	Column5	Column6	Column7

Test Method	TENSILE LMSMA.msm
Sample I. D.	MingearLMSMA.mss
Specimen Number	7

Time (s)	Load (N)	Stress (MPa)	_COM1 (C)	Crosshead (mm)	_Strain2 (mm)	Strain (mm/mm)

0.400	450.611	17.201	0.000	-0.003	-0.000	-0.012
0.600	435.609	16.628	0.000	-0.005	-0.000	-0.013
0.800	420.225	16.041	0.000	-0.007	-0.000	-0.013
1.000	405.808	15.490	0.000	-0.009	-0.000	-0.014
1.200	391.383	14.940	0.000	-0.011	-0.000	-0.015
1.400	376.733	14.381	0.000	-0.013	-0.000	-0.015
1.600	362.542	13.839	0.000	-0.015	0.000	-0.016
1.800	349.364	13.336	0.000	-0.017	-0.000	-0.016
2.000	335.301	12.799	0.000	-0.019	-0.000	-0.017
2.200	322.413	12.307	0.000	-0.021	0.000	-0.018
2.400	309.831	11.827	0.000	-0.023	-0.000	-0.018
2.600	296.845	11.331	0.000	-0.025	0.000	-0.019
2.790	285.185	10.886	0.000	-0.026	0.000	-0.020
3.200	280.477	10.706	0.000	-0.027	0.000	-0.020
3.400	282.521	10.784	0.000	-0.027	-0.000	-0.020
3.600	283.386	10.817	0.000	-0.027	0.000	-0.020
3.800	283.498	10.822	0.000	-0.027	-0.000	-0.020
4.000	283.943	10.839	0.000	-0.027	-0.000	-0.020
4.200	283.533	10.823	0.000	-0.027	-0.000	-0.020
4.400	283.577	10.825	0.000	-0.027	0.000	-0.020
4.600	283.109	10.807	0.000	-0.027	0.000	-0.020
4.800	283.149	10.808	0.000	-0.027	0.000	-0.020
5.000	283.060	10.805	0.000	-0.026	-0.000	-0.020
5.200	282.653	10.789	0.000	-0.026	0.000	-0.019
5.400	283.077	10.806	0.000	-0.026	0.000	-0.019
5.600	282.767	10.794	0.000	-0.026	0.000	-0.019
5.800	282.840	10.796	0.000	-0.026	-0.000	-0.019
6.000	282.459	10.782	0.000	-0.026	-0.000	-0.019
6.200	282.512	10.784	0.000	-0.026	0.000	-0.019
6.400	282.394	10.779	0.000	-0.025	0.000	-0.019
6.600	282.643	10.789	0.000	-0.025	0.000	-0.019
6.800	282.170	10.771	0.000	-0.025	0.000	-0.019
7.000	282.172	10.771	0.000	-0.025	-0.000	-0.019
7.200	282.050	10.766	0.000	-0.024	-0.000	-0.019
7.400	282.182	10.771	0.000	-0.024	-0.000	-0.019
7.600	282.149	10.770	0.000	-0.024	-0.000	-0.019
7.800	281.738	10.754	0.000	-0.024	0.000	-0.019
8.000	282.001	10.764	0.000	-0.024	-0.000	-0.019
8.200	281.801	10.757	0.000	-0.023	0.000	-0.019
8.400	281.868	10.759	0.000	-0.023	0.000	-0.018
8.430	281.828	10.758	0.000	-0.023	0.000	-0.018
8.800	301.363	11.504	0.000	-0.020	0.000	-0.017
9.000	314.491	12.005	0.000	-0.018	-0.000	-0.017
9.200	326.238	12.453	0.000	-0.016	-0.000	-0.016
9.400	338.127	12.907	0.000	-0.014	0.000	-0.016
9.600	349.124	13.327	0.000	-0.012	0.000	-0.015
9.800	359.622	13.727	0.000	-0.010	0.000	-0.014
10.000	370.478	14.142	0.000	-0.008	0.000	-0.014
10.200	379.994	14.505	0.000	-0.006	-0.000	-0.013
10.400	389.579	14.871	0.000	-0.004	-0.000	-0.012
10.600	398.984	15.230	0.000	-0.002	0.000	-0.012
10.800	408.496	15.593	0.000	-0.000	0.000	-0.011
11.000	417.127	15.922	0.000	0.002	-0.000	-0.011
11.200	427.010	16.300	0.000	0.004	0.000	-0.010
11.400	435.989	16.642	0.000	0.006	0.000	-0.009
11.600	445.127	16.991	0.000	0.008	-0.000	-0.009
11.800	454.342	17.343	0.000	0.010	-0.000	-0.008
12.000	463.329	17.686	0.000	0.012	-0.000	-0.008
12.200	472.366	18.031	0.000	0.014	0.000	-0.007
12.400	481.859	18.393	0.000	0.016	-0.000	-0.006
12.600	490.687	18.730	0.000	0.018	0.000	-0.006
12.800	499.237	19.057	0.000	0.020	0.000	-0.005
13.000	508.064	19.394	0.000	0.022	-0.000	-0.004
13.200	516.069	19.699	0.000	0.024	0.000	-0.004
13.400	525.911	20.075	0.000	0.026	0.000	-0.003
13.600	547.839	20.912	0.000	0.028	0.000	-0.002
13.800	584.937	22.328	0.000	0.030	0.000	-0.002
14.000	623.993	23.819	0.000	0.032	0.000	-0.001
14.200	673.809	25.720	0.000	0.034	0.000	-0.001
14.400	733.164	27.986	0.000	0.036	0.000	0.000
14.600	799.933	30.535	0.000	0.038	0.000	0.001
14.800	873.858	33.357	0.000	0.040	0.000	0.001
15.000	955.611	36.477	0.000	0.042	-0.000	0.002
15.200	1052.591	40.179	0.000	0.044	0.000	0.003
15.400	1133.576	43.270	0.000	0.046	0.000	0.003
15.600	1181.529	45.101	0.000	0.048	0.000	0.004
15.800	1214.396	46.355	0.000	0.050	0.000	0.004
16.000	1241.146	47.377	0.000	0.052	-0.000	0.005
16.200	1268.808	48.432	0.000	0.054	0.000	0.006
16.400	1302.149	49.705	0.000	0.056	0.000	0.006
16.600	1330.600	50.791	0.000	0.058	0.000	0.007
16.800	1358.692	51.863	0.000	0.060	0.000	0.008
17.000	1392.214	53.143	0.000	0.062	0.000	0.008
17.200	1437.346	54.866	0.000	0.064	0.000	0.009
17.400	1534.342	58.568	0.000	0.066	0.000	0.009
17.600	1640.342	62.614	0.000	0.068	0.000	0.010
17.800	1737.128	66.309	0.000	0.070	0.000	0.011
18.000	1828.419	69.794	0.000	0.072	0.000	0.011
18.200	1922.770	73.395	0.000	0.074	-0.000	0.012
18.400	2016.954	76.990	0.000	0.075	0.000	0.013
18.600	2089.614	79.764	0.000	0.077	0.000	0.013
18.800	2153.828	82.215	0.000	0.079	0.000	0.014
19.000	2218.404	84.680	0.000	0.081	0.000	0.014
19.200	2265.090	86.462	0.000	0.083	0.000	0.015
19.400	2338.830	89.277	0.000	0.085	0.000	0.016
19.600	2427.003	92.643	0.000	0.087	0.000	0.016
19.800	2550.668	97.363	0.000	0.089	0.000	0.017
20.000	2691.238	102.729	0.000	0.091	0.000	0.018
20.200	2830.965	108.062	0.000	0.093	-0.000	0.018
20.400	2964.524	113.161	0.000	0.095	0.000	0.019
20.600	3060.121	116.810	0.000	0.097	-0.000	0.019
20.800	3148.739	120.192	0.000	0.099	0.000	0.020
21.000	3224.918	123.100	0.000	0.101	-0.000	0.021
21.200	3299.632	125.952	0.000	0.103	0.000	0.021
21.210	3303.394	126.096	0.000	0.103	0.000	0.021
27.800	3300.478	125.984	0.000	0.029	0.000	-0.002
34.200	3297.644	125.876	0.000	0.071	-0.000	0.011
40.600	3305.291	126.168	0.000	0.095	0.000	0.019
47.000	3311.356	126.400	0.000	0.103	-0.000	0.021
53.400	3308.779	126.301	0.000	0.096	0.000	0.019
59.800	3309.305	126.321	0.000	0.089	-0.000	0.017
66.200	3305.812	126.188	0.000	0.085	0.000	0.016
72.600	3308.028	126.273	0.000	0.086	-0.000	0.016
79.000	3309.474	126.328	0.000	0.085	-0.000	0.016
85.400	3306.175	126.202	0.000	0.085	0.000	0.016
91.800	3306.438	126.212	0.000	0.087	0.000	0.016
98.200	3306.838	126.227	0.000	0.093	0.000	0.018
104.600	3301.481	126.023	0.000	0.102	0.000	0.021
111.000	3304.399	126.134	0.000	0.121	0.000	0.027
117.400	3294.298	125.749	0.000	0.170	0.000	0.042
123.800	3309.480	126.328	0.000	0.223	-0.000	0.059
130.200	3306.545	126.216	0.000	0.215	-0.000	0.056
136.600	3272.690	124.924	0.000	0.241	0.000	0.065
143.000	3265.204	124.638	0.000	0.452	0.000	0.131
149.400	3265.033	124.631	0.000	0.654	0.000	0.195
155.800	3324.567	126.904	0.000	0.762	0.000	0.229
162.200	4218.057	161.010	0.000	0.354	-0.000	0.100
168.600	3303.848	126.113	0.000	0.217	-0.000	0.057
175.000	3303.218	126.089	0.000	0.226	0.000	0.060
181.400	3309.090	126.313	0.000	0.226	0.000	0.060
187.800	3302.750	126.071	0.000	0.236	-0.000	0.063
194.200	3311.051	126.388	0.000	0.230	-0.000	0.061
200.600	3309.389	126.325	0.000	0.220	-0.000	0.058
207.000	3307.927	126.269	0.000	0.213	0.000	0.056
213.400	3306.898	126.230	0.000	0.206	-0.000	0.054
219.800	3055.629	116.638	0.000	0.491	-0.000	0.144
226.200	2542.887	97.066	0.000	1.024	0.000	0.311
232.600	3073.571	117.323	0.000	1.558	0.000	0.479
239.000	3249.701	124.046	0.000	1.918	0.000	0.593
245.400	3382.649	129.121	0.000	1.983	-0.000	0.613
251.800	4255.790	162.450	0.000	1.647	0.000	0.508
258.200	5611.388	214.196	0.000	1.114	0.000	0.340
264.600	3308.067	126.274	0.000	0.843	0.000	0.254
271.000	3310.415	126.364	0.000	0.839	0.000	0.253
277.400	3304.445	126.136	0.000	0.844	0.000	0.255
283.800	3309.440	126.327	0.000	0.846	-0.000	0.255
290.200	3309.032	126.311	0.000	0.839	-0.000	0.253
296.600	3273.460	124.953	0.000	0.823	-0.000	0.248
303.000	3395.649	129.617	0.000	0.826	-0.000	0.249
309.400	3319.546	126.712	0.000	0.817	-0.000	0.246
315.800	3234.629	123.471	0.000	0.816	-0.000	0.246
322.200	3274.900	125.008	0.000	0.912	0.000	0.276
328.600	3295.265	125.785	0.000	1.303	-0.000	0.399
335.000	3285.870	125.427	0.000	1.676	0.000	0.517
341.400	3324.018	126.883	0.000	1.950	0.000	0.603
347.800	3217.314	122.810	0.000	2.147	-0.000	0.665
354.200	3322.586	126.828	0.000	2.237	0.000	0.693
360.600	3241.961	123.751	0.000	2.243	-0.000	0.695
367.000	3363.152	128.377	0.000	2.262	-0.000	0.701
373.400	3357.988	128.180	0.000	2.279	0.000	0.707
379.800	3363.436	128.388	0.000	2.297	0.000	0.712
386.200	3237.162	123.568	0.000	2.307	0.000	0.715
392.600	3362.791	128.363	0.000	2.335	-0.000	0.724
399.000	3333.333	127.239	0.000	2.360	0.000	0.732
405.400	3247.520	123.963	0.000	2.373	0.000	0.736
411.800	3250.505	124.077	0.000	2.403	-0.000	0.746
418.200	3342.803	127.600	0.000	2.431	-0.000	0.755
424.600	3264.053	124.594	0.000	2.458	0.000	0.763
431.000	3295.835	125.807	0.000	2.487	-0.000	0.772
437.400	3284.007	125.356	0.000	2.506	-0.000	0.778
443.800	3341.063	127.534	0.000	2.544	-0.000	0.790
450.200	3237.304	123.573	0.000	2.561	0.000	0.795
456.600	3352.861	127.984	0.000	2.597	0.000	0.807
463.000	3243.560	123.812	0.000	2.613	0.000	0.812
469.400	3367.902	128.558	0.000	2.643	0.000	0.821
475.800	3240.079	123.679	0.000	2.661	0.000	0.827
482.200	3360.003	128.257	0.000	2.692	0.000	0.837
488.600	3240.021	123.677	0.000	2.705	-0.000	0.841
495.000	3367.483	128.542	0.000	2.732	-0.000	0.849
501.400	3252.687	124.160	0.000	2.747	-0.000	0.854
507.800	3469.180	132.424	0.000	2.566	0.000	0.797
514.200	6262.574	239.052	0.000	2.032	0.000	0.629
520.600	4496.542	171.640	0.000	1.499	-0.000	0.461
527.000	3236.708	123.550	0.000	1.339	0.000	0.411
533.400	3352.055	127.953	0.000	1.347	-0.000	0.413
539.800	3376.364	128.881	0.000	1.354	-0.000	0.415
546.200	3221.032	122.952	0.000	1.335	-0.000	0.409
552.600	3393.743	129.545	0.000	1.331	-0.000	0.408
559.000	3252.995	124.172	0.000	1.322	-0.000	0.405
565.400	3328.993	127.073	0.000	1.316	-0.000	0.403
571.800	3326.648	126.983	0.000	1.319	0.000	0.404
578.200	3223.177	123.034	0.000	1.309	-0.000	0.401
584.600	3306.192	126.203	0.000	1.313	-0.000	0.402
591.000	3373.277	128.763	0.000	1.325	-0.000	0.406
597.400	3380.413	129.036	0.000	1.338	0.000	0.410
603.800	3374.806	128.822	0.000	1.361	-0.000	0.418
610.200	3368.128	128.567	0.000	1.398	-0.000	0.429
616.600	3248.798	124.012	0.000	1.450	-0.000	0.446
623.000	3288.615	125.532	0.000	1.524	-0.000	0.469
629.400	3322.225	126.815	0.000	1.626	0.000	0.501
635.800	3345.491	127.703	0.000	1.739	-0.000	0.537
642.200	3290.917	125.619	0.000	1.855	-0.000	0.573
648.600	3213.418	122.661	0.000	1.973	-0.000	0.610
655.000	3333.989	127.264	0.000	2.107	-0.000	0.652
661.400	3309.178	126.317	0.000	2.234	-0.000	0.692
667.800	3331.227	127.158	0.000	2.350	0.000	0.729
674.200	3284.000	125.355	0.000	2.459	-0.000	0.763
680.600	3250.275	124.068	0.000	2.557	-0.000	0.794
687.000	3349.815	127.868	0.000	2.667	0.000	0.829
693.400	3258.791	124.393	0.000	2.753	-0.000	0.856
699.800	3265.576	124.652	0.000	2.842	-0.000	0.884
706.200	3353.238	127.998	0.000	2.931	-0.000	0.912
712.600	3252.465	124.152	0.000	3.002	-0.000	0.934
719.000	3306.835	126.227	0.000	3.080	-0.000	0.959
725.400	3291.517	125.642	0.000	3.130	-0.000	0.975
731.800	3323.525	126.864	0.000	3.192	-0.000	0.994
738.200	3270.654	124.846	0.000	3.230	-0.000	1.006
744.600	3346.650	127.747	0.000	3.283	-0.000	1.023
751.000	3252.023	124.135	0.000	3.312	-0.000	1.032
757.400	3362.273	128.343	0.000	3.346	-0.000	1.043
763.800	3259.117	124.406	0.000	3.368	-0.000	1.049
770.200	3352.872	127.984	0.000	3.391	-0.000	1.057
776.600	3238.965	123.636	0.000	3.406	-0.000	1.061
783.000	3354.240	128.037	0.000	3.426	-0.000	1.068
789.400	3241.772	123.744	0.000	3.432	0.000	1.070
795.800	3332.280	127.198	0.000	3.456	0.000	1.077
802.200	3270.366	124.835	0.000	3.456	0.000	1.077
808.600	3288.271	125.519	0.000	3.473	0.000	1.083
815.000	3368.899	128.596	0.000	3.483	-0.000	1.086
821.400	3246.235	123.914	0.000	3.483	-0.000	1.086
827.800	3306.258	126.205	0.000	3.497	-0.000	1.090
834.200	3337.064	127.381	0.000	3.497	0.000	1.090
840.600	3242.833	123.784	0.000	3.498	0.000	1.090
847.000	3296.938	125.849	0.000	3.505	-0.000	1.093
853.400	3355.896	128.100	0.000	3.506	-0.000	1.093
859.800	3262.408	124.531	0.000	3.501	0.000	1.091
866.200	3256.703	124.314	0.000	3.508	0.000	1.094
872.600	3370.755	128.667	0.000	3.513	-0.000	1.095
879.000	3346.109	127.726	0.000	3.512	0.000	1.095
885.400	3263.749	124.582	0.000	3.507	-0.000	1.093
891.800	3289.808	125.577	0.000	3.516	0.000	1.096
898.200	3337.230	127.387	0.000	3.521	-0.000	1.098
904.600	3356.022	128.105	0.000	3.518	-0.000	1.097
911.000	3266.433	124.685	0.000	3.511	0.000	1.095
917.400	3237.462	123.579	0.000	3.515	0.000	1.096
923.800	3306.833	126.227	0.000	3.523	-0.000	1.098
930.200	3375.642	128.854	0.000	3.525	-0.000	1.099
936.600	3339.373	127.469	0.000	3.521	0.000	1.098
943.000	3237.093	123.565	0.000	3.519	-0.000	1.097
949.400	3303.710	126.108	0.000	3.526	0.000	1.099
955.800	3372.278	128.725	0.000	3.528	0.000	1.100
962.200	3299.577	125.950	0.000	3.521	-0.000	1.098
968.600	3257.166	124.331	0.000	3.520	-0.000	1.097
975.000	3252.508	124.153	0.000	3.525	-0.000	1.099
981.400	3331.757	127.178	0.000	3.532	0.000	1.101
987.800	3357.039	128.143	0.000	3.534	-0.000	1.102
994.200	3333.427	127.242	0.000	3.527	-0.000	1.100
1000.600	3244.175	123.835	0.000	3.524	-0.000	1.099
1007.000	3264.504	124.611	0.000	3.529	-0.000	1.100
1013.400	3330.694	127.138	0.000	3.535	-0.000	1.102
1019.800	3373.720	128.780	0.000	3.533	0.000	1.101
1026.200	3307.019	126.234	0.000	3.527	-0.000	1.100
1032.600	3243.459	123.808	0.000	3.528	-0.000	1.100
1039.000	3296.942	125.849	0.000	3.534	-0.000	1.102
1045.400	3367.825	128.555	0.000	3.536	-0.000	1.103
1051.800	3328.192	127.042	0.000	3.531	0.000	1.101
1058.200	3310.346	126.361	0.000	3.530	-0.000	1.101
1064.600	3241.394	123.729	0.000	3.529	-0.000	1.100
1071.000	3275.845	125.044	0.000	3.534	0.000	1.102
1077.400	3287.946	125.506	0.000	3.536	-0.000	1.103
1083.800	3341.456	127.549	0.000	3.541	-0.000	1.104
1090.200	3376.804	128.898	0.000	3.538	0.000	1.103
1096.600	3361.732	128.323	0.000	3.537	-0.000	1.103
1103.000	3295.794	125.806	0.000	3.532	-0.000	1.101
1109.400	3252.635	124.158	0.000	3.530	0.000	1.101
1115.800	3243.298	123.802	0.000	3.534	0.000	1.102
1122.200	3323.943	126.880	0.000	3.542	-0.000	1.104
1128.600	3355.716	128.093	0.000	3.544	0.000	1.105
1135.000	3355.363	128.079	0.000	3.539	0.000	1.103
1141.400	3296.152	125.819	0.000	3.534	-0.000	1.102
1147.800	3261.088	124.481	0.000	3.532	0.000	1.101
1154.200	3247.731	123.971	0.000	3.536	0.000	1.103
1160.600	3304.324	126.131	0.000	3.542	0.000	1.104
1167.000	3345.051	127.686	0.000	3.545	0.000	1.105
1173.400	3371.953	128.713	0.000	3.542	-0.000	1.104
1179.800	3326.273	126.969	0.000	3.537	-0.000	1.103
1186.200	3275.323	125.024	0.000	3.534	0.000	1.102
1192.600	3242.438	123.769	0.000	3.537	-0.000	1.103
1199.000	3282.085	125.282	0.000	3.541	-0.000	1.104
1205.400	3345.713	127.711	0.000	3.546	0.000	1.106
1211.800	3375.184	128.836	0.000	3.543	-0.000	1.105
1218.200	3329.310	127.085	0.000	3.539	0.000	1.103
1224.600	3270.567	124.843	0.000	3.534	0.000	1.102
1231.000	3240.459	123.693	0.000	3.537	-0.000	1.103
1237.400	3287.048	125.472	0.000	3.542	-0.000	1.104
1243.800	3345.502	127.703	0.000	3.546	-0.000	1.106
1250.200	3369.158	128.606	0.000	3.543	-0.000	1.105
1256.600	3311.065	126.389	0.000	3.538	-0.000	1.103
1263.000	3247.025	123.944	0.000	3.536	0.000	1.102
1269.400	3267.503	124.726	0.000	3.541	0.000	1.104
1275.800	3333.365	127.240	0.000	3.547	-0.000	1.106
1282.200	3373.826	128.784	0.000	3.544	-0.000	1.105
1288.600	3315.280	126.549	0.000	3.539	-0.000	1.103
1295.000	3255.354	124.262	0.000	3.536	-0.000	1.102
1301.400	3250.708	124.085	0.000	3.540	0.000	1.104
1307.800	3321.508	126.787	0.000	3.546	-0.000	1.106
1314.200	3374.926	128.826	0.000	3.546	-0.000	1.106
1320.600	3334.224	127.273	0.000	3.541	-0.000	1.104
1327.000	3252.996	124.172	0.000	3.537	-0.000	1.103
1333.400	3259.405	124.417	0.000	3.542	0.000	1.104
1339.800	3343.285	127.618	0.000	3.548	-0.000	1.106
1346.200	3359.574	128.240	0.000	3.544	0.000	1.105
1352.600	3299.424	125.944	0.000	3.539	-0.000	1.103
1359.000	3240.027	123.677	0.000	3.540	-0.000	1.104
1365.400	3298.628	125.914	0.000	3.546	-0.000	1.106
1371.800	3358.320	128.192	0.000	3.549	0.000	1.107
1378.200	3328.719	127.062	0.000	3.542	-0.000	1.104
1384.600	3272.266	124.908	0.000	3.537	-0.000	1.103
1391.000	3241.494	123.733	0.000	3.541	-0.000	1.104
1397.400	3321.912	126.803	0.000	3.548	-0.000	1.106
1403.800	3365.872	128.481	0.000	3.549	-0.000	1.107
1410.200	3339.939	127.491	0.000	3.543	0.000	1.105
1416.600	3280.393	125.218	0.000	3.538	-0.000	1.103
1423.000	3241.315	123.726	0.000	3.540	-0.000	1.104
1429.400	3289.528	125.567	0.000	3.546	-0.000	1.106
1435.800	3331.858	127.182	0.000	3.550	-0.000	1.107
1442.200	3360.883	128.290	0.000	3.550	-0.000	1.107
1448.600	3330.290	127.122	0.000	3.543	-0.000	1.105
1455.000	3299.578	125.950	0.000	3.541	-0.000	1.104
1461.400	3259.754	124.430	0.000	3.539	-0.000	1.103
1467.800	3258.404	124.378	0.000	3.544	0.000	1.105
1474.200	3288.659	125.533	0.000	3.547	-0.000	1.106
1480.600	3350.327	127.887	0.000	3.551	-0.000	1.107
1487.000	3360.864	128.289	0.000	3.547	0.000	1.106
1493.400	3328.736	127.063	0.000	3.544	0.000	1.105
1499.800	3249.450	124.037	0.000	3.540	-0.000	1.104
1506.200	3254.255	124.220	0.000	3.544	-0.000	1.105
1512.600	3286.389	125.447	0.000	3.547	-0.000	1.106
1519.000	3374.573	128.813	0.000	3.549	-0.000	1.107
1525.400	3356.838	128.136	0.000	3.547	-0.000	1.106
1531.800	3321.507	126.787	0.000	3.543	-0.000	1.105
1538.200	3245.817	123.898	0.000	3.541	-0.000	1.104
1544.600	3237.399	123.577	0.000	3.542	-0.000	1.104
1551.000	3271.448	124.876	0.000	3.546	-0.000	1.106
1557.400	3334.419	127.280	0.000	3.551	-0.000	1.107
1563.800	3346.796	127.753	0.000	3.552	-0.000	1.108
1570.200	3368.686	128.588	0.000	3.548	-0.000	1.106
1576.600	3333.285	127.237	0.000	3.545	-0.000	1.105
1583.000	3325.977	126.958	0.000	3.544	-0.000	1.105
1589.400	3258.057	124.365	0.000	3.540	-0.000	1.104
1595.800	3241.761	123.743	0.000	3.541	0.000	1.104
1602.200	3240.436	123.693	0.000	3.543	0.000	1.105
1608.600	3300.641	125.991	0.000	3.549	-0.000	1.106
1615.000	3313.772	126.492	0.000	3.550	-0.000	1.107
1621.400	3335.743	127.331	0.000	3.552	-0.000	1.108
1627.800	3375.737	128.857	0.000	3.550	0.000	1.107
1634.200	3371.693	128.703	0.000	3.551	-0.000	1.107
1640.600	3355.040	128.067	0.000	3.547	-0.000	1.106
1647.000	3324.466	126.900	0.000	3.544	-0.000	1.105
1653.400	3332.652	127.213	0.000	3.545	-0.000	1.105
1659.800	3287.482	125.488	0.000	3.541	-0.000	1.104
1666.200	3264.599	124.615	0.000	3.540	-0.000	1.104
1672.600	3262.005	124.516	0.000	3.541	-0.000	1.104
1679.000	3240.920	123.711	0.000	3.543	0.000	1.105
1685.400	3239.983	123.675	0.000	3.544	0.000	1.105
1691.800	3254.719	124.238	0.000	3.545	-0.000	1.105
1698.200	3295.507	125.795	0.000	3.549	0.000	1.107
1704.600	3285.152	125.399	0.000	3.548	0.000	1.106
1711.000	3322.395	126.821	0.000	3.551	0.000	1.107
1717.400	3364.271	128.420	0.000	3.552	0.000	1.108
1723.800	3358.416	128.196	0.000	3.553	-0.000	1.108
1730.200	3372.812	128.746	0.000	3.550	-0.000	1.107
1736.600	3351.331	127.926	0.000	3.548	-0.000	1.106
1743.000	3341.897	127.565	0.000	3.547	-0.000	1.106
1749.400	3299.383	125.943	0.000	3.543	-0.000	1.105
1755.800	3287.108	125.474	0.000	3.542	-0.000	1.104
1762.200	3261.021	124.478	0.000	3.541	-0.000	1.104
1768.600	3239.375	123.652	0.000	3.544	-0.000	1.105
1775.000	3238.780	123.629	0.000	3.543	-0.000	1.105
1781.400	3271.254	124.869	0.000	3.547	-0.000	1.106
1787.800	3310.359	126.362	0.000	3.551	-0.000	1.107
1794.200	3317.754	126.644	0.000	3.551	-0.000	1.107
1800.600	3357.527	128.162	0.000	3.553	-0.000	1.108
1807.000	3376.079	128.870	0.000	3.550	-0.000	1.107
1813.400	3374.324	128.803	0.000	3.550	-0.000	1.107
1819.800	3346.309	127.734	0.000	3.547	-0.000	1.106
1826.200	3338.567	127.438	0.000	3.547	-0.000	1.106
1832.600	3340.599	127.516	0.000	3.547	-0.000	1.106
1839.000	3325.350	126.934	0.000	3.545	-0.000	1.105
1845.400	3334.058	127.266	0.000	3.546	-0.000	1.106
1851.800	3325.575	126.942	0.000	3.545	-0.000	1.105
1858.200	3317.732	126.643	0.000	3.545	-0.000	1.105
1864.600	3325.892	126.955	0.000	3.546	0.000	1.105
1871.000	3317.793	126.645	0.000	3.545	0.000	1.105
1877.400	3309.716	126.337	0.000	3.544	0.000	1.105
1883.800	3310.972	126.385	0.000	3.544	-0.000	1.105
1890.200	3291.863	125.656	0.000	3.543	0.000	1.105
1896.600	3344.554	127.667	0.000	3.553	-0.000	1.108
1903.000	3367.061	128.526	0.000	3.552	-0.000	1.108
1909.400	3371.561	128.698	0.000	3.550	0.000	1.107
1915.800	3343.142	127.613	0.000	3.547	-0.000	1.106
1922.200	3341.225	127.540	0.000	3.547	-0.000	1.106
1928.600	3308.563	126.293	0.000	3.544	0.000	1.105
1935.000	3271.735	124.887	0.000	3.541	0.000	1.104
1941.400	3238.511	123.619	0.000	3.543	0.000	1.105
1947.800	3261.095	124.481	0.000	3.547	-0.000	1.106
1954.200	3315.123	126.543	0.000	3.551	-0.000	1.107
1960.600	3267.589	124.729	0.000	3.548	-0.000	1.106
1967.000	3315.586	126.561	0.000	3.551	-0.000	1.107
1973.400	3372.725	128.742	0.000	3.552	-0.000	1.107
1979.800	3356.641	128.128	0.000	3.549	0.000	1.106
1986.200	3302.686	126.069	0.000	3.544	-0.000	1.105
1992.600	3254.109	124.214	0.000	3.542	0.000	1.104
1999.000	3246.971	123.942	0.000	3.545	-0.000	1.105
2005.400	3320.176	126.736	0.000	3.552	-0.000	1.107
2011.800	3372.801	128.745	0.000	3.552	0.000	1.108
2018.200	3344.064	127.648	0.000	3.547	0.000	1.106
2024.600	3259.556	124.422	0.000	3.542	0.000	1.104
2031.000	3245.253	123.876	0.000	3.545	-0.000	1.105
2037.400	3299.337	125.941	0.000	3.550	-0.000	1.107
2043.800	3372.385	128.729	0.000	3.552	-0.000	1.107
2050.200	3360.257	128.266	0.000	3.549	-0.000	1.107
2056.600	3311.039	126.388	0.000	3.544	-0.000	1.105
2063.000	3257.847	124.357	0.000	3.542	0.000	1.104
2069.400	3238.386	123.614	0.000	3.544	-0.000	1.105
2075.800	3298.502	125.909	0.000	3.550	-0.000	1.107
2082.200	3343.506	127.627	0.000	3.554	-0.000	1.108
2088.600	3373.497	128.772	0.000	3.550	0.000	1.107
2095.000	3280.569	125.225	0.000	3.542	-0.000	1.104
2101.400	3238.704	123.626	0.000	3.544	-0.000	1.105
2107.800	3295.318	125.787	0.000	3.550	-0.000	1.107
2114.200	3374.391	128.806	0.000	3.551	-0.000	1.107
2120.600	3324.798	126.913	0.000	3.546	0.000	1.106
2127.000	3248.915	124.016	0.000	3.542	-0.000	1.104
2133.400	3290.589	125.607	0.000	3.549	-0.000	1.107
2139.800	3329.586	127.096	0.000	3.553	-0.000	1.108
2146.200	3370.895	128.672	0.000	3.552	-0.000	1.108
2152.600	3369.222	128.609	0.000	3.550	-0.000	1.107
2159.000	3365.883	128.481	0.000	3.550	-0.000	1.107
2165.400	3295.902	125.810	0.000	3.543	-0.000	1.105
2171.800	3289.173	125.553	0.000	3.543	-0.000	1.105
2178.200	3271.698	124.886	0.000	3.542	-0.000	1.104
2184.600	3261.124	124.482	0.000	3.547	-0.000	1.106
2191.000	3278.292	125.138	0.000	3.548	-0.000	1.106
2197.400	3320.173	126.736	0.000	3.552	-0.000	1.108
2203.800	3366.913	128.520	0.000	3.553	-0.000	1.108
2210.200	3375.519	128.849	0.000	3.551	-0.000	1.107
2216.600	3330.426	127.128	0.000	3.546	-0.000	1.106
2223.000	3290.724	125.612	0.000	3.543	-0.000	1.105
2229.400	3285.798	125.424	0.000	3.542	0.000	1.105
2235.800	3243.388	123.805	0.000	3.545	-0.000	1.105
2242.200	3281.153	125.247	0.000	3.549	-0.000	1.106
2248.600	3306.203	126.203	0.000	3.551	-0.001	1.107
2255.000	3371.562	128.698	0.000	3.552	-0.001	1.107
2261.400	3374.687	128.817	0.000	3.551	-0.001	1.107
2267.800	3337.617	127.402	0.000	3.547	0.071	1.106
2274.200	3285.339	125.407	0.000	3.542	-0.084	1.105
2280.600	3279.634	125.189	0.000	3.542	0.057	1.104
2287.000	3242.076	123.755	0.000	3.545	0.236	1.105
2293.400	3304.160	126.125	0.000	3.550	0.359	1.107
2299.800	3309.786	126.340	0.000	3.551	0.495	1.107
2306.200	3363.303	128.383	0.000	3.553	0.614	1.108
2312.600	3373.936	128.788	0.000	3.550	0.715	1.107
2319.000	3353.359	128.003	0.000	3.548	0.865	1.106
2325.400	3290.986	125.622	0.000	3.543	0.963	1.105
2331.800	3282.721	125.307	0.000	3.542	1.063	1.104
2338.200	3258.447	124.380	0.000	3.542	1.145	1.104
2344.600	3244.196	123.836	0.000	3.545	1.222	1.105
2351.000	3238.163	123.606	0.000	3.544	1.326	1.105
2357.400	3266.764	124.698	0.000	3.547	1.444	1.106
2363.800	3318.298	126.665	0.000	3.552	1.485	1.107
2370.200	3307.464	126.251	0.000	3.551	1.581	1.107
2376.600	3352.177	127.958	0.000	3.553	1.681	1.108
2383.000	3371.966	128.713	0.000	3.550	1.750	1.107
2389.400	3348.010	127.799	0.000	3.548	1.842	1.106
2395.800	3295.605	125.798	0.000	3.543	1.945	1.105
2402.200	3288.622	125.532	0.000	3.542	2.000	1.105
2408.600	3264.358	124.606	0.000	3.542	2.070	1.104
2415.000	3245.505	123.886	0.000	3.545	2.135	1.105
2421.400	3248.642	124.006	0.000	3.545	2.214	1.105
2427.800	3298.652	125.915	0.000	3.550	2.270	1.107
2434.200	3334.035	127.265	0.000	3.553	2.353	1.108
2440.600	3345.447	127.701	0.000	3.554	2.432	1.108
2447.000	3366.609	128.509	0.000	3.550	2.545	1.107
2453.400	3321.095	126.771	0.000	3.545	2.651	1.105
2459.800	3312.073	126.427	0.000	3.545	2.708	1.105
2466.200	3352.857	127.984	0.000	3.548	2.748	1.106
2472.600	3319.240	126.701	0.000	3.545	2.767	1.105
2479.000	3295.546	125.796	0.000	3.543	2.830	1.105
2485.400	3260.904	124.474	0.000	3.542	2.918	1.104
2491.800	3241.443	123.731	0.000	3.543	3.006	1.105
2498.200	3261.040	124.479	0.000	3.547	3.116	1.106
2504.600	3312.777	126.454	0.000	3.551	3.222	1.107
2511.000	3322.913	126.841	0.000	3.552	3.295	1.108
2517.400	3361.235	128.304	0.000	3.553	3.343	1.108
2523.800	3355.762	128.095	0.000	3.549	3.359	1.106
2530.200	3331.316	127.162	0.000	3.546	3.385	1.106
2536.600	3286.394	125.447	0.000	3.542	3.416	1.104
2543.000	3241.375	123.728	0.000	3.543	3.417	1.105
2549.400	3264.761	124.621	0.000	3.547	3.410	1.106
2555.800	3320.142	126.735	0.000	3.552	3.394	1.107
2562.200	3340.287	127.504	0.000	3.553	3.347	1.108
2568.600	3373.786	128.783	0.000	3.550	3.359	1.107
2575.000	3330.283	127.122	0.000	3.546	3.328	1.106
2581.400	3291.174	125.629	0.000	3.543	3.276	1.105
2587.800	3247.615	123.967	0.000	3.542	3.235	1.105
2594.200	3257.349	124.338	0.000	3.546	3.185	1.106
2600.600	3318.296	126.665	0.000	3.551	3.147	1.107
2607.000	3353.642	128.014	0.000	3.553	3.146	1.108
2613.400	3366.197	128.493	0.000	3.550	3.152	1.107
2619.800	3300.772	125.996	0.000	3.544	3.163	1.105
2626.200	3277.360	125.102	0.000	3.542	3.141	1.104
2632.600	3240.955	123.712	0.000	3.544	3.094	1.105
2639.000	3272.791	124.928	0.000	3.548	3.079	1.106
2645.400	3316.767	126.606	0.000	3.551	3.039	1.107
2651.800	3342.961	127.606	0.000	3.553	2.991	1.108
2658.200	3375.637	128.853	0.000	3.551	2.976	1.107
2664.600	3353.657	128.014	0.000	3.548	2.965	1.106
2671.000	3297.665	125.877	0.000	3.543	2.964	1.105
2677.400	3283.930	125.353	0.000	3.542	2.966	1.104
2683.800	3263.274	124.564	0.000	3.541	2.957	1.104
2690.200	3253.882	124.206	0.000	3.546	2.980	1.106
2696.600	3297.364	125.866	0.000	3.550	2.988	1.107
2703.000	3338.855	127.449	0.000	3.553	3.006	1.108
2709.400	3362.089	128.336	0.000	3.549	2.996	1.107
2715.800	3307.192	126.241	0.000	3.544	2.994	1.105
2722.200	3242.643	123.777	0.000	3.543	3.004	1.105
2728.600	3272.699	124.924	0.000	3.548	2.978	1.106
2735.000	3325.837	126.952	0.000	3.552	2.995	1.108
2741.400	3353.504	128.009	0.000	3.548	3.017	1.106
2747.800	3307.467	126.251	0.000	3.544	3.021	1.105
2754.200	3276.804	125.081	0.000	3.542	3.052	1.104
2760.600	3267.235	124.716	0.000	3.547	3.080	1.106
2767.000	3317.139	126.620	0.000	3.551	3.097	1.107
2773.400	3363.202	128.379	0.000	3.552	3.091	1.108
2779.800	3332.055	127.190	0.000	3.546	3.061	1.106
2786.200	3295.553	125.796	0.000	3.543	3.059	1.105
2792.600	3240.790	123.706	0.000	3.543	3.074	1.105
2799.000	3293.695	125.726	0.000	3.549	3.129	1.107
2805.400	3330.908	127.146	0.000	3.552	3.186	1.108
2811.800	3330.311	127.123	0.000	3.546	3.215	1.106
2818.200	3281.223	125.249	0.000	3.542	3.247	1.104
2824.600	3243.302	123.802	0.000	3.544	3.198	1.105
2831.000	3348.849	127.831	0.000	3.553	3.181	1.108
2837.400	3359.998	128.256	0.000	3.549	3.150	1.106
2843.800	3285.360	125.407	0.000	3.542	3.165	1.104
2850.200	3270.937	124.857	0.000	3.548	3.159	1.106
2856.600	3318.766	126.683	0.000	3.553	3.135	1.108
2863.000	3370.604	128.661	0.000	3.551	3.137	1.107
2869.400	3295.739	125.804	0.000	3.544	3.096	1.105
2875.800	3262.743	124.544	0.000	3.542	3.060	1.104
2882.200	3289.280	125.557	0.000	3.549	3.017	1.107
2888.600	3283.759	125.346	0.000	3.542	2.929	1.104
2895.000	3247.001	123.943	0.000	3.543	2.867	1.105
2901.400	3303.071	126.083	0.000	3.550	2.872	1.107
2907.800	3326.462	126.976	0.000	3.552	2.886	1.108
2914.200	3371.680	128.702	0.000	3.552	2.907	1.107
2920.600	3307.215	126.242	0.000	3.544	2.925	1.105
2927.000	3293.388	125.714	0.000	3.543	2.981	1.105
2933.400	3241.042	123.716	0.000	3.544	3.028	1.105
2939.800	3325.488	126.939	0.000	3.552	3.071	1.108
2946.200	3364.029	128.410	0.000	3.553	3.116	1.108
2952.600	3295.280	125.786	0.000	3.544	3.170	1.105
2959.000	3239.703	123.665	0.000	3.545	3.213	1.105
2965.400	3291.742	125.651	0.000	3.550	3.262	1.107
2971.800	3371.591	128.699	0.000	3.551	3.300	1.107
2978.200	3301.423	126.021	0.000	3.545	3.329	1.105
2984.600	3285.408	125.409	0.000	3.543	3.333	1.105
2991.000	3279.946	125.201	0.000	3.550	3.330	1.107
2997.400	3326.382	126.973	0.000	3.553	3.291	1.108
3003.800	3351.222	127.921	0.000	3.547	3.265	1.106
3010.200	3342.153	127.575	0.000	3.471	3.235	1.082
3016.600	4639.348	177.091	0.000	3.029	3.195	0.943
3023.000	6611.684	252.378	0.000	2.495	3.180	0.775
3029.400	4698.785	179.360	0.000	1.962	3.155	0.607
3035.800	3309.078	126.313	0.000	1.757	3.154	0.542
3042.200	3237.951	123.598	0.000	1.744	3.104	0.538
3048.600	3245.158	123.873	0.000	1.737	3.059	0.536
3055.000	3229.440	123.273	0.000	1.730	3.030	0.534
3061.400	2579.846	98.477	0.000	2.111	3.030	0.654
3067.800	2018.481	77.049	0.000	2.645	3.013	0.822
3074.200	2562.708	97.823	0.000	3.178	2.987	0.990
3080.600	3293.119	125.704	0.000	3.586	2.987	1.118
3087.000	3263.849	124.586	0.000	3.684	2.995	1.149
3093.400	3301.064	126.007	0.000	3.705	2.977	1.156
3099.800	3324.994	126.920	0.000	3.717	2.962	1.160
3106.200	3295.215	125.784	0.000	3.720	2.951	1.160
3112.600	3310.908	126.383	0.000	3.725	2.921	1.162
3119.000	3291.983	125.660	0.000	3.726	2.907	1.162
3125.400	3262.432	124.532	0.000	3.725	2.895	1.162
3131.800	3245.860	123.900	0.000	3.715	2.894	1.159
3138.200	3454.313	131.857	0.000	3.539	2.885	1.103
3144.600	6599.514	251.914	0.000	3.005	2.857	0.935
3151.000	5877.568	224.356	0.000	2.472	2.878	0.767
3157.400	3292.723	125.688	0.000	2.093	2.871	0.648
3163.800	3251.427	124.112	0.000	2.069	2.862	0.640
3170.200	3226.190	123.149	0.000	2.066	2.843	0.639
3176.600	3259.912	124.436	0.000	2.052	2.860	0.635
3183.000	3275.272	125.022	0.000	2.063	2.866	0.639
3189.400	3345.636	127.708	0.000	2.084	2.837	0.645
3195.800	3321.920	126.803	0.000	2.253	2.843	0.698
3202.200	3355.825	128.097	0.000	2.414	2.863	0.749
3208.600	3320.874	126.763	0.000	2.484	2.843	0.771
3215.000	3258.325	124.375	0.000	2.557	2.886	0.794
3221.400	3272.314	124.909	0.000	2.636	2.926	0.819
3227.800	3350.237	127.884	0.000	2.738	2.931	0.851
3234.200	3281.306	125.253	0.000	2.825	2.941	0.879
3240.600	3332.442	127.205	0.000	2.914	2.926	0.906
3247.000	3274.313	124.986	0.000	2.999	2.888	0.933
3253.400	3347.011	127.761	0.000	3.081	2.875	0.959
3259.800	3262.949	124.552	0.000	3.154	2.884	0.982
3266.200	3267.116	124.711	0.000	3.236	2.851	1.008
3272.600	3342.902	127.604	0.000	3.316	2.849	1.033
3279.000	3303.823	126.112	0.000	3.377	2.873	1.052
3285.400	3237.109	123.566	0.000	3.445	2.869	1.074
3291.800	3307.548	126.254	0.000	3.518	2.863	1.097
3298.200	3349.307	127.848	0.000	3.577	2.846	1.115
3301.340	3356.890	128.138	0.000	3.606	2.841	1.125