File: documentation/exampledata/NiTiPd_Characterization.txt
""
"Test Method","SMA-CFTC.msm"
"Sample I. D.","Sample89.mss"
"Specimen Number","1"

"Time (h)","Load (N)","Crosshead (in)","Temperature Chamber (C)","Extension (mm)","Stress (MPa)"

0.001,3.737,0.00015,49.20,-0.259,8.193
0.005,4.091,0.00171,49.80,-0.219,8.970
0.009,4.288,0.00328,49.90,-0.179,9.402
0.014,4.523,0.00486,50.00,-0.139,9.918
0.018,5.029,0.00644,50.10,-0.099,11.028
0.023,5.733,0.00801,50.00,-0.059,12.571
0.027,6.573,0.00959,49.80,-0.019,14.412
0.032,7.840,0.01117,49.60,0.021,17.192
0.036,9.386,0.01273,49.60,0.061,20.581
0.041,11.793,0.01430,49.60,0.101,25.860
0.045,14.723,0.01589,49.50,0.141,32.284
0.049,18.114,0.01746,49.70,0.181,39.721
0.054,21.723,0.01904,49.60,0.221,47.634
0.058,25.453,0.02061,49.70,0.261,55.813
0.063,29.426,0.02218,49.70,0.301,64.527
0.067,33.341,0.02376,49.90,0.341,73.111
0.072,37.255,0.02533,49.90,0.381,81.694
0.076,41.089,0.02691,49.90,0.421,90.101
0.081,44.980,0.02848,49.90,0.461,98.632
0.085,48.904,0.03006,50.00,0.501,107.237
0.089,52.704,0.03163,50.00,0.541,115.569
0.094,56.538,0.03320,50.00,0.581,123.977
0.098,60.216,0.03478,49.90,0.621,132.043
0.103,63.960,0.03635,49.90,0.661,140.253
0.107,67.624,0.03793,49.90,0.701,148.285
0.112,71.237,0.03950,49.90,0.741,156.209
0.116,74.908,0.04108,49.90,0.781,164.258
0.121,78.438,0.04265,49.90,0.821,171.999
0.125,82.019,0.04422,49.90,0.861,179.852
0.129,85.555,0.04580,49.90,0.901,187.606
0.134,89.057,0.04737,49.90,0.941,195.285
0.138,91.195,0.04843,49.90,0.967,199.974
0.143,91.189,0.04846,49.90,0.968,199.959
0.147,91.184,0.04850,49.90,0.969,199.949
0.152,91.196,0.04852,50.00,0.970,199.975
0.156,91.176,0.04854,49.90,0.970,199.932
0.161,91.228,0.04860,49.90,0.972,200.045
0.165,91.179,0.04860,49.90,0.972,199.937
0.169,91.203,0.04863,49.90,0.973,199.990
0.174,91.194,0.04865,49.90,0.973,199.972
0.178,91.205,0.04867,49.90,0.974,199.995
0.183,91.180,0.04868,49.90,0.974,199.941
0.187,91.207,0.04872,49.80,0.975,199.999
0.192,91.184,0.04879,49.60,0.977,199.948
0.196,91.182,0.04887,49.30,0.979,199.944
0.201,91.189,0.04896,49.10,0.981,199.959
0.205,91.194,0.04906,48.80,0.983,199.971
0.209,91.186,0.04915,48.60,0.986,199.954
0.214,91.182,0.04924,48.40,0.988,199.945
0.218,91.196,0.04935,48.10,0.991,199.974
0.223,91.187,0.04945,47.80,0.993,199.955
0.227,91.189,0.04956,47.60,0.996,199.960
0.232,91.198,0.04966,47.30,0.999,199.979
0.236,91.179,0.04977,47.10,1.002,199.939
0.241,91.181,0.04989,46.80,1.005,199.942
0.245,91.177,0.05000,46.50,1.008,199.933
0.249,91.171,0.05014,46.30,1.011,199.920
0.254,91.198,0.05026,46.00,1.014,199.978
0.258,91.163,0.05041,45.70,1.018,199.902
0.263,91.181,0.05056,45.40,1.022,199.942
0.267,91.180,0.05072,45.10,1.026,199.940
0.272,91.167,0.05087,44.80,1.030,199.912
0.276,91.196,0.05105,44.40,1.034,199.975
0.281,91.175,0.05123,44.10,1.039,199.930
0.285,91.180,0.05144,43.70,1.044,199.941
0.289,91.183,0.05164,43.40,1.049,199.947
0.294,91.189,0.05185,43.00,1.055,199.959
0.298,91.177,0.05208,42.60,1.060,199.934
0.303,91.174,0.05230,42.20,1.066,199.926
0.307,91.153,0.05254,41.80,1.072,199.882
0.312,91.154,0.05278,41.30,1.078,199.883
0.316,91.189,0.05305,40.90,1.085,199.960
0.321,91.166,0.05333,40.50,1.092,199.910
0.325,91.174,0.05360,40.10,1.099,199.928
0.329,91.161,0.05391,39.60,1.107,199.898
0.334,91.156,0.05420,39.20,1.114,199.888
0.338,91.173,0.05453,38.70,1.122,199.925
0.343,91.183,0.05483,38.20,1.130,199.947
0.347,91.172,0.05515,37.80,1.138,199.923
0.352,91.181,0.05548,37.40,1.147,199.942
0.356,91.125,0.05579,36.90,1.155,199.820
0.361,91.169,0.05609,36.50,1.162,199.917
0.365,91.182,0.05643,36.00,1.171,199.944
0.369,91.146,0.05679,35.60,1.180,199.866
0.374,91.149,0.05720,35.10,1.190,199.872
0.378,91.156,0.05759,34.60,1.200,199.887
0.383,91.152,0.05807,34.10,1.212,199.878
0.387,91.148,0.05854,33.60,1.224,199.870
0.392,91.145,0.05907,33.10,1.238,199.864
0.396,91.170,0.05970,32.40,1.254,199.919
0.401,91.119,0.06031,31.90,1.269,199.805
0.405,91.028,0.06139,31.00,1.297,199.607
0.409,90.977,0.06351,29.80,1.351,199.494
0.414,90.968,0.06622,28.20,1.419,199.476
0.418,90.973,0.06758,27.10,1.454,199.486
0.423,91.156,0.06979,25.50,1.510,199.888
0.427,90.905,0.07192,24.20,1.564,199.338
0.432,90.970,0.07350,23.10,1.604,199.479
0.436,91.202,0.07559,21.70,1.658,199.989
0.441,90.853,0.07706,20.80,1.695,199.223
0.445,91.064,0.07873,19.80,1.737,199.686
0.449,91.115,0.08213,18.60,1.823,199.798
0.454,90.642,0.08369,17.70,1.863,198.760
0.458,90.970,0.08596,16.80,1.921,199.479
0.463,90.945,0.08978,15.70,2.018,199.426
0.467,91.083,0.09346,14.60,2.111,199.728
0.472,90.853,0.09544,13.90,2.162,199.224
0.476,90.986,0.09942,12.80,2.263,199.515
0.481,90.886,0.10305,12.00,2.355,199.295
0.485,90.961,0.10523,11.20,2.410,199.460
0.489,90.591,0.10920,10.40,2.511,198.649
0.494,90.580,0.11271,9.70,2.600,198.625
0.498,90.768,0.11672,8.90,2.702,199.037
0.503,90.572,0.12283,8.00,2.857,198.608
0.507,91.127,0.12788,7.20,2.986,199.824
0.512,90.915,0.13073,6.70,3.058,199.360
0.516,90.495,0.13619,6.00,3.197,198.437
0.521,90.873,0.14133,5.30,3.327,199.266
0.525,90.480,0.14524,4.70,3.426,198.405
0.529,90.823,0.15420,3.80,3.654,199.156
0.534,90.518,0.15629,3.50,3.707,198.489
0.538,90.173,0.16186,2.70,3.849,197.731
0.543,90.948,0.16739,2.10,3.989,199.431
0.547,90.915,0.17055,1.70,4.069,199.359
0.552,90.820,0.17420,1.10,4.162,199.152
0.556,90.817,0.17901,0.60,4.284,199.144
0.561,90.339,0.18500,-0.30,4.437,198.096
0.565,91.000,0.18904,-0.80,4.539,199.545
0.569,90.836,0.19238,-1.30,4.624,199.186
0.574,90.754,0.19463,0.00,4.681,199.006
0.578,90.982,0.19885,-2.30,4.788,199.506
0.583,90.830,0.20173,0.00,4.861,199.173
0.587,91.027,0.20399,-3.00,4.919,199.605
0.592,90.864,0.20754,-3.60,5.009,199.247
0.596,90.935,0.20989,-4.00,5.069,199.402
0.601,91.046,0.21276,-4.50,5.142,199.646
0.605,91.155,0.21452,-4.70,5.186,199.885
0.609,91.048,0.21674,-5.30,5.243,199.650
0.614,91.099,0.21915,-5.70,5.304,199.762
0.618,90.876,0.22103,-6.10,5.352,199.272
0.623,91.119,0.22316,-6.60,5.406,199.807
0.627,91.082,0.22460,-6.90,5.442,199.726
0.632,91.084,0.22638,-7.30,5.488,199.730
0.636,90.971,0.22825,-7.60,5.535,199.481
0.641,91.138,0.22950,-8.00,5.567,199.848
0.645,90.991,0.23093,-8.20,5.603,199.525
0.649,91.121,0.23220,-8.60,5.635,199.811
0.654,90.788,0.23443,-9.10,5.692,199.080
0.658,91.016,0.23704,-9.70,5.758,199.579
0.663,91.022,0.23898,-10.10,5.807,199.594
0.667,91.003,0.24061,-10.60,5.849,199.551
0.672,91.086,0.24179,-10.80,5.879,199.735
0.676,91.159,0.24310,-11.10,5.912,199.893
0.681,91.048,0.24476,-11.50,5.954,199.651
0.685,91.112,0.24627,-11.90,5.993,199.791
0.689,91.080,0.24792,-12.30,6.035,199.720
0.694,90.999,0.25005,-13.00,6.089,199.542
0.698,90.908,0.25130,-13.20,6.120,199.343
0.703,90.978,0.25277,-13.60,6.158,199.498
0.707,91.148,0.25444,-14.10,6.200,199.870
0.712,90.946,0.25617,-14.60,6.244,199.428
0.716,91.066,0.25731,-14.80,6.273,199.691
0.721,91.032,0.25938,-15.50,6.326,199.616
0.725,91.005,0.26102,-16.00,6.367,199.557
0.729,91.151,0.26239,-16.40,6.402,199.877
0.734,90.907,0.26417,-17.00,6.447,199.342
0.738,90.953,0.26572,-17.40,6.487,199.442
0.743,91.115,0.26676,-17.80,6.513,199.797
0.747,91.053,0.26837,-18.40,6.554,199.661
0.752,91.135,0.27006,-18.90,6.597,199.842
0.756,91.167,0.27195,-19.60,6.645,199.912
0.761,91.167,0.27354,-20.20,6.685,199.911
0.765,91.100,0.27478,-20.60,6.717,199.764
0.769,91.162,0.27574,-21.00,6.741,199.901
0.774,91.063,0.27717,-21.60,6.778,199.683
0.778,91.164,0.27869,-22.30,6.816,199.905
0.783,91.052,0.27964,-22.70,6.840,199.659
0.787,91.020,0.28077,-23.20,6.869,199.589
0.792,91.100,0.28187,-23.80,6.897,199.764
0.796,91.008,0.28317,-24.50,6.930,199.564
0.801,91.142,0.28423,-25.10,6.957,199.856
0.805,91.169,0.28474,-25.30,6.970,199.915
0.809,91.055,0.28521,-25.50,6.982,199.666
0.814,91.174,0.28600,-25.90,7.002,199.928
0.818,91.099,0.28663,-26.20,7.018,199.762
0.823,91.163,0.28749,-26.80,7.040,199.902
0.827,91.085,0.28799,-27.00,7.052,199.731
0.832,91.142,0.28852,-27.30,7.066,199.856
0.836,91.105,0.28936,-27.80,7.087,199.775
0.841,91.232,0.29022,-28.40,7.109,200.053
0.845,91.145,0.29074,-28.60,7.122,199.863
0.849,91.084,0.29144,-29.00,7.140,199.730
0.854,91.039,0.29207,-29.40,7.156,199.631
0.858,91.143,0.29294,-30.00,7.178,199.858
0.863,91.176,0.29348,-30.40,7.192,199.932
0.867,91.158,0.29437,-30.90,7.214,199.891
0.872,91.161,0.29515,-31.40,7.234,199.899
0.876,91.097,0.29573,-31.70,7.249,199.758
0.881,91.205,0.29637,-32.20,7.265,199.995
0.885,91.134,0.29681,-32.40,7.276,199.840
0.889,91.020,0.29752,-32.90,7.294,199.590
0.894,91.049,0.29825,-33.40,7.313,199.652
0.898,91.183,0.29885,-33.90,7.328,199.946
0.903,91.173,0.29928,-34.20,7.339,199.926
0.907,91.078,0.30000,-34.70,7.357,199.716
0.912,91.235,0.30069,-35.30,7.375,200.060
0.916,91.098,0.30141,-35.80,7.393,199.760
0.921,91.102,0.30203,-36.40,7.409,199.769
0.925,91.130,0.30238,-36.60,7.418,199.831
0.929,91.180,0.30316,-37.40,7.438,199.941
0.934,91.049,0.30376,-37.80,7.453,199.654
0.938,91.145,0.30430,-38.30,7.467,199.864
0.943,91.217,0.30486,-38.80,7.481,200.020
0.947,91.230,0.30539,-39.20,7.494,200.051
0.952,91.068,0.30591,-39.70,7.507,199.695
0.956,91.083,0.30656,-40.30,7.524,199.728
0.961,91.209,0.30711,-40.90,7.538,200.004
0.965,91.075,0.30749,-41.10,7.548,199.710
0.969,91.026,0.30798,-41.70,7.560,199.602
0.974,91.097,0.30883,-42.40,7.582,199.758
0.978,91.217,0.30927,-43.00,7.593,200.022
0.983,91.161,0.30977,-43.50,7.606,199.899
0.987,91.123,0.31038,-44.10,7.621,199.816
0.992,91.154,0.31086,-44.60,7.633,199.884
0.996,91.226,0.31091,-44.60,7.634,200.042
1.001,91.162,0.31063,-44.40,7.627,199.901
1.005,91.139,0.31076,-44.00,7.631,199.849
1.009,90.906,0.31117,-44.40,7.641,199.340
1.014,91.632,0.31110,-45.00,7.639,200.931
1.018,91.090,0.31121,-43.70,7.642,199.742
1.023,91.593,0.31063,-43.10,7.627,200.845
1.027,90.873,0.31012,-41.30,7.615,199.266
1.032,91.306,0.31020,-40.70,7.617,200.216
1.036,91.019,0.30929,-39.50,7.593,199.587
1.041,90.572,0.30938,-38.40,7.596,198.606
1.045,91.551,0.30915,-37.80,7.590,200.755
1.049,91.397,0.30810,-36.30,7.563,200.415
1.054,90.882,0.30851,-35.30,7.574,199.287
1.058,91.506,0.30787,-34.70,7.557,200.654
1.063,91.437,0.30696,-33.30,7.534,200.504
1.067,91.007,0.30674,-32.00,7.529,199.561
1.072,91.398,0.30624,-31.20,7.516,200.417
1.076,90.947,0.30569,-30.00,7.502,199.430
1.081,91.379,0.30548,-29.10,7.497,200.377
1.085,91.326,0.30484,-28.20,7.480,200.260
1.089,91.335,0.30429,-26.90,7.466,200.280
1.094,91.257,0.30375,-25.80,7.453,200.108
1.098,91.285,0.30335,-24.90,7.443,200.169
1.103,91.262,0.30270,-23.80,7.426,200.121
1.107,91.265,0.30228,-22.90,7.415,200.127
1.112,91.253,0.30183,-21.90,7.404,200.100
1.116,91.244,0.30131,-21.00,7.391,200.081
1.121,91.268,0.30083,-20.10,7.378,200.133
1.125,91.259,0.30030,-19.20,7.365,200.112
1.129,91.252,0.29980,-18.40,7.352,200.098
1.134,91.240,0.29925,-17.40,7.338,200.071
1.138,91.279,0.29864,-16.60,7.323,200.157
1.143,91.261,0.29800,-15.60,7.307,200.118
1.147,91.272,0.29734,-14.80,7.290,200.141
1.152,91.263,0.29646,-13.70,7.268,200.123
1.156,91.292,0.29576,-12.70,7.250,200.185
1.161,91.352,0.29478,-11.80,7.225,200.318
1.165,91.348,0.29378,-10.80,7.199,200.309
1.169,91.320,0.29279,-9.80,7.174,200.248
1.174,91.312,0.29165,-8.70,7.145,200.229
1.178,91.349,0.29061,-7.70,7.119,200.310
1.183,91.300,0.28941,-6.50,7.088,200.202
1.187,91.348,0.28818,-5.50,7.057,200.308
1.192,91.270,0.28690,-4.40,7.025,200.137
1.196,91.313,0.28558,-3.40,6.991,200.232
1.201,91.394,0.28415,-2.30,6.955,200.409
1.205,91.350,0.28277,-1.20,6.920,200.313
1.209,91.400,0.28113,-0.20,6.878,200.423
1.214,91.398,0.27931,0.90,6.832,200.419
1.218,91.439,0.27733,1.90,6.782,200.508
1.223,91.386,0.27510,3.10,6.725,200.391
1.227,91.493,0.27293,4.10,6.670,200.626
1.232,91.509,0.27035,5.10,6.604,200.662
1.236,91.495,0.26756,6.20,6.533,200.630
1.241,91.564,0.26446,7.20,6.455,200.782
1.245,91.503,0.26118,8.30,6.371,200.648
1.249,91.651,0.25781,9.50,6.286,200.973
1.254,91.475,0.25431,10.50,6.197,200.586
1.258,91.714,0.25017,11.60,6.092,201.111
1.263,91.725,0.24555,12.70,5.974,201.136
1.267,91.695,0.24082,13.70,5.854,201.069
1.272,91.772,0.23530,14.90,5.714,201.237
1.276,91.759,0.22944,15.80,5.565,201.210
1.281,91.903,0.22269,17.00,5.394,201.526
1.285,91.960,0.21575,18.00,5.217,201.650
1.289,91.991,0.20872,19.10,5.039,201.719
1.294,92.109,0.20127,20.00,4.850,201.976
1.298,91.938,0.19284,21.20,4.636,201.601
1.303,91.889,0.18477,22.30,4.431,201.494
1.307,91.983,0.17751,23.30,4.246,201.700
1.312,91.830,0.17074,24.50,4.074,201.366
1.316,91.877,0.16486,25.40,3.925,201.468
1.321,91.743,0.15885,26.50,3.772,201.174
1.325,91.834,0.15175,27.70,3.592,201.374
1.329,91.501,0.14787,28.60,3.493,200.643
1.334,91.762,0.14354,29.60,3.383,201.216
1.338,91.790,0.13689,30.90,3.214,201.278
1.343,91.470,0.13351,32.10,3.129,200.576
1.347,91.687,0.13028,32.90,3.047,201.051
1.352,91.684,0.12601,34.10,2.938,201.046
1.356,91.564,0.12254,35.00,2.850,200.783
1.361,91.560,0.11917,36.20,2.764,200.773
1.365,91.415,0.11640,37.20,2.694,200.456
1.369,91.532,0.11307,38.30,2.610,200.713
1.374,91.752,0.11307,39.40,2.610,201.194
1.378,91.356,0.10985,40.50,2.528,200.325
1.383,91.459,0.10772,41.50,2.473,200.552
1.387,91.470,0.10506,42.50,2.406,200.576
1.392,91.395,0.10269,43.60,2.346,200.412
1.396,91.326,0.10056,44.70,2.292,200.261
1.401,91.516,0.09857,45.60,2.241,200.676
1.405,91.529,0.09597,46.90,2.175,200.706
1.409,91.364,0.09387,48.00,2.122,200.344
1.414,91.344,0.09226,48.90,2.081,200.301
1.418,91.348,0.09111,49.40,2.052,200.309
1.423,91.190,0.09037,50.10,2.033,199.962
1.427,91.311,0.09005,50.10,2.025,200.226
1.432,91.239,0.09040,50.00,2.034,200.069
1.436,91.149,0.08974,49.90,2.017,199.872
1.441,91.205,0.08980,49.70,2.018,199.994
1.445,91.188,0.08998,49.20,2.023,199.957
1.449,91.196,0.08982,49.00,2.019,199.976
1.454,91.231,0.08966,49.00,2.015,200.051
1.458,91.241,0.08952,48.80,2.011,200.074
1.463,91.189,0.08934,48.90,2.007,199.960
1.467,91.196,0.08939,48.70,2.008,199.976
1.472,91.248,0.08902,48.80,1.998,200.089
1.476,91.173,0.08894,48.90,1.997,199.925
1.480,68.499,0.07253,48.80,1.580,150.204
1.485,68.415,0.07173,48.90,1.559,150.022
1.489,68.322,0.07194,48.40,1.565,149.817
1.494,68.342,0.07239,47.20,1.576,149.861
1.498,68.386,0.07276,46.30,1.586,149.958
1.503,68.380,0.07311,45.40,1.594,149.945
1.507,68.359,0.07348,44.50,1.604,149.897
1.511,68.348,0.07387,43.60,1.614,149.875
1.516,68.351,0.07428,42.80,1.624,149.880
1.520,68.331,0.07476,41.90,1.636,149.836
1.525,68.344,0.07532,40.90,1.651,149.866
1.529,68.330,0.07587,40.00,1.665,149.833
1.534,68.261,0.07655,38.90,1.682,149.682
1.538,68.322,0.07726,37.90,1.700,149.817
1.543,68.320,0.07807,36.80,1.720,149.812
1.547,68.293,0.07902,35.60,1.745,149.752
1.551,68.299,0.07987,34.50,1.766,149.767
1.556,68.301,0.08085,33.30,1.791,149.771
1.560,68.137,0.08267,31.90,1.837,149.411
1.565,67.292,0.08501,30.00,1.897,147.559
1.569,69.026,0.08456,29.00,1.885,151.361
1.574,67.971,0.08690,28.30,1.945,149.047
1.578,70.174,0.09054,25.40,2.037,153.879
1.583,68.248,0.08765,26.20,1.964,149.654
1.587,68.691,0.09772,23.70,2.220,150.625
1.591,67.860,0.09133,24.30,2.057,148.803
1.596,71.017,0.09965,21.10,2.268,155.727
1.600,65.296,0.09467,22.10,2.142,143.181
1.605,72.003,0.10611,18.80,2.433,157.888
1.609,66.713,0.10087,20.50,2.300,146.288
1.614,71.980,0.10428,17.50,2.386,157.837
1.618,66.867,0.11244,15.90,2.593,146.627
1.623,66.718,0.10613,16.70,2.433,146.299
1.627,70.164,0.11461,14.90,2.648,153.857
1.631,62.714,0.11855,15.10,2.749,137.521
1.636,71.453,0.11952,13.10,2.773,156.682
1.640,73.345,0.12495,11.20,2.911,160.831
1.645,65.593,0.13146,11.10,3.077,143.833
1.649,68.719,0.14263,8.30,3.360,150.688
1.654,66.440,0.13294,9.40,3.114,145.691
1.658,66.528,0.13969,8.70,3.286,145.882
1.663,71.692,0.15417,5.40,3.653,157.207
1.667,67.012,0.15081,6.50,3.568,146.944
1.671,65.777,0.15891,4.90,3.774,144.236
1.676,67.733,0.17122,3.70,4.086,148.525
1.680,67.883,0.17789,2.00,4.256,148.854
1.685,67.761,0.17787,1.80,4.255,148.586
1.689,66.406,0.18355,0.20,4.400,145.616
1.694,64.241,0.19016,-0.60,4.568,140.867
1.698,67.710,0.19439,-1.40,4.675,148.475
1.703,67.050,0.20064,-2.70,4.834,147.028
1.707,67.291,0.20569,-3.50,4.962,147.555
1.711,69.395,0.21428,-5.40,5.180,152.169
1.716,66.796,0.21968,-6.30,5.317,146.470
1.720,67.539,0.22085,-6.50,5.347,148.099
1.725,66.814,0.22598,-7.70,5.477,146.511
1.729,67.838,0.22811,-8.70,5.531,148.755
1.734,67.723,0.23490,-10.40,5.704,148.503
1.738,68.277,0.23547,-11.40,5.718,149.719
1.743,67.492,0.23902,-12.40,5.809,147.998
1.747,68.777,0.24168,-13.50,5.876,150.815
1.751,69.175,0.24731,-15.00,6.019,151.687
1.756,67.826,0.24870,-15.40,6.055,148.730
1.760,68.159,0.25154,-16.70,6.126,149.459
1.765,68.174,0.25404,-17.60,6.190,149.492
1.769,67.952,0.25703,-18.70,6.266,149.005
1.774,69.036,0.25865,-20.10,6.307,151.383
1.778,67.904,0.26032,-20.50,6.350,148.900
1.783,67.991,0.26281,-21.60,6.413,149.091
1.787,69.473,0.26518,-23.40,6.473,152.340
1.791,67.641,0.26742,-24.00,6.530,148.324
1.796,68.517,0.26894,-25.00,6.569,150.244
1.800,68.022,0.27034,-25.60,6.604,149.160
1.805,68.131,0.27312,-27.50,6.675,149.397
1.809,68.227,0.27390,-28.00,6.695,149.608
1.814,68.074,0.27550,-29.10,6.735,149.272
1.818,68.054,0.27737,-30.30,6.783,149.229
1.823,68.082,0.27816,-31.00,6.803,149.291
1.827,67.977,0.28051,-32.60,6.862,149.060
1.831,68.386,0.28113,-33.10,6.878,149.958
1.836,68.111,0.28288,-34.60,6.923,149.353
1.840,68.211,0.28415,-35.70,6.955,149.574
1.845,68.240,0.28504,-36.50,6.977,149.637
1.849,68.371,0.28627,-37.70,7.009,149.924
1.854,68.273,0.28732,-38.90,7.035,149.710
1.858,68.380,0.28811,-39.80,7.055,149.943
1.863,68.229,0.28910,-40.60,7.081,149.614
1.867,68.279,0.28995,-41.50,7.102,149.724
1.871,68.334,0.29078,-42.30,7.123,149.843
1.876,68.283,0.29168,-43.20,7.146,149.730
1.880,68.245,0.29235,-44.10,7.163,149.648
1.885,68.775,0.29312,-45.00,7.183,150.811
1.889,68.269,0.29320,-44.80,7.185,149.702
1.894,68.420,0.29354,-45.00,7.193,150.032
1.898,68.323,0.29384,-45.00,7.201,149.820
1.903,68.110,0.29389,-44.70,7.202,149.353
1.907,68.369,0.29391,-44.90,7.203,149.919
1.911,68.406,0.29409,-44.90,7.207,150.002
1.916,68.875,0.29433,-45.10,7.214,151.029
1.920,68.208,0.29441,-45.00,7.215,149.568
1.925,68.169,0.29387,-44.40,7.202,149.482
1.929,68.910,0.29409,-44.70,7.207,151.107
1.934,68.201,0.29371,-43.10,7.198,149.551
1.938,68.786,0.29341,-42.60,7.190,150.834
1.943,68.165,0.29304,-41.10,7.181,149.473
1.947,68.711,0.29267,-40.50,7.171,150.669
1.951,68.178,0.29220,-39.00,7.159,149.501
1.956,68.679,0.29206,-38.50,7.156,150.599
1.960,68.158,0.29131,-36.90,7.137,149.457
1.965,68.693,0.29138,-36.40,7.139,150.631
1.969,68.189,0.29055,-34.80,7.117,149.524
1.974,68.656,0.29056,-34.20,7.118,150.549
1.978,68.466,0.28965,-32.80,7.095,150.133
1.983,68.443,0.28969,-31.90,7.096,150.081
1.987,68.576,0.28881,-30.80,7.073,150.373
1.991,68.127,0.28842,-29.60,7.063,149.389
1.996,68.604,0.28812,-28.80,7.056,150.436
2.000,68.486,0.28731,-27.50,7.035,150.177
2.005,68.185,0.28680,-26.40,7.022,149.516
2.009,68.556,0.28652,-25.50,7.015,150.330
2.014,68.504,0.28591,-24.50,7.000,150.217
2.018,68.520,0.28526,-23.50,6.983,150.252
2.023,68.547,0.28458,-22.30,6.966,150.310
2.027,68.505,0.28396,-21.30,6.950,150.218
2.031,68.440,0.28315,-20.00,6.930,150.076
2.036,68.493,0.28259,-19.10,6.915,150.191
2.040,68.475,0.28180,-18.10,6.895,150.153
2.045,68.478,0.28116,-17.20,6.879,150.158
2.049,68.476,0.28037,-16.30,6.859,150.154
2.054,68.475,0.27963,-15.40,6.840,150.153
2.058,68.496,0.27880,-14.60,6.819,150.199
2.063,68.478,0.27791,-13.70,6.796,150.159
2.067,68.500,0.27697,-12.70,6.773,150.207
2.071,68.504,0.27600,-11.80,6.748,150.217
2.076,68.538,0.27501,-10.90,6.723,150.290
2.080,68.526,0.27369,-10.00,6.689,150.264
2.085,68.490,0.27246,-9.00,6.658,150.184
2.089,68.590,0.27121,-8.10,6.626,150.405
2.094,68.539,0.26969,-7.00,6.587,150.293
2.098,68.571,0.26814,-6.00,6.548,150.364
2.103,68.595,0.26657,0.00,6.508,150.415
2.107,68.634,0.26460,-3.90,6.458,150.500
2.111,68.592,0.26252,-3.00,6.405,150.409
2.116,68.671,0.26034,-1.90,6.350,150.583
2.120,68.663,0.25775,-0.90,6.284,150.564
2.125,68.744,0.25492,0.20,6.212,150.742
2.129,68.736,0.25178,1.30,6.133,150.724
2.134,68.758,0.24811,2.20,6.040,150.773
2.138,68.800,0.24406,3.40,5.936,150.866
2.143,68.857,0.24007,4.40,5.835,150.991
2.147,68.914,0.23526,5.60,5.713,151.115
2.151,68.922,0.23046,6.50,5.591,151.132
2.156,69.125,0.22443,7.60,5.438,151.578
2.160,68.996,0.21756,8.80,5.263,151.295
2.165,69.050,0.21150,9.70,5.109,151.412
2.169,69.355,0.20332,10.90,4.902,152.082
2.174,69.121,0.19580,11.90,4.711,151.568
2.178,69.381,0.18789,13.10,4.510,152.140
2.183,69.130,0.18062,14.00,4.325,151.589
2.187,69.147,0.17326,15.20,4.138,151.627
2.191,69.124,0.16628,16.30,3.961,151.575
2.196,69.072,0.16005,17.30,3.803,151.462
2.200,68.969,0.15386,18.40,3.646,151.236
2.205,68.859,0.14870,19.40,3.514,150.995
2.209,68.822,0.14376,20.50,3.389,150.913
2.214,68.835,0.13954,21.30,3.282,150.941
2.218,68.957,0.13331,22.70,3.124,151.210
2.223,68.726,0.12974,23.80,3.033,150.703
2.227,68.796,0.12618,24.80,2.942,150.856
2.231,68.750,0.12247,25.90,2.848,150.756
2.236,68.776,0.11914,26.80,2.764,150.811
2.240,68.777,0.11576,28.00,2.678,150.816
2.245,68.712,0.11268,29.10,2.600,150.672
2.249,68.630,0.11025,30.00,2.538,150.491
2.254,68.684,0.10694,31.20,2.454,150.611
2.258,68.588,0.10446,32.30,2.391,150.400
2.263,68.721,0.10248,33.30,2.341,150.692
2.267,68.712,0.10021,34.20,2.283,150.672
2.271,68.647,0.09779,35.50,2.221,150.529
2.276,68.606,0.09572,36.50,2.169,150.441
2.280,68.564,0.09390,37.60,2.122,150.347
2.285,68.620,0.09204,38.70,2.075,150.469
2.289,68.524,0.09039,39.70,2.033,150.260
2.294,68.529,0.08890,40.80,1.995,150.271
2.298,68.579,0.08728,41.80,1.954,150.381
2.303,68.544,0.08579,43.00,1.916,150.304
2.307,68.583,0.08478,43.70,1.891,150.389
2.311,68.542,0.08290,45.20,1.843,150.299
2.316,68.483,0.08177,46.20,1.814,150.171
2.320,68.522,0.08061,47.20,1.785,150.256
2.325,68.596,0.07931,48.30,1.752,150.418
2.329,68.468,0.07838,49.20,1.728,150.138
2.334,68.464,0.07790,49.70,1.716,150.129
2.338,68.438,0.07748,50.00,1.705,150.071
2.342,61.001,0.07293,50.20,1.590,133.763
2.347,46.082,0.06271,50.50,1.330,101.048
2.351,45.661,0.06137,50.50,1.296,100.126
2.356,45.630,0.06086,50.60,1.283,100.057
2.360,45.607,0.06058,50.50,1.276,100.007
2.364,45.604,0.06039,50.40,1.271,100.000
2.369,45.641,0.06013,50.50,1.265,100.083
2.373,45.618,0.06002,50.40,1.262,100.031
2.378,45.552,0.06024,49.80,1.268,99.887
2.382,45.575,0.06046,48.90,1.273,99.938
2.387,45.582,0.06062,48.10,1.277,99.953
2.391,45.619,0.06079,47.30,1.281,100.033
2.396,45.553,0.06093,46.50,1.285,99.889
2.400,45.592,0.06112,45.70,1.290,99.974
2.404,45.577,0.06132,45.00,1.295,99.942
2.409,45.580,0.06152,44.20,1.300,99.948
2.413,45.591,0.06172,43.40,1.305,99.973
2.418,45.563,0.06193,42.70,1.310,99.910
2.422,45.588,0.06215,41.90,1.316,99.966
2.427,45.567,0.06242,41.30,1.323,99.920
2.431,45.566,0.06263,40.50,1.328,99.918
2.436,45.582,0.06288,39.90,1.335,99.953
2.440,45.588,0.06315,39.20,1.342,99.967
2.444,45.627,0.06339,38.40,1.348,100.050
2.449,45.581,0.06369,37.80,1.355,99.951
2.453,45.582,0.06402,37.10,1.363,99.953
2.458,45.573,0.06434,36.40,1.372,99.933
2.462,45.571,0.06474,35.60,1.382,99.927
2.467,45.558,0.06513,34.90,1.392,99.900
2.471,45.577,0.06558,34.10,1.403,99.940
2.476,45.558,0.06598,33.20,1.413,99.900
2.480,45.570,0.06644,32.50,1.425,99.925
2.484,45.546,0.06698,31.60,1.439,99.875
2.489,45.523,0.06756,30.80,1.453,99.823
2.493,45.507,0.06826,29.80,1.471,99.788
2.498,45.355,0.06948,28.80,1.502,99.455
2.502,45.315,0.07129,27.00,1.548,99.368
2.507,45.516,0.07327,24.80,1.599,99.808
2.511,45.500,0.07452,23.40,1.630,99.773
2.516,45.529,0.07635,21.60,1.677,99.836
2.520,45.478,0.07783,20.00,1.714,99.724
2.524,45.471,0.07967,18.40,1.761,99.708
2.529,45.573,0.08063,17.50,1.785,99.933
2.533,46.171,0.08160,16.30,1.810,101.244
2.538,45.342,0.08434,15.20,1.880,99.425
2.542,45.562,0.08503,14.20,1.897,99.909
2.547,45.388,0.08552,13.50,1.910,99.527
2.551,45.130,0.08756,12.50,1.961,98.961
2.556,45.189,0.08956,11.20,2.012,99.092
2.560,45.226,0.09147,10.20,2.061,99.172
2.564,45.314,0.09459,9.00,2.140,99.365
2.569,45.626,0.09562,8.00,2.166,100.048
2.573,45.411,0.09822,6.80,2.232,99.577
2.578,45.283,0.09950,6.00,2.265,99.298
2.582,45.315,0.10340,4.70,2.364,99.368
2.587,45.351,0.10484,3.90,2.400,99.446
2.591,45.450,0.10728,3.00,2.462,99.664
2.596,45.251,0.11092,2.10,2.555,99.226
2.600,45.411,0.11261,1.30,2.598,99.578
2.604,45.253,0.11513,0.40,2.662,99.230
2.609,45.414,0.11961,-0.60,2.776,99.584
2.613,45.368,0.12304,-1.30,2.863,99.482
2.618,45.097,0.12587,-2.30,2.935,98.888
2.622,45.123,0.13004,-3.30,3.040,98.945
2.627,44.833,0.13481,-4.10,3.162,98.311
2.631,45.393,0.13892,-4.90,3.266,99.538
2.636,45.134,0.14218,-5.60,3.349,98.971
2.640,45.169,0.14574,0.00,3.439,99.047
2.644,45.430,0.14968,-7.00,3.539,99.620
2.649,45.286,0.15253,-7.60,3.612,99.304
2.653,45.341,0.15506,-8.10,3.676,99.424
2.658,45.481,0.15839,-8.70,3.761,99.730
2.662,45.214,0.16147,-9.30,3.839,99.144
2.667,45.065,0.16457,-9.70,3.918,98.818
2.671,45.343,0.16855,-10.30,4.019,99.428
2.676,45.296,0.17249,-10.90,4.119,99.324
2.680,45.291,0.17503,-11.40,4.183,99.313
2.684,45.389,0.17827,-12.00,4.265,99.528
2.689,45.281,0.18278,-12.60,4.380,99.292
2.693,44.883,0.18736,-13.20,4.496,98.420
2.698,45.452,0.19070,-13.80,4.581,99.667
2.702,45.383,0.19278,-14.30,4.634,99.515
2.707,45.408,0.19471,-14.80,4.683,99.571
2.711,45.358,0.19700,-15.20,4.741,99.460
2.716,45.270,0.19921,-15.70,4.797,99.268
2.720,45.270,0.20174,-16.20,4.862,99.269
2.724,45.347,0.20369,-16.50,4.911,99.438
2.729,45.455,0.20562,-17.00,4.960,99.674
2.733,45.519,0.20751,-17.30,5.008,99.815
2.738,45.581,0.20903,-17.60,5.047,99.950
2.742,45.329,0.21054,-18.00,5.085,99.397
2.747,45.200,0.21346,-18.50,5.159,99.114
2.751,45.517,0.21477,-18.80,5.193,99.809
2.756,45.569,0.21619,-19.30,5.229,99.924
2.760,45.538,0.21768,-19.60,5.267,99.855
2.764,45.428,0.21875,-19.90,5.294,99.614
2.769,45.478,0.21970,-20.20,5.318,99.725
2.773,45.448,0.22136,-20.70,5.360,99.659
2.778,45.275,0.22233,-20.90,5.385,99.278
2.782,45.539,0.22494,-21.60,5.451,99.859
2.787,45.435,0.22670,-22.20,5.496,99.629
2.791,45.252,0.22939,-22.80,5.564,99.229
2.796,45.352,0.23168,-23.40,5.622,99.449
2.800,45.362,0.23382,-24.20,5.676,99.469
2.804,45.592,0.23569,-24.90,5.724,99.974
2.809,45.423,0.23708,-25.40,5.759,99.603
2.813,45.483,0.23867,-26.10,5.800,99.735
2.818,45.537,0.23995,-26.70,5.832,99.854
2.822,45.337,0.24124,-27.20,5.865,99.414
2.827,45.320,0.24287,-27.90,5.906,99.379
2.831,45.567,0.24403,-28.50,5.936,99.919
2.836,45.566,0.24500,-29.00,5.960,99.917
2.840,45.425,0.24604,-29.60,5.987,99.609
2.844,45.507,0.24687,-29.90,6.008,99.788
2.849,45.475,0.24787,-30.50,6.033,99.718
2.853,45.542,0.24885,-31.00,6.058,99.865
2.858,45.464,0.24996,-31.70,6.086,99.695
2.862,45.339,0.25110,-32.40,6.115,99.420
2.867,45.636,0.25163,-32.50,6.129,100.070
2.871,45.540,0.25235,-33.00,6.147,99.861
2.876,45.457,0.25293,-33.40,6.162,99.678
2.880,45.487,0.25397,-34.10,6.188,99.745
2.884,45.521,0.25473,-34.70,6.208,99.819
2.889,45.568,0.25543,-35.00,6.225,99.923
2.893,45.476,0.25626,-35.70,6.246,99.720
2.898,45.497,0.25717,-36.30,6.270,99.767
2.902,45.548,0.25767,-36.80,6.282,99.878
2.907,45.517,0.25835,-37.50,6.299,99.810
2.911,45.496,0.25900,-37.90,6.316,99.765
2.916,45.526,0.25979,-38.40,6.336,99.830
2.920,45.574,0.26031,-39.00,6.349,99.935
2.924,45.543,0.26087,-39.40,6.364,99.866
2.929,45.517,0.26111,-39.60,6.370,99.811
2.933,45.644,0.26174,-40.40,6.386,100.089
2.938,45.542,0.26226,-40.60,6.399,99.866
2.942,45.567,0.26278,-41.30,6.412,99.920
2.947,45.506,0.26335,-41.70,6.427,99.786
2.951,45.504,0.26387,-42.20,6.440,99.781
2.956,45.548,0.26434,-42.70,6.452,99.877
2.960,45.550,0.26474,-43.20,6.462,99.882
2.964,45.488,0.26518,-43.60,6.473,99.747
2.969,45.591,0.26581,-44.30,6.489,99.973
2.973,45.602,0.26618,-44.70,6.498,99.996
2.978,45.623,0.26661,-45.00,6.509,100.041
2.982,45.610,0.26636,-44.60,6.503,100.015
2.987,45.376,0.26654,-44.60,6.508,99.501
2.991,45.609,0.26653,-44.40,6.507,100.011
2.996,45.372,0.26585,-43.00,6.490,99.491
3.000,45.846,0.26587,-42.60,6.491,100.531
3.004,45.409,0.26528,-41.10,6.476,99.573
3.009,45.854,0.26504,-40.60,6.469,100.549
3.013,45.336,0.26460,-39.00,6.458,99.413
3.018,45.836,0.26448,-38.30,6.455,100.509
3.022,45.580,0.26372,-37.10,6.436,99.948
3.027,45.670,0.26381,-36.20,6.438,100.145
3.031,45.772,0.26301,-35.10,6.418,100.368
3.036,45.562,0.26290,-34.00,6.415,99.909
3.040,45.730,0.26228,-33.10,6.399,100.277
3.044,45.425,0.26188,-31.80,6.389,99.609
3.049,45.717,0.26143,-30.80,6.378,100.248
3.053,45.727,0.26088,-29.80,6.364,100.271
3.058,45.607,0.26024,-28.50,6.347,100.007
3.062,45.532,0.25989,-27.60,6.339,99.842
3.067,45.714,0.25943,-26.60,6.327,100.243
3.071,45.659,0.25863,-25.50,6.307,100.121
3.076,45.681,0.25819,-24.40,6.295,100.170
3.080,45.655,0.25759,-23.40,6.280,100.112
3.084,45.672,0.25707,-22.50,6.267,100.149
3.089,45.654,0.25639,-21.50,6.250,100.110
3.093,45.699,0.25581,-20.70,6.235,100.209
3.098,45.638,0.25515,-19.80,6.218,100.075
3.102,45.688,0.25450,-19.00,6.202,100.184
3.107,45.684,0.25367,-18.00,6.181,100.176
3.111,45.654,0.25292,-17.10,6.162,100.111
3.116,45.700,0.25196,-16.20,6.137,100.212
3.120,45.715,0.25099,-15.30,6.113,100.244
3.124,45.724,0.24981,-14.40,6.083,100.263
3.129,45.743,0.24854,-13.40,6.050,100.305
3.133,45.783,0.24706,-12.46,6.013,100.394
3.138,45.806,0.24532,-11.50,5.969,100.444
3.142,45.802,0.24316,-10.40,5.914,100.435
3.147,45.753,0.24125,-9.30,5.865,100.327
3.151,45.891,0.23907,-8.40,5.810,100.630
3.156,45.848,0.23631,-7.30,5.740,100.536
3.160,45.928,0.23376,-6.20,5.675,100.712
3.164,45.954,0.23035,0.00,5.588,100.768
3.169,46.017,0.22710,-4.10,5.506,100.907
3.173,46.060,0.22306,-3.00,5.403,101.001
3.178,46.127,0.21850,-1.90,5.287,101.147
3.182,46.145,0.21327,-0.90,5.155,101.187
3.187,46.360,0.20730,0.10,5.003,101.659
3.191,46.434,0.19977,1.30,4.812,101.821
3.196,46.357,0.19276,2.40,4.633,101.652
3.200,46.539,0.18444,3.40,4.422,102.052
3.204,46.366,0.17580,4.50,4.203,101.671
3.209,46.485,0.16720,5.50,3.984,101.934
3.213,46.400,0.15935,6.60,3.785,101.746
3.218,46.349,0.15217,7.60,3.603,101.635
3.222,46.229,0.14575,8.80,3.440,101.371
3.227,46.249,0.13983,9.80,3.289,101.415
3.231,46.084,0.13403,10.90,3.142,101.054
3.236,46.124,0.12920,12.00,3.019,101.141
3.240,46.032,0.12487,13.00,2.909,100.939
3.244,46.044,0.12020,14.10,2.791,100.966
3.249,46.005,0.11620,15.10,2.689,100.880
3.253,45.961,0.11264,16.20,2.598,100.783
3.258,45.982,0.10915,17.30,2.510,100.830
3.262,45.934,0.10571,18.30,2.422,100.723
3.267,45.912,0.10243,19.40,2.339,100.675
3.271,45.938,0.09956,20.50,2.266,100.733
3.276,45.911,0.09663,21.50,2.192,100.674
3.280,45.817,0.09447,22.50,2.137,100.468
3.284,45.962,0.09172,23.60,2.067,100.787
3.289,45.738,0.08915,24.90,2.002,100.294
3.293,45.931,0.08752,25.70,1.961,100.719
3.298,45.736,0.08528,26.90,1.904,100.290
3.302,45.805,0.08347,27.90,1.858,100.441
3.307,45.766,0.08177,29.10,1.814,100.355
3.311,45.863,0.07993,30.00,1.768,100.568
3.316,45.716,0.07823,31.30,1.724,100.247
3.320,45.718,0.07702,32.30,1.694,100.251
3.324,45.747,0.07562,33.30,1.658,100.315
3.329,45.766,0.07435,34.40,1.626,100.356
3.333,45.674,0.07309,35.40,1.594,100.154
3.338,45.701,0.07180,36.60,1.561,100.213
3.342,45.798,0.07102,37.30,1.541,100.426
3.347,45.691,0.06960,38.80,1.505,100.192
3.351,45.659,0.06876,39.80,1.484,100.121
3.356,45.722,0.06780,40.70,1.460,100.260
3.360,45.676,0.06684,42.00,1.435,100.159
3.364,45.802,0.06613,42.70,1.417,100.435
3.369,45.633,0.06507,44.10,1.390,100.064
3.373,45.743,0.06451,44.90,1.376,100.306
3.378,45.675,0.06350,46.20,1.350,100.156
3.382,45.690,0.06280,47.30,1.333,100.189
3.387,45.685,0.06216,48.20,1.316,100.178
3.391,45.620,0.06159,49.10,1.302,100.036
3.396,45.633,0.06126,49.70,1.294,100.063
3.400,45.651,0.06104,50.00,1.288,100.104
3.404,45.616,0.06086,50.40,1.283,100.028
3.409,31.597,0.05364,50.40,1.100,69.286
3.413,22.917,0.04758,50.50,0.946,50.253
3.418,22.832,0.04695,50.60,0.930,50.067
3.422,22.812,0.04662,50.50,0.922,50.022
3.427,22.836,0.04639,50.50,0.916,50.074
3.431,22.817,0.04619,50.40,0.911,50.034
3.436,22.840,0.04605,50.40,0.907,50.083
3.440,22.753,0.04625,49.50,0.912,49.893
3.444,22.809,0.04638,48.30,0.915,50.016
3.449,22.782,0.04650,47.30,0.919,49.957
3.453,22.784,0.04659,46.30,0.921,49.961
3.458,22.806,0.04670,45.50,0.924,50.008
3.462,22.799,0.04683,44.60,0.927,49.994
3.467,22.775,0.04691,43.80,0.929,49.941
3.471,22.787,0.04707,42.90,0.933,49.967
3.476,22.784,0.04723,41.90,0.937,49.960
3.480,22.796,0.04741,41.10,0.942,49.988
3.484,22.776,0.04761,40.20,0.947,49.942
3.489,22.785,0.04780,39.40,0.952,49.963
3.493,22.782,0.04803,38.40,0.957,49.958
3.498,22.771,0.04830,37.50,0.964,49.932
3.502,22.760,0.04863,36.50,0.973,49.908
3.507,22.784,0.04901,35.30,0.982,49.961
3.511,22.752,0.04940,34.20,0.992,49.890
3.516,22.749,0.04981,33.10,1.003,49.884
3.520,22.718,0.05038,31.80,1.017,49.816
3.524,22.686,0.05116,30.30,1.037,49.746
3.529,22.448,0.05327,27.60,1.090,49.223
3.533,22.782,0.05265,26.70,1.075,49.957
3.538,23.212,0.05370,25.20,1.101,50.899
3.542,22.797,0.05454,24.30,1.123,49.990
3.547,22.258,0.05415,23.80,1.113,48.808
3.551,23.414,0.05607,22.00,1.162,51.342
3.556,22.058,0.05562,21.60,1.150,48.369
3.560,23.355,0.05696,19.90,1.184,51.213
3.564,22.409,0.05784,19.20,1.207,49.138
3.569,22.369,0.05800,18.30,1.211,49.051
3.573,23.756,0.05893,16.50,1.234,52.092
3.578,22.470,0.05998,16.10,1.261,49.271
3.582,22.187,0.06006,15.10,1.263,48.651
3.587,23.576,0.06212,13.60,1.315,51.697
3.591,21.699,0.06417,12.40,1.367,47.582
3.596,22.395,0.06502,11.50,1.389,49.107
3.600,21.958,0.06477,11.20,1.383,48.150
3.604,21.599,0.06694,10.00,1.438,47.363
3.609,22.449,0.06825,8.60,1.471,49.227
3.613,23.366,0.06874,7.30,1.483,51.237
3.618,24.449,0.07099,6.10,1.541,53.612
3.622,22.424,0.07221,5.70,1.572,49.171
3.627,21.901,0.07573,4.40,1.661,48.024
3.631,21.717,0.07733,3.10,1.702,47.622
3.636,22.419,0.07669,2.50,1.685,49.161
3.640,24.363,0.08056,1.00,1.784,53.424
3.644,22.168,0.08339,0.40,1.855,48.609
3.649,21.557,0.08713,-1.20,1.951,47.270
3.653,24.066,0.08794,-2.30,1.971,52.771
3.658,22.361,0.09001,0.00,2.024,49.033
3.662,22.161,0.09585,-4.70,2.172,48.596
3.667,20.278,0.09836,-5.10,2.236,44.466
3.671,22.476,0.10262,-6.60,2.344,49.286
3.676,21.993,0.10409,-7.10,2.381,48.227
3.680,23.367,0.10990,-9.00,2.529,51.239
3.684,21.127,0.11675,-10.20,2.703,46.327
3.689,21.924,0.11743,-10.00,2.720,48.075
3.693,22.648,0.12521,-11.30,2.918,49.663
3.698,22.709,0.12937,-12.30,3.024,49.797
3.702,21.127,0.13820,-13.70,3.248,46.328
3.707,20.692,0.14258,-14.80,3.359,45.373
3.711,21.814,0.15137,-16.20,3.582,47.835
3.716,22.091,0.15584,-16.60,3.696,48.442
3.720,21.913,0.16121,-17.70,3.832,48.051
3.724,23.819,0.16801,-19.30,4.005,52.231
3.729,22.944,0.17222,-20.30,4.112,50.312
3.733,22.397,0.17610,-21.10,4.210,49.112
3.738,23.376,0.18245,-22.60,4.372,51.259
3.742,21.131,0.18705,-23.50,4.489,46.337
3.747,21.972,0.18982,-24.50,4.559,48.181
3.751,22.626,0.19261,-25.40,4.630,49.615
3.756,23.200,0.19586,-26.90,4.712,50.872
3.760,21.777,0.19887,-27.70,4.789,47.753
3.764,22.409,0.20013,-28.30,4.821,49.138
3.769,22.626,0.20297,-29.50,4.893,49.615
3.773,22.489,0.20455,-30.40,4.933,49.314
3.778,22.478,0.20646,-31.50,4.982,49.290
3.782,22.257,0.20926,-33.00,5.053,48.806
3.787,22.661,0.21016,-33.50,5.076,49.690
3.791,22.582,0.21207,-35.10,5.124,49.517
3.796,22.452,0.21450,-36.40,5.186,49.234
3.800,22.588,0.21569,-37.10,5.216,49.530
3.804,22.804,0.21669,-37.90,5.241,50.005
3.809,22.952,0.21836,-39.30,5.284,50.330
3.813,22.440,0.22009,-40.20,5.328,49.206
3.818,22.699,0.22105,-40.80,5.352,49.774
3.822,22.667,0.22318,-42.70,5.406,49.705
3.827,22.729,0.22371,-43.20,5.420,49.841
3.831,22.639,0.22480,-44.40,5.447,49.643
3.836,22.435,0.22571,-44.60,5.471,49.196
3.840,22.641,0.22568,-44.00,5.470,49.648
3.844,22.776,0.22643,-44.60,5.489,49.942
3.849,23.122,0.22684,-45.20,5.499,50.702
3.853,22.939,0.22707,-45.00,5.505,50.302
3.858,22.609,0.22678,-44.20,5.498,49.578
3.862,22.292,0.22713,-44.30,5.507,48.881
3.867,22.768,0.22753,-44.40,5.517,49.925
3.871,22.665,0.22807,-44.90,5.530,49.700
3.876,22.611,0.22828,-44.90,5.536,49.581
3.880,22.588,0.22771,-44.30,5.521,49.531
3.884,22.829,0.22844,-44.30,5.540,50.060
3.889,23.055,0.22766,-43.30,5.520,50.555
3.893,22.515,0.22785,-42.20,5.525,49.370
3.898,23.056,0.22720,-41.20,5.508,50.558
3.902,22.529,0.22717,-39.70,5.507,49.402
3.907,23.022,0.22681,-39.30,5.499,50.483
3.911,22.556,0.22632,-37.60,5.486,49.461
3.916,23.062,0.22621,-37.10,5.483,50.570
3.920,22.681,0.22550,-35.50,5.465,49.734
3.924,23.014,0.22576,-34.90,5.472,50.464
3.929,22.994,0.22490,-33.60,5.450,50.421
3.933,22.481,0.22481,-32.50,5.448,49.297
3.938,23.009,0.22433,-31.70,5.435,50.454
3.942,22.551,0.22369,-30.20,5.419,49.450
3.947,23.024,0.22356,-29.60,5.416,50.488
3.951,23.020,0.22266,-28.30,5.393,50.477
3.956,22.481,0.22233,-27.10,5.385,49.296
3.960,22.971,0.22180,-26.40,5.371,50.371
3.964,23.007,0.22094,-25.10,5.349,50.450
3.969,22.731,0.22011,-24.00,5.328,49.845
3.973,22.790,0.21964,-22.90,5.316,49.974
3.978,22.949,0.21887,-22.10,5.297,50.324
3.982,22.937,0.21798,-21.00,5.274,50.296
3.987,22.889,0.21652,-19.70,5.237,50.192
3.991,22.949,0.21571,-18.90,5.217,50.323
3.996,22.844,0.21439,-17.70,5.183,50.092
4.000,22.974,0.21339,-16.90,5.157,50.378
4.004,22.957,0.21174,-15.90,5.116,50.340
4.009,22.938,0.21039,-15.00,5.081,50.298
4.013,22.991,0.20862,-14.10,5.036,50.414
4.018,23.007,0.20662,-13.20,4.986,50.450
4.022,23.039,0.20445,-12.40,4.930,50.521
4.027,23.140,0.20196,-11.40,4.867,50.743
4.031,23.103,0.19891,-10.50,4.790,50.660
4.036,23.169,0.19558,-9.60,4.705,50.806
4.040,23.189,0.19126,-8.60,4.596,50.850
4.044,23.419,0.18643,-7.70,4.473,51.353
4.049,23.393,0.18050,-6.60,4.322,51.296
4.053,23.531,0.17409,-5.70,4.159,51.598
4.058,23.671,0.16573,-4.60,3.947,51.906
4.062,23.677,0.15714,-3.70,3.729,51.919
4.067,23.807,0.14828,-2.60,3.504,52.204
4.071,23.567,0.13956,-1.70,3.282,51.679
4.076,23.572,0.13189,-0.50,3.087,51.689
4.080,23.507,0.12509,0.50,2.915,51.545
4.084,23.325,0.11887,1.60,2.757,51.148
4.089,23.309,0.11386,2.60,2.630,51.113
4.093,23.350,0.10872,3.70,2.499,51.201
4.098,23.268,0.10413,4.90,2.382,51.022
4.102,23.151,0.10025,5.87,2.284,50.766
4.107,23.164,0.09639,7.00,2.186,50.795
4.111,23.152,0.09300,8.10,2.100,50.767
4.116,23.053,0.09008,9.00,2.025,50.551
4.120,23.308,0.08675,10.10,1.941,51.109
4.124,23.012,0.08353,11.30,1.859,50.460
4.129,23.028,0.08144,12.30,1.806,50.496
4.133,23.053,0.07880,13.40,1.739,50.551
4.138,22.998,0.07658,14.50,1.683,50.430
4.142,22.995,0.07446,15.50,1.629,50.424
4.147,23.001,0.07231,16.60,1.574,50.436
4.151,23.017,0.07057,17.70,1.530,50.473
4.156,23.005,0.06870,18.70,1.482,50.445
4.160,22.906,0.06716,19.80,1.443,50.229
4.164,22.971,0.06550,20.90,1.401,50.372
4.169,22.945,0.06400,21.90,1.363,50.313
4.173,22.917,0.06264,23.00,1.329,50.253
4.178,22.909,0.06141,24.00,1.297,50.235
4.182,22.906,0.06020,25.10,1.267,50.229
4.187,22.869,0.05908,26.20,1.238,50.146
4.191,22.871,0.05816,27.20,1.215,50.153
4.196,22.949,0.05717,28.20,1.190,50.322
4.200,22.899,0.05587,29.50,1.157,50.213
4.204,22.870,0.05524,30.60,1.141,50.150
4.209,22.891,0.05441,31.50,1.119,50.195
4.213,22.879,0.05362,32.60,1.099,50.170
4.218,22.853,0.05285,33.60,1.080,50.113
4.222,22.875,0.05215,34.80,1.062,50.160
4.227,22.869,0.05152,35.90,1.046,50.147
4.231,22.846,0.05085,36.90,1.029,50.098
4.236,22.853,0.05021,38.00,1.013,50.112
4.240,22.870,0.04961,39.10,0.998,50.149
4.244,22.872,0.04912,40.10,0.985,50.155
4.249,22.873,0.04852,41.10,0.970,50.156
4.253,22.850,0.04804,42.20,0.958,50.106
4.258,22.829,0.04757,43.30,0.946,50.060
4.262,22.852,0.04698,44.50,0.931,50.110
4.267,22.862,0.04658,45.50,0.921,50.133
4.271,22.862,0.04624,46.30,0.912,50.132
4.276,22.850,0.04554,47.70,0.894,50.107
4.280,22.832,0.04522,48.70,0.886,50.065
4.284,22.819,0.04501,49.30,0.881,50.037
4.289,22.829,0.04485,49.80,0.877,50.059
4.293,22.814,0.04463,50.10,0.871,50.026
4.298,15.842,0.04152,50.40,0.792,34.739
4.302,10.075,0.03817,50.40,0.707,22.093
4.307,10.083,0.03778,50.50,0.697,22.110
4.311,10.041,0.03757,50.50,0.692,22.018
4.316,10.059,0.03739,50.50,0.687,22.057
4.320,10.065,0.03728,50.30,0.684,22.071
4.324,10.047,0.03712,50.40,0.680,22.030
4.329,9.998,0.03708,50.30,0.679,21.923
4.333,10.063,0.03730,48.70,0.685,22.066
4.338,10.075,0.03732,47.40,0.685,22.092
4.342,10.039,0.03739,46.40,0.687,22.013
4.347,10.029,0.03755,45.30,0.691,21.991
4.351,10.123,0.03760,44.20,0.692,22.198
4.356,10.057,0.03780,43.20,0.697,22.053
4.360,10.006,0.03793,42.10,0.701,21.941
4.364,9.991,0.03806,41.20,0.704,21.909
4.369,10.009,0.03824,40.10,0.709,21.947
4.373,10.017,0.03842,39.00,0.713,21.965
4.378,10.140,0.03862,37.80,0.718,22.234
4.382,9.968,0.03863,36.90,0.719,21.858
4.387,9.940,0.03900,35.90,0.728,21.797
4.391,10.204,0.03917,34.60,0.732,22.375
4.396,9.913,0.03951,33.90,0.741,21.737
4.400,10.207,0.03962,32.50,0.744,22.382
4.404,10.010,0.04041,31.50,0.764,21.950
4.409,9.731,0.04008,30.70,0.755,21.339
4.413,10.376,0.04058,29.00,0.768,22.752
4.418,9.635,0.04129,28.60,0.786,21.128
4.422,9.858,0.04089,27.50,0.776,21.617
4.427,10.576,0.04195,25.60,0.803,23.191
4.431,9.663,0.04250,25.10,0.817,21.189
4.436,9.335,0.04223,24.50,0.810,20.470
4.440,10.288,0.04247,22.90,0.816,22.559
4.444,10.573,0.04408,21.30,0.857,23.184
4.449,9.392,0.04449,21.20,0.868,20.595
4.453,9.422,0.04375,20.30,0.849,20.661
4.458,10.735,0.04472,18.30,0.873,23.539
4.462,10.439,0.04615,17.30,0.910,22.890
4.467,9.310,0.04668,16.50,0.923,20.414
4.471,8.587,0.04660,15.90,0.921,18.829
4.476,10.988,0.04715,14.20,0.935,24.095
4.480,7.551,0.04800,13.90,0.957,16.558
4.484,11.064,0.04827,12.20,0.964,24.262
4.489,10.992,0.04920,11.00,0.987,24.104
4.493,11.087,0.05092,9.70,1.031,24.312
4.498,12.068,0.05179,8.70,1.053,26.462
4.502,9.434,0.05326,8.10,1.090,20.688
4.507,10.357,0.05552,6.10,1.148,22.711
4.511,9.011,0.05413,6.90,1.112,19.759
4.516,12.354,0.05628,4.20,1.167,27.090
4.520,8.418,0.05871,3.70,1.229,18.458
4.524,9.016,0.05775,3.50,1.204,19.770
4.529,11.170,0.05859,2.20,1.226,24.494
4.533,6.745,0.06203,0.10,1.313,14.791
4.538,9.515,0.06121,0.40,1.292,20.865
4.542,6.657,0.06411,-0.70,1.366,14.597
4.547,9.986,0.06681,-2.50,1.435,21.897
4.551,12.151,0.06721,-3.70,1.445,26.645
4.556,9.714,0.06942,-4.30,1.501,21.302
4.560,9.988,0.07378,-6.00,1.611,21.902
4.564,7.635,0.07610,0.00,1.670,16.742
4.569,6.688,0.07917,-8.60,1.748,14.664
4.573,9.056,0.08003,-8.10,1.770,19.858
4.578,4.673,0.08469,-10.20,1.889,10.246
4.582,7.596,0.08791,-10.90,1.970,16.656
4.587,11.260,0.08965,-11.70,2.015,24.691
4.591,12.606,0.09461,-12.90,2.140,27.643
4.596,9.554,0.09888,-13.30,2.249,20.950
4.600,5.196,0.10511,-15.60,2.407,11.393
4.604,2.394,0.11002,-16.40,2.532,5.249
4.609,9.318,0.11469,-16.50,2.651,20.433
4.613,8.399,0.12176,-18.10,2.830,18.417
4.618,9.330,0.12673,-18.90,2.956,20.458
4.622,9.105,0.13488,-21.10,3.163,19.965
4.627,5.013,0.14019,-22.20,3.298,10.992
4.631,9.493,0.14471,-22.00,3.413,20.816
4.636,10.135,0.15060,-23.90,3.563,22.224
4.640,9.805,0.15454,-24.00,3.663,21.499
4.644,9.371,0.15931,-25.60,3.784,20.548
4.649,8.362,0.16123,-26.70,3.833,18.337
4.653,10.120,0.16309,-27.70,3.880,22.190
4.658,10.938,0.16700,-29.70,3.979,23.984
4.662,9.909,0.16846,-29.30,4.016,21.728
4.667,9.415,0.17194,-30.60,4.105,20.646
4.671,8.773,0.17485,-32.60,4.179,19.236
4.676,9.591,0.17545,-32.90,4.194,21.032
4.680,9.884,0.17760,-34.20,4.249,21.673
4.684,9.886,0.17911,-35.20,4.287,21.678
4.689,9.890,0.18057,-35.70,4.324,21.687
4.693,9.722,0.18346,-37.20,4.397,21.318
4.698,9.514,0.18480,-38.10,4.431,20.863
4.702,9.752,0.18551,-38.60,4.449,21.384
4.707,9.787,0.18822,-40.80,4.518,21.461
4.711,9.630,0.18948,-41.60,4.550,21.116
4.716,9.661,0.19018,-42.40,4.568,21.185
4.720,9.958,0.19224,-44.00,4.620,21.835
4.724,9.817,0.19328,-45.10,4.647,21.527
4.729,9.679,0.19370,-44.80,4.658,21.225
4.733,10.034,0.19320,-44.50,4.645,22.002
4.738,9.967,0.19379,-44.60,4.660,21.856
4.742,9.923,0.19449,-44.50,4.677,21.760
4.747,10.256,0.19522,-45.80,4.696,22.489
4.751,9.838,0.19533,-45.00,4.699,21.572
4.756,9.725,0.19474,-44.30,4.684,21.324
4.760,9.717,0.19589,-44.80,4.713,21.308
4.764,10.339,0.19555,-45.00,4.704,22.671
4.769,9.970,0.19600,-45.20,4.716,21.863
4.773,9.752,0.19557,-44.40,4.705,21.384
4.778,10.347,0.19588,-44.60,4.713,22.689
4.782,9.862,0.19520,-42.60,4.696,21.624
4.787,10.314,0.19572,-42.40,4.709,22.616
4.791,10.114,0.19485,-40.70,4.687,22.178
4.796,9.971,0.19529,-39.70,4.698,21.863
4.800,10.272,0.19456,-38.60,4.679,22.525
4.804,9.726,0.19438,-37.20,4.675,21.328
4.809,10.241,0.19403,-36.50,4.666,22.456
4.813,9.662,0.19406,-35.10,4.667,21.188
4.818,10.257,0.19355,-34.60,4.654,22.491
4.822,10.009,0.19278,-33.20,4.634,21.949
4.827,10.176,0.19319,-32.50,4.644,22.314
4.831,10.249,0.19234,-31.30,4.623,22.475
4.836,9.650,0.19172,-29.90,4.607,21.160
4.840,10.179,0.19170,-29.20,4.607,22.320
4.844,10.236,0.19088,-28.20,4.586,22.447
4.849,9.912,0.18998,-26.70,4.563,21.736
4.853,9.976,0.18980,-25.80,4.558,21.875
4.858,10.220,0.18886,-24.90,4.535,22.410
4.862,10.107,0.18773,-23.40,4.506,22.162
4.867,9.984,0.18731,-22.60,4.495,21.893
4.871,10.191,0.18637,-21.70,4.471,22.346
4.876,10.247,0.18527,-20.70,4.443,22.470
4.880,10.232,0.18383,-19.50,4.407,22.436
4.884,10.179,0.18228,-18.30,4.367,22.320
4.889,10.219,0.18098,-17.40,4.334,22.409
4.893,10.246,0.17933,-16.40,4.293,22.468
4.898,10.273,0.17729,-15.50,4.241,22.527
4.902,10.279,0.17495,-14.50,4.181,22.539
4.907,10.372,0.17244,-13.70,4.117,22.744
4.911,10.416,0.16896,-12.80,4.029,22.841
4.916,10.440,0.16527,-12.00,3.935,22.893
4.920,10.621,0.16050,-11.00,3.814,23.291
4.924,10.591,0.15446,-10.00,3.661,23.225
4.929,10.872,0.14810,-9.20,3.499,23.840
4.933,10.795,0.14046,-8.20,3.305,23.671
4.938,10.840,0.13277,-7.30,3.110,23.770
4.942,10.813,0.12517,-6.30,2.917,23.712
4.947,10.717,0.11785,-5.30,2.731,23.501
4.951,10.598,0.11181,-4.30,2.577,23.239
4.956,10.835,0.10616,-3.30,2.434,23.759
4.960,10.362,0.10114,-2.30,2.306,22.722
4.964,10.504,0.09615,-1.10,2.180,23.033
4.969,10.361,0.09228,-0.20,2.081,22.720
4.973,10.590,0.08843,0.90,1.984,23.221
4.978,10.317,0.08433,2.00,1.880,22.624
4.982,10.345,0.08178,2.90,1.815,22.684
4.987,10.365,0.07830,4.20,1.726,22.729
4.991,10.328,0.07568,5.20,1.660,22.648
4.996,10.332,0.07309,6.20,1.594,22.655
5.000,10.286,0.07052,7.30,1.529,22.554
5.004,10.298,0.06819,8.40,1.469,22.582
5.009,10.212,0.06605,9.50,1.415,22.394
5.013,10.269,0.06390,10.50,1.361,22.517
5.018,10.229,0.06198,11.60,1.312,22.431
5.022,10.260,0.06021,12.70,1.267,22.497
5.027,10.188,0.05860,13.80,1.226,22.341
5.031,10.227,0.05694,14.80,1.184,22.426
5.036,10.155,0.05553,15.90,1.148,22.269
5.040,10.121,0.05424,17.00,1.115,22.193
5.044,10.157,0.05290,18.10,1.081,22.272
5.049,10.134,0.05176,19.10,1.052,22.222
5.053,10.163,0.05056,20.20,1.022,22.286
5.058,10.122,0.04961,21.30,0.998,22.196
5.062,10.136,0.04867,22.20,0.974,22.226
5.067,10.139,0.04774,23.30,0.950,22.234
5.071,10.145,0.04679,24.50,0.926,22.247
5.076,10.104,0.04606,25.40,0.907,22.157
5.080,10.065,0.04520,26.60,0.886,22.070
5.084,10.135,0.04459,27.50,0.870,22.224
5.089,10.086,0.04374,28.90,0.849,22.117
5.093,10.119,0.04323,29.70,0.835,22.188
5.098,10.104,0.04257,30.90,0.819,22.156
5.102,10.091,0.04207,32.00,0.806,22.127
5.107,10.115,0.04154,32.90,0.793,22.181
5.111,10.071,0.04098,34.10,0.778,22.084
5.116,10.080,0.04055,35.10,0.767,22.103
5.120,10.088,0.04003,36.20,0.754,22.122
5.124,10.061,0.03959,37.30,0.743,22.061
5.129,10.074,0.03917,38.30,0.732,22.089
5.133,10.059,0.03876,39.40,0.722,22.058
5.138,10.099,0.03830,40.50,0.710,22.145
5.142,10.046,0.03796,41.60,0.702,22.029
5.147,10.064,0.03761,42.60,0.693,22.068
5.151,10.063,0.03726,43.60,0.684,22.066
5.156,10.073,0.03690,44.80,0.675,22.087
5.160,10.076,0.03659,45.80,0.667,22.096
5.164,10.057,0.03629,46.80,0.659,22.054
5.169,10.073,0.03596,48.00,0.651,22.087
5.173,10.087,0.03571,48.90,0.645,22.119
5.178,10.045,0.03552,49.60,0.640,22.026
5.182,10.076,0.03546,49.70,0.638,22.094
5.187,10.035,0.03529,50.30,0.634,22.004
5.191,10.021,0.03527,50.40,0.633,21.974
5.196,10.047,0.03524,50.60,0.633,22.032
5.199,10.043,0.03521,50.50,0.632,22.022