File: input/preprocessor_samples/isobaric_7cycle.txt
"Test Method,""SMA-CFTC.msm"""
"Sample I. D.,""+7 cycles.mss"""
"Specimen Number,""1"""

"Time (h),""Load (N)"",""Crosshead (in)"",""Temperature Chamber (C)"",""Extension (mm)"",""Stress (MPa)"""

"0.001,77.872,0.00013,50.40,-0.176,170.759"
"0.001,79.035,0.00033,50.50,-0.171,173.309"
"0.002,80.273,0.00052,50.50,-0.166,176.024"
"0.002,81.522,0.00072,50.40,-0.161,178.763"
"0.003,82.723,0.00091,50.40,-0.156,181.396"
"0.003,83.955,0.00111,50.40,-0.151,184.096"
"0.004,85.195,0.00131,50.40,-0.146,186.817"
"0.004,86.462,0.00150,50.40,-0.141,189.595"
"0.005,87.760,0.00170,50.40,-0.136,192.441"
"0.006,89.069,0.00190,50.40,-0.131,195.311"
"0.006,90.424,0.00210,50.30,-0.126,198.282"
"0.007,91.846,0.00230,50.30,-0.121,201.401"
"0.007,93.201,0.00249,50.40,-0.116,204.371"
"0.008,94.668,0.00269,50.30,-0.111,207.588"
"0.008,96.134,0.00289,50.30,-0.106,210.803"
"0.009,97.685,0.00309,50.30,-0.101,214.205"
"0.009,99.191,0.00328,50.30,-0.096,217.507"
"0.010,100.738,0.00348,50.30,-0.091,220.898"
"0.011,102.366,0.00368,50.30,-0.086,224.469"
"0.011,104.028,0.00387,50.30,-0.081,228.113"
"0.012,105.713,0.00407,50.30,-0.076,231.808"
"0.012,107.420,0.00426,50.30,-0.071,235.551"
"0.013,109.075,0.00446,50.30,-0.066,239.180"
"0.013,110.821,0.00466,50.30,-0.061,243.008"
"0.014,112.594,0.00485,50.30,-0.056,246.897"
"0.014,114.375,0.00505,50.30,-0.051,250.801"
"0.015,116.174,0.00524,50.30,-0.046,254.748"
"0.016,117.983,0.00544,50.20,-0.041,258.714"
"0.016,119.814,0.00564,50.20,-0.036,262.730"
"0.017,121.651,0.00583,50.20,-0.031,266.756"
"0.017,123.501,0.00603,50.20,-0.026,270.813"
"0.018,125.387,0.00623,50.30,-0.021,274.950"
"0.018,127.345,0.00643,50.20,-0.016,279.243"
"0.019,129.338,0.00663,50.20,-0.011,283.613"
"0.019,131.242,0.00682,50.20,-0.006,287.789"
"0.020,133.228,0.00702,50.20,-0.001,292.144"
"0.021,135.235,0.00721,50.20,0.004,296.544"
"0.021,137.314,0.00741,50.20,0.009,301.102"
"0.022,139.390,0.00761,50.20,0.014,305.655"
"0.022,141.427,0.00780,50.20,0.019,310.123"
"0.023,143.530,0.00800,50.20,0.024,314.734"
"0.023,145.691,0.00820,50.20,0.029,319.472"
"0.024,147.884,0.00840,50.20,0.034,324.282"
"0.024,150.060,0.00859,50.20,0.039,329.053"
"0.025,152.311,0.00879,50.20,0.044,333.989"
"0.026,154.633,0.00898,50.20,0.049,339.080"
"0.026,157.021,0.00918,50.20,0.054,344.316"
"0.027,159.433,0.00938,50.20,0.059,349.605"
"0.027,161.875,0.00957,50.20,0.064,354.961"
"0.028,164.383,0.00977,50.20,0.069,360.459"
"0.028,166.867,0.00997,50.20,0.074,365.906"
"0.029,169.413,0.01017,50.20,0.079,371.489"
"0.029,171.905,0.01036,50.20,0.084,376.954"
"0.030,174.428,0.01056,50.10,0.089,382.487"
"0.031,176.970,0.01075,50.10,0.094,388.061"
"0.031,179.633,0.01095,50.10,0.099,393.900"
"0.032,182.262,0.01115,50.10,0.104,399.665"
"0.032,184.894,0.01135,50.10,0.109,405.437"
"0.033,187.584,0.01154,50.10,0.114,411.336"
"0.033,190.232,0.01174,50.10,0.119,417.142"
"0.034,192.951,0.01194,50.10,0.124,423.104"
"0.034,195.481,0.01213,50.10,0.129,428.652"
"0.035,197.174,0.01233,50.10,0.134,432.363"
"0.036,198.743,0.01252,50.10,0.139,435.806"
"0.036,201.649,0.01272,50.10,0.144,442.176"
"0.037,204.545,0.01292,50.10,0.149,448.528"
"0.037,207.488,0.01311,50.10,0.154,454.981"
"0.038,210.576,0.01331,50.20,0.159,461.751"
"0.038,213.573,0.01351,50.10,0.164,468.324"
"0.039,216.352,0.01371,50.10,0.169,474.418"
"0.039,219.328,0.01391,50.10,0.174,480.944"
"0.040,222.304,0.01410,50.10,0.179,487.469"
"0.041,225.403,0.01430,50.10,0.184,494.266"
"0.041,228.506,0.01449,50.10,0.189,501.069"
"0.042,231.642,0.01469,50.10,0.194,507.947"
"0.042,234.236,0.01489,50.10,0.199,513.634"
"0.043,237.193,0.01509,50.10,0.204,520.117"
"0.043,240.142,0.01528,50.10,0.209,526.584"
"0.044,243.209,0.01548,50.10,0.214,533.311"
"0.044,246.172,0.01567,50.00,0.219,539.807"
"0.045,249.406,0.01587,50.10,0.224,546.898"
"0.046,252.697,0.01607,50.10,0.229,554.116"
"0.046,255.869,0.01627,50.10,0.234,561.070"
"0.047,258.879,0.01646,50.10,0.239,567.671"
"0.047,262.059,0.01666,50.10,0.244,574.644"
"0.048,265.432,0.01686,50.10,0.249,582.041"
"0.048,268.855,0.01706,50.10,0.254,589.546"
"0.049,272.241,0.01725,50.10,0.259,596.972"
"0.049,275.684,0.01745,50.10,0.264,604.523"
"0.050,278.641,0.01765,50.10,0.269,611.006"
"0.051,281.610,0.01784,50.10,0.274,617.515"
"0.051,285.247,0.01804,50.10,0.279,625.492"
"0.052,288.918,0.01824,50.10,0.284,633.541"
"0.052,292.437,0.01843,50.10,0.289,641.258"
"0.053,295.976,0.01863,50.10,0.294,649.017"
"0.053,299.593,0.01883,50.00,0.299,656.950"
"0.054,303.131,0.01903,50.10,0.304,664.707"
"0.054,306.787,0.01922,50.00,0.309,672.724"
"0.055,310.477,0.01942,50.00,0.314,680.815"
"0.056,314.252,0.01962,50.10,0.319,689.093"
"0.056,317.979,0.01981,50.10,0.324,697.266"
"0.057,321.753,0.02001,50.00,0.329,705.541"
"0.057,325.549,0.02021,50.00,0.334,713.866"
"0.058,329.258,0.02040,50.00,0.339,722.000"
"0.058,332.922,0.02059,50.00,0.344,730.033"
"0.059,336.613,0.02079,50.00,0.349,738.126"
"0.059,340.380,0.02098,50.10,0.354,746.388"
"0.060,344.198,0.02118,50.10,0.359,754.760"
"0.061,348.114,0.02138,50.00,0.364,763.347"
"0.061,351.933,0.02157,50.00,0.369,771.721"
"0.062,355.925,0.02177,50.00,0.374,780.474"
"0.062,359.769,0.02197,50.00,0.379,788.903"
"0.063,363.681,0.02217,50.00,0.384,797.482"
"0.063,367.573,0.02237,50.00,0.389,806.017"
"0.064,371.397,0.02256,50.00,0.394,814.401"
"0.064,375.432,0.02276,50.00,0.399,823.250"
"0.065,379.357,0.02296,50.00,0.404,831.857"
"0.066,383.305,0.02315,50.00,0.409,840.512"
"0.066,387.282,0.02335,50.00,0.414,849.235"
"0.067,391.187,0.02355,50.00,0.419,857.797"
"0.067,394.510,0.02374,50.00,0.424,865.083"
"0.068,398.662,0.02394,50.00,0.429,874.188"
"0.068,402.799,0.02414,50.10,0.434,883.261"
"0.069,406.936,0.02433,50.00,0.439,892.331"
"0.069,411.092,0.02453,50.00,0.444,901.444"
"0.070,415.303,0.02473,50.00,0.449,910.678"
"0.071,419.491,0.02492,50.10,0.454,919.862"
"0.071,423.695,0.02512,50.00,0.459,929.081"
"0.072,428.026,0.02532,50.10,0.464,938.578"
"0.072,432.233,0.02552,50.00,0.469,947.802"
"0.073,436.421,0.02572,50.00,0.474,956.986"
"0.073,440.608,0.02591,50.00,0.479,966.168"
"0.074,444.794,0.02611,50.00,0.484,975.348"
"0.074,448.728,0.02630,50.00,0.489,983.972"
"0.075,451.736,0.02650,50.00,0.494,990.569"
"0.076,456.076,0.02670,50.00,0.499,1000.086"
"0.076,460.360,0.02689,50.00,0.504,1009.480"
"0.077,464.662,0.02709,50.00,0.509,1018.913"
"0.077,468.743,0.02728,50.00,0.514,1027.862"
"0.078,473.065,0.02748,50.00,0.519,1037.339"
"0.078,477.342,0.02768,50.00,0.524,1046.719"
"0.079,481.644,0.02788,50.00,0.529,1056.152"
"0.079,485.905,0.02807,50.00,0.534,1065.495"
"0.080,490.117,0.02827,50.00,0.539,1074.731"
"0.081,494.358,0.02846,50.10,0.544,1084.031"
"0.081,498.340,0.02866,50.10,0.549,1092.763"
"0.082,502.257,0.02886,50.10,0.554,1101.351"
"0.082,506.484,0.02905,50.10,0.559,1110.621"
"0.083,510.846,0.02925,50.10,0.564,1120.185"
"0.083,515.240,0.02945,50.00,0.569,1129.821"
"0.084,519.618,0.02965,50.00,0.574,1139.421"
"0.084,523.951,0.02985,50.00,0.579,1148.924"
"0.085,528.320,0.03004,50.00,0.584,1158.504"
"0.086,532.590,0.03024,50.00,0.589,1167.866"
"0.086,536.859,0.03043,50.00,0.594,1177.227"
"0.087,541.294,0.03063,50.00,0.599,1186.952"
"0.087,544.964,0.03083,50.00,0.604,1195.001"
"0.088,549.340,0.03103,50.00,0.609,1204.595"
"0.088,553.790,0.03123,50.00,0.614,1214.355"
"0.089,558.157,0.03142,50.00,0.619,1223.929"
"0.089,562.519,0.03162,50.00,0.624,1233.496"
"0.090,565.942,0.03181,50.00,0.629,1241.000"
"0.091,570.413,0.03202,50.00,0.634,1250.805"
"0.091,574.834,0.03221,50.00,0.639,1260.500"
"0.092,579.184,0.03241,50.00,0.644,1270.038"
"0.092,583.476,0.03260,50.00,0.649,1279.449"
"0.093,587.941,0.03280,50.00,0.654,1289.241"
"0.093,592.380,0.03300,50.00,0.659,1298.973"
"0.094,596.780,0.03319,50.00,0.664,1308.623"
"0.094,601.121,0.03339,50.00,0.669,1318.141"
"0.095,605.450,0.03358,50.00,0.674,1327.634"
"0.096,609.892,0.03378,50.00,0.679,1337.375"
"0.096,614.200,0.03398,50.00,0.684,1346.822"
"0.097,618.604,0.03417,50.00,0.689,1356.478"
"0.097,622.976,0.03437,50.00,0.694,1366.065"
"0.098,627.376,0.03457,50.00,0.699,1375.714"
"0.098,631.785,0.03477,50.00,0.704,1385.383"
"0.099,636.001,0.03496,50.00,0.709,1394.626"
"0.099,640.020,0.03516,50.00,0.714,1403.439"
"0.100,643.688,0.03536,50.00,0.719,1411.483"
"0.101,648.103,0.03556,50.10,0.724,1421.165"
"0.101,652.498,0.03575,50.00,0.729,1430.802"
"0.102,657.015,0.03595,50.00,0.734,1440.707"
"0.102,661.543,0.03614,50.00,0.739,1450.635"
"0.103,666.021,0.03634,50.00,0.744,1460.454"
"0.103,670.443,0.03654,50.00,0.749,1470.151"
"0.104,674.904,0.03673,50.00,0.754,1479.933"
"0.104,679.322,0.03693,50.00,0.759,1489.622"
"0.105,683.739,0.03712,50.10,0.764,1499.306"
"0.106,688.349,0.03732,50.00,0.769,1509.415"
"0.106,692.848,0.03752,50.00,0.774,1519.282"
"0.107,697.342,0.03772,50.00,0.779,1529.137"
"0.107,701.320,0.03792,50.00,0.784,1537.858"
"0.108,705.951,0.03811,50.00,0.789,1548.014"
"0.108,710.472,0.03831,50.00,0.794,1557.928"
"0.109,715.009,0.03851,50.00,0.799,1567.877"
"0.109,719.490,0.03870,50.00,0.804,1577.703"
"0.110,723.938,0.03890,50.00,0.809,1587.455"
"0.111,728.488,0.03909,50.00,0.814,1597.433"
"0.111,732.930,0.03929,50.00,0.819,1607.172"
"0.112,737.391,0.03949,50.00,0.824,1616.955"
"0.112,741.879,0.03968,50.10,0.829,1626.798"
"0.113,746.403,0.03988,50.00,0.834,1636.716"
"0.113,750.957,0.04008,50.00,0.839,1646.703"
"0.114,755.421,0.04028,50.00,0.844,1656.491"
"0.114,759.896,0.04047,50.00,0.849,1666.305"
"0.115,764.417,0.04067,50.00,0.854,1676.218"
"0.116,768.889,0.04087,50.00,0.859,1686.023"
"0.116,773.277,0.04106,50.00,0.864,1695.647"
"0.117,777.827,0.04126,50.00,0.869,1705.624"
"0.117,782.333,0.04146,50.00,0.874,1715.505"
"0.118,786.825,0.04166,50.00,0.879,1725.355"
"0.118,791.301,0.04185,50.00,0.884,1735.169"
"0.119,795.766,0.04205,50.00,0.889,1744.961"
"0.119,800.169,0.04224,50.00,0.894,1754.616"
"0.120,804.602,0.04244,50.00,0.899,1764.336"
"0.121,809.221,0.04264,50.00,0.904,1774.464"
"0.121,813.640,0.04283,50.00,0.909,1784.153"
"0.122,818.169,0.04304,50.00,0.914,1794.086"
"0.122,822.467,0.04323,50.00,0.919,1803.511"
"0.123,826.953,0.04343,50.00,0.924,1813.347"
"0.123,831.453,0.04363,50.00,0.929,1823.214"
"0.124,835.944,0.04382,50.00,0.934,1833.063"
"0.124,840.461,0.04402,50.00,0.939,1842.968"
"0.125,844.878,0.04421,50.00,0.944,1852.652"
"0.126,849.377,0.04441,50.00,0.949,1862.519"
"0.126,853.779,0.04460,50.00,0.954,1872.171"
"0.127,858.273,0.04480,50.00,0.959,1882.026"
"0.127,862.675,0.04500,50.10,0.964,1891.680"
"0.128,867.147,0.04519,50.00,0.969,1901.485"
"0.128,871.044,0.04539,50.10,0.974,1910.031"
"0.129,875.553,0.04559,50.00,0.979,1919.917"
"0.129,880.035,0.04579,50.00,0.984,1929.747"
"0.130,884.594,0.04598,50.00,0.989,1939.743"
"0.131,888.937,0.04618,50.00,0.994,1949.266"
"0.131,893.209,0.04638,50.00,0.999,1958.633"
"0.132,897.733,0.04657,50.00,1.004,1968.553"
"0.132,902.155,0.04677,50.00,1.009,1978.251"
"0.133,906.629,0.04697,50.00,1.014,1988.060"
"0.133,910.413,0.04717,50.10,1.019,1996.358"
"0.134,914.713,0.04736,50.00,1.024,2005.787"
"0.134,919.167,0.04756,50.00,1.029,2015.554"
"0.135,923.644,0.04775,50.00,1.034,2025.372"
"0.136,928.256,0.04795,50.00,1.039,2035.485"
"0.136,932.495,0.04815,50.00,1.044,2044.780"
"0.137,936.764,0.04835,50.00,1.049,2054.141"
"0.137,940.610,0.04854,49.90,1.054,2062.576"
"0.138,945.113,0.04874,49.90,1.059,2072.449"
"0.138,949.664,0.04894,49.90,1.064,2082.429"
"0.139,954.171,0.04913,49.90,1.069,2092.313"
"0.139,958.635,0.04933,49.90,1.074,2102.101"
"0.140,962.687,0.04953,49.90,1.079,2110.985"
"0.141,967.221,0.04973,49.80,1.084,2120.928"
"0.141,971.481,0.04992,49.80,1.089,2130.268"
"0.142,976.004,0.05012,49.80,1.094,2140.188"
"0.142,980.399,0.05031,49.80,1.099,2149.824"
"0.143,984.844,0.05051,49.80,1.104,2159.571"
"0.143,989.371,0.05071,49.80,1.109,2169.498"
"0.144,993.797,0.05091,49.80,1.114,2179.203"
"0.144,998.146,0.05111,49.80,1.119,2188.739"
"0.145,1002.579,0.05130,49.80,1.124,2198.460"
"0.146,1006.979,0.05150,49.80,1.129,2208.110"
"0.146,1011.287,0.05169,49.80,1.134,2217.557"
"0.147,1015.747,0.05189,49.80,1.139,2227.336"
"0.147,1020.153,0.05208,49.80,1.144,2236.998"
"0.148,1024.516,0.05228,49.80,1.149,2246.565"
"0.148,1028.874,0.05248,49.80,1.154,2256.121"
"0.149,1032.796,0.05268,49.80,1.159,2264.720"
"0.149,1037.141,0.05287,49.80,1.164,2274.249"
"0.150,1041.525,0.05307,49.80,1.169,2283.862"
"0.151,1046.045,0.05327,49.70,1.174,2293.773"
"0.151,1050.451,0.05346,49.80,1.179,2303.436"
"0.152,1054.954,0.05366,49.80,1.184,2313.310"
"0.152,1059.229,0.05386,49.80,1.189,2322.683"
"0.153,1063.689,0.05406,49.80,1.194,2332.464"
"0.153,1068.165,0.05425,49.80,1.199,2342.277"
"0.154,1072.504,0.05445,49.80,1.204,2351.792"
"0.154,1076.967,0.05465,49.70,1.209,2361.580"
"0.155,1081.292,0.05484,49.70,1.214,2371.063"
"0.156,1085.593,0.05504,49.70,1.219,2380.495"
"0.156,1089.775,0.05523,49.70,1.224,2389.665"
"0.157,1094.198,0.05543,49.70,1.229,2399.364"
"0.166,1094.976,0.05581,49.80,1.238,2401.070"
"0.184,1095.083,0.05612,49.90,1.246,2401.304"
"0.201,1095.004,0.05629,49.50,1.251,2401.130"
"0.219,1094.967,0.05635,48.20,1.252,2401.050"
"0.237,1095.012,0.05632,46.40,1.251,2401.148"
"0.255,1095.004,0.05611,40.10,1.246,2401.131"
"0.273,1094.972,0.05622,34.70,1.249,2401.061"
"0.290,1094.937,0.05645,30.40,1.255,2400.985"
"0.308,1095.222,0.05709,25.30,1.271,2401.610"
"0.326,1094.519,0.05881,21.80,1.314,2400.068"
"0.344,1095.015,0.05974,17.60,1.338,2401.156"
"0.361,1094.832,0.06098,13.60,1.370,2400.754"
"0.379,1094.920,0.06287,9.50,1.418,2400.948"
"0.397,1095.016,0.06814,5.50,1.551,2401.157"
"0.415,1094.014,0.07848,1.00,1.814,2398.961"
"0.433,1093.445,0.10138,-3.20,2.396,2397.712"
"0.450,1081.240,0.28178,-7.80,6.978,2370.950"
"0.468,1092.958,0.68427,-11.70,17.201,2396.645"
"0.486,1093.347,0.75664,-15.30,19.039,2397.499"
"0.504,1094.332,0.80210,-18.90,20.194,2399.657"
"0.521,1094.432,0.83445,-22.50,21.016,2399.878"
"0.539,1094.554,0.85685,-25.70,21.585,2400.144"
"0.557,1094.443,0.87809,-28.90,22.124,2399.900"
"0.575,1094.094,0.90130,-29.50,22.714,2399.136"
"0.593,1093.975,0.92855,-29.70,23.406,2398.874"
"0.610,1094.635,0.94815,-25.70,23.904,2400.323"
"0.628,1095.396,0.95531,-21.80,24.086,2401.991"
"0.646,1095.235,0.95535,-17.30,24.087,2401.637"
"0.664,1095.102,0.95272,-13.00,24.020,2401.345"
"0.681,1095.087,0.94933,-9.00,23.934,2401.312"
"0.699,1095.145,0.94579,-5.50,23.844,2401.440"
"0.717,1095.116,0.94161,-1.90,23.738,2401.378"
"0.735,1095.162,0.93650,2.00,23.608,2401.477"
"0.753,1095.146,0.92984,6.10,23.439,2401.443"
"0.770,1095.214,0.92177,10.40,23.234,2401.591"
"0.788,1095.330,0.91138,14.70,22.970,2401.846"
"0.806,1095.309,0.89773,18.90,22.623,2401.799"
"0.824,1095.494,0.87952,23.20,22.161,2402.205"
"0.841,1095.952,0.85411,27.50,21.515,2403.209"
"0.859,1096.497,0.80905,31.80,20.371,2404.405"
"0.877,1108.436,0.59326,36.00,14.890,2430.584"
"0.895,1096.673,0.33490,40.50,8.327,2404.792"
"0.913,1095.835,0.28720,44.70,7.116,2402.953"
"0.930,1095.566,0.25956,48.90,6.413,2402.365"
"0.948,1095.216,0.24787,50.50,6.117,2401.596"
"0.966,1095.294,0.23099,50.50,5.688,2401.767"
"0.984,1095.053,0.21789,49.70,5.355,2401.238"
"1.001,1095.012,0.21705,46.30,5.334,2401.148"
"1.019,1095.021,0.21692,42.80,5.331,2401.169"
"1.037,1094.991,0.21772,38.30,5.351,2401.102"
"1.055,1094.881,0.21958,31.10,5.398,2400.862"
"1.073,1094.965,0.22116,27.60,5.438,2401.046"
"1.090,1094.975,0.22271,23.40,5.478,2401.068"
"1.108,1094.906,0.22467,19.70,5.527,2400.917"
"1.126,1094.922,0.22813,16.10,5.615,2400.952"
"1.144,1095.031,0.23339,12.40,5.749,2401.190"
"1.161,1095.165,0.24626,6.40,6.076,2401.485"
"1.179,1095.084,0.26607,1.70,6.579,2401.306"
"1.197,1094.467,0.28348,-1.30,7.021,2399.954"
"1.215,1093.261,0.33343,-4.80,8.290,2397.309"
"1.233,1087.940,0.47424,-8.40,11.866,2385.641"
"1.250,1090.966,0.71564,-12.10,17.998,2392.276"
"1.268,1093.796,0.80719,-15.80,20.323,2398.483"
"1.286,1093.401,0.86085,-19.60,21.686,2397.617"
"1.304,1094.255,0.90122,-23.20,22.712,2399.488"
"1.321,1094.101,0.93296,-27.20,23.518,2399.151"
"1.339,1095.871,0.95931,-30.30,24.187,2403.033"
"1.357,1095.324,0.97386,-30.10,24.557,2401.834"
"1.375,1094.634,0.98572,-27.60,24.858,2400.321"
"1.393,1094.708,0.98817,-23.40,24.920,2400.481"
"1.410,1094.994,0.98790,-19.40,24.913,2401.109"
"1.428,1094.546,0.98423,-15.20,24.820,2400.126"
"1.446,1095.096,0.98000,-10.90,24.713,2401.332"
"1.464,1095.072,0.97558,0.00,24.600,2401.279"
"1.481,1095.052,0.97051,-3.80,24.472,2401.236"
"1.499,1095.173,0.96392,0.00,24.304,2401.502"
"1.517,1095.222,0.95566,4.10,24.094,2401.609"
"1.535,1095.399,0.94432,8.20,23.806,2401.997"
"1.553,1095.449,0.92958,12.60,23.432,2402.106"
"1.570,1095.736,0.90901,16.80,22.910,2402.737"
"1.588,1095.900,0.87766,21.10,22.113,2403.096"
"1.606,1096.492,0.82477,25.40,20.770,2404.394"
"1.624,1101.410,0.69057,29.70,17.361,2415.177"
"1.641,1097.568,0.46756,33.90,11.697,2406.754"
"1.659,1096.434,0.39222,38.20,9.783,2404.267"
"1.677,1095.882,0.35194,42.50,8.760,2403.056"
"1.695,1095.581,0.32610,46.70,8.104,2402.397"
"1.713,1095.090,0.31287,49.80,7.768,2401.321"
"1.730,1095.083,0.30926,50.50,7.676,2401.305"
"1.748,1095.036,0.30730,50.50,7.626,2401.202"
"1.766,1094.992,0.30732,48.00,7.627,2401.105"
"1.784,1094.916,0.30781,44.70,7.639,2400.937"
"1.801,1095.023,0.30863,40.90,7.660,2401.172"
"1.819,1094.971,0.30994,36.40,7.693,2401.058"
"1.837,1094.707,0.31254,29.40,7.759,2400.479"
"1.855,1094.877,0.31492,25.00,7.820,2400.853"
"1.873,1094.888,0.31674,21.30,7.866,2400.877"
"1.890,1095.101,0.32085,16.50,7.970,2401.343"
"1.908,1095.070,0.32584,12.60,8.097,2401.276"
"1.926,1095.236,0.33998,7.80,8.456,2401.641"
"1.944,1094.694,0.35980,3.50,8.960,2400.451"
"1.961,1094.193,0.39043,0.00,9.738,2399.352"
"1.979,1091.383,0.45512,-5.00,11.381,2393.191"
"1.997,1086.478,0.60122,-9.10,15.092,2382.436"
"2.015,1092.339,0.76405,-13.30,19.228,2395.287"
"2.033,1093.791,0.84615,-17.60,21.313,2398.471"
"2.050,1094.204,0.90093,-21.70,22.704,2399.377"
"2.068,1093.956,0.94007,-25.60,23.699,2398.834"
"2.086,1094.632,0.97261,-29.60,24.525,2400.315"
"2.104,1094.184,0.98719,-29.60,24.895,2399.333"
"2.121,1093.918,0.99952,-29.70,25.208,2398.750"
"2.139,1094.800,1.00868,-28.50,25.441,2400.683"
"2.157,1095.640,1.00977,-25.00,25.469,2402.525"
"2.175,1095.456,1.01122,-20.50,25.506,2402.123"
"2.193,1094.592,1.00629,-15.70,25.381,2400.228"
"2.210,1095.098,1.00183,-11.80,25.267,2401.337"
"2.228,1095.167,0.99704,-8.20,25.146,2401.488"
"2.246,1095.127,0.99081,-4.60,24.987,2401.401"
"2.264,1095.326,0.98265,-0.80,24.780,2401.838"
"2.281,1095.290,0.97236,3.40,24.519,2401.758"
"2.299,1095.389,0.95823,7.70,24.160,2401.975"
"2.317,1095.645,0.93843,11.90,23.657,2402.537"
"2.335,1095.945,0.90921,16.20,22.915,2403.194"
"2.353,1097.005,0.85709,20.50,21.591,2405.519"
"2.370,1099.440,0.74451,24.80,18.731,2410.859"
"2.388,1098.578,0.55126,29.10,13.823,2408.969"
"2.406,1096.578,0.46707,33.40,11.684,2404.583"
"2.424,1096.023,0.42071,37.70,10.507,2403.366"
"2.441,1095.656,0.39057,41.80,9.741,2402.561"
"2.459,1095.311,0.37068,46.30,9.236,2401.805"
"2.477,1095.066,0.36157,49.60,9.005,2401.267"
"2.495,1095.008,0.35909,50.60,8.942,2401.140"
"2.513,1095.091,0.35791,50.50,8.912,2401.323"
"2.530,1094.978,0.35786,48.60,8.910,2401.073"
"2.548,1094.992,0.35846,45.50,8.926,2401.104"
"2.566,1094.958,0.35914,42.40,8.943,2401.030"
"2.584,1094.992,0.35998,39.00,8.964,2401.105"
"2.601,1094.981,0.36074,36.30,8.984,2401.081"
"2.619,1094.849,0.36617,28.50,9.121,2400.790"
"2.637,1095.015,0.36526,27.70,9.098,2401.156"
"2.655,1094.991,0.36625,24.40,9.123,2401.103"
"2.673,1095.077,0.37738,17.50,9.406,2401.292"
"2.690,1094.277,0.38339,13.40,9.559,2399.537"
"2.708,1093.233,0.40675,8.00,10.152,2397.248"
"2.726,1095.763,0.42748,3.30,10.679,2402.796"
"2.744,1094.654,0.46231,0.40,11.563,2400.364"
"2.761,1079.942,0.55275,-5.20,13.861,2368.104"
"2.779,1094.842,0.67492,-9.20,16.964,2400.776"
"2.797,1087.786,0.80514,-13.60,20.271,2385.303"
"2.815,1094.925,0.87764,-17.60,22.113,2400.958"
"2.833,1093.229,0.92771,-21.50,23.385,2397.239"
"2.850,1094.794,0.96441,-25.60,24.317,2400.670"
"2.868,1092.925,0.99422,-29.50,25.074,2396.573"
"2.886,1095.174,1.00802,-29.60,25.424,2401.504"
"2.904,1094.800,1.01734,-28.50,25.661,2400.684"
"2.921,1095.681,1.02457,-28.70,25.845,2402.617"
"2.939,1094.575,1.02833,-24.70,25.940,2400.191"
"2.957,1095.565,1.02411,-20.30,25.833,2402.362"
"2.975,1094.693,1.01951,-15.50,25.716,2400.449"
"2.993,1095.084,1.01427,-11.50,25.583,2401.307"
"3.010,1095.122,1.00875,-7.90,25.443,2401.390"
"3.028,1095.172,1.00186,-4.40,25.268,2401.500"
"3.046,1095.278,0.99277,-0.70,25.037,2401.731"
"3.064,1095.351,0.98135,3.60,24.747,2401.892"
"3.081,1095.615,0.96470,7.70,24.324,2402.471"
"3.099,1095.928,0.94068,11.90,23.714,2403.156"
"3.117,1096.379,0.90176,16.20,22.726,2404.146"
"3.135,1097.859,0.82941,20.60,20.888,2407.392"
"3.153,1099.831,0.65985,24.90,16.581,2411.717"
"3.170,1097.249,0.53442,29.10,13.395,2406.055"
"3.188,1096.378,0.47530,33.50,11.893,2404.145"
"3.206,1095.623,0.43749,37.70,10.933,2402.488"
"3.224,1095.399,0.41400,42.00,10.336,2401.998"
"3.241,1095.324,0.39924,46.30,9.961,2401.833"
"3.259,1095.003,0.39238,49.80,9.787,2401.128"
"3.277,1095.014,0.39098,50.60,9.752,2401.154"
"3.295,1094.917,0.39032,50.50,9.735,2400.941"
"3.313,1094.935,0.39069,48.50,9.744,2400.980"
"3.330,1094.914,0.39137,45.40,9.762,2400.934"
"3.348,1094.968,0.39217,42.20,9.782,2401.053"
"3.366,1094.989,0.39307,38.90,9.805,2401.099"
"3.384,1094.949,0.39412,35.70,9.831,2401.011"
"3.401,1094.767,0.39789,29.20,9.927,2400.611"
"3.419,1094.748,0.40123,23.70,10.012,2400.570"
"3.437,1094.308,0.40707,19.30,10.160,2399.604"
"3.455,1094.891,0.41437,14.80,10.346,2400.883"
"3.473,1095.055,0.42329,11.20,10.572,2401.243"
"3.490,1094.789,0.43834,7.70,10.955,2400.660"
"3.508,1091.841,0.46769,2.30,11.700,2394.195"
"3.526,1092.690,0.51269,-2.00,12.843,2396.058"
"3.544,1092.029,0.57726,-6.00,14.483,2394.608"
"3.561,1091.155,0.73127,-10.90,18.395,2392.690"
"3.579,1096.368,0.83777,-15.20,21.100,2404.123"
"3.597,1092.584,0.90235,-19.30,22.740,2395.825"
"3.615,1093.649,0.95148,-23.70,23.988,2398.160"
"3.633,1094.056,0.98574,-27.70,24.859,2399.053"
"3.650,1094.729,1.00914,-29.90,25.453,2400.528"
"3.668,1094.204,1.01800,-29.40,25.678,2399.377"
"3.686,1094.749,1.02595,-29.60,25.880,2400.572"
"3.704,1094.601,1.02920,-26.90,25.963,2400.247"
"3.721,1095.575,1.02748,-22.80,25.919,2402.383"
"3.739,1094.746,1.02448,-18.40,25.842,2400.566"
"3.757,1095.238,1.01943,-14.30,25.714,2401.645"
"3.775,1095.150,1.01370,-10.30,25.569,2401.451"
"3.793,1095.171,1.00745,-6.80,25.410,2401.497"
"3.810,1095.268,0.99929,-3.10,25.203,2401.709"
"3.828,1095.303,0.98850,0.70,24.929,2401.787"
"3.846,1095.466,0.97345,5.00,24.546,2402.144"
"3.864,1095.663,0.95133,9.20,23.985,2402.577"
"3.881,1096.181,0.91847,13.40,23.150,2403.712"
"3.899,1097.073,0.85746,17.70,21.600,2405.667"
"3.917,1099.773,0.71661,22.10,18.023,2411.589"
"3.935,1097.260,0.57646,26.40,14.463,2406.078"
"3.953,1096.016,0.50943,30.60,12.760,2403.349"
"3.970,1095.866,0.47027,35.00,11.766,2403.022"
"3.988,1095.796,0.44324,39.20,11.079,2402.868"
"4.006,1095.319,0.42646,43.40,10.653,2401.821"
"4.024,1095.182,0.41715,47.60,10.416,2401.521"
"4.041,1095.020,0.41372,50.30,10.329,2401.167"
"4.059,1095.116,0.41308,50.70,10.313,2401.378"
"4.077,1094.962,0.41278,50.40,10.305,2401.040"
"4.095,1095.024,0.41345,47.60,10.322,2401.175"
"4.113,1094.988,0.41417,44.50,10.341,2401.096"
"4.130,1094.965,0.41499,41.50,10.361,2401.046"
"4.148,1094.970,0.41578,38.80,10.382,2401.056"
"4.166,1094.897,0.41760,34.70,10.428,2400.898"
"4.184,1094.689,0.42288,27.40,10.562,2400.440"
"4.201,1094.562,0.42730,23.20,10.674,2400.162"
"4.219,1094.400,0.43206,19.10,10.795,2399.806"
"4.237,1095.728,0.44637,13.40,11.159,2402.719"
"4.255,1094.119,0.46069,10.10,11.522,2399.192"
"4.273,1094.805,0.48280,6.40,12.084,2400.696"
"4.290,1096.471,0.52170,0.70,13.072,2404.347"
"4.308,1093.686,0.58180,-2.70,14.598,2398.240"
"4.326,1095.134,0.66585,-6.00,16.733,2401.415"
"4.344,1092.937,0.80207,-10.80,20.193,2396.598"
"4.361,1094.640,0.88167,-14.80,22.215,2400.332"
"4.379,1082.662,0.94075,-19.20,23.716,2374.068"
"4.397,1095.333,0.97593,-24.00,24.609,2401.852"
"4.415,1093.376,1.00717,-27.40,25.403,2397.562"
"4.433,1094.279,1.02529,-29.20,25.863,2399.541"
"4.450,1095.017,1.03378,-29.40,26.079,2401.160"
"4.468,1095.962,1.04125,-30.20,26.269,2403.233"
"4.486,1095.765,1.04225,-26.90,26.294,2402.801"
"4.504,1095.606,1.04062,-22.10,26.252,2402.452"
"4.521,1095.370,1.03555,-18.00,26.124,2401.934"
"4.539,1095.210,1.02999,-13.60,25.983,2401.583"
"4.557,1095.161,1.02421,-9.70,25.836,2401.476"
"4.575,1095.200,1.01755,-6.20,25.667,2401.560"
"4.593,1095.279,1.00794,-2.60,25.422,2401.734"
"4.610,1095.480,0.99568,1.40,25.111,2402.175"
"4.628,1095.500,0.97859,5.60,24.677,2402.218"
"4.646,1095.875,0.95311,9.90,24.030,2403.040"
"4.664,1096.459,0.91279,14.20,23.006,2404.322"
"4.681,1097.502,0.83165,18.50,20.945,2406.608"
"4.699,1098.991,0.66861,22.80,16.804,2409.874"
"4.717,1096.998,0.56274,26.70,14.114,2405.504"
"4.735,1096.357,0.51346,31.30,12.863,2404.099"
"4.753,1095.916,0.47670,35.70,11.929,2403.132"
"4.770,1095.581,0.45465,39.90,11.369,2402.397"
"4.788,1095.369,0.44109,44.10,11.025,2401.931"
"4.806,1095.130,0.43312,48.40,10.822,2401.409"
"4.824,1095.063,0.43093,50.40,10.766,2401.261"
"4.841,1094.923,0.43050,50.60,10.755,2400.954"
"4.859,1094.935,0.43053,49.90,10.756,2400.980"
"4.877,1094.939,0.43127,46.80,10.775,2400.988"
"4.895,1094.997,0.43208,43.60,10.796,2401.117"
"4.913,1094.951,0.43318,40.20,10.824,2401.014"
"4.930,1094.824,0.43533,35.60,10.878,2400.736"
"4.948,1095.410,0.43998,27.80,10.996,2402.022"
"4.966,1095.648,0.44435,23.00,11.107,2402.543"
"4.984,1094.628,0.45109,19.90,11.278,2400.307"
"5.001,1094.375,0.45978,15.80,11.499,2399.753"
"5.019,1094.968,0.47418,11.40,11.865,2401.052"
"5.037,1091.127,0.49391,7.30,12.366,2392.630"
"5.055,1093.814,0.53436,3.20,13.393,2398.523"
"5.073,1095.697,0.58166,-1.90,14.595,2402.651"
"5.090,1079.206,0.65263,-5.20,16.397,2366.488"
"5.108,1085.668,0.77257,-9.30,19.444,2380.659"
"5.126,1087.083,0.87437,-14.80,22.030,2383.762"
"5.144,1091.114,0.93502,-19.10,23.570,2392.601"
"5.161,1091.330,0.97026,-21.80,24.465,2393.074"
"5.179,1094.635,1.00398,-25.90,25.322,2400.323"
"5.197,1094.871,1.02868,-29.80,25.949,2400.841"
"5.215,1094.980,1.03489,-29.80,26.107,2401.079"
"5.233,1094.727,1.04189,-29.30,26.285,2400.524"
"5.250,1094.617,1.04538,-27.30,26.373,2400.282"
"5.268,1095.592,1.04149,-23.20,26.275,2402.421"
"5.286,1095.416,1.03894,-19.10,26.210,2402.034"
"5.304,1095.256,1.03336,-14.80,26.068,2401.683"
"5.321,1095.079,1.02692,-10.60,25.904,2401.296"
"5.339,1095.244,1.01992,-7.00,25.727,2401.658"
"5.357,1095.324,1.01129,-3.40,25.508,2401.834"
"5.375,1095.300,0.99926,0.50,25.202,2401.780"
"5.393,1095.458,0.98335,4.60,24.798,2402.126"
"5.410,1095.705,0.95830,8.80,24.161,2402.668"
"5.428,1096.382,0.91963,13.10,23.179,2404.154"
"5.446,1097.306,0.84563,17.40,21.300,2406.179"
"5.464,1099.855,0.69065,21.60,17.363,2411.769"
"5.481,1096.577,0.58120,26.10,14.583,2404.581"
"5.499,1095.784,0.52967,30.30,13.274,2402.841"
"5.517,1095.812,0.49426,34.50,12.375,2402.904"
"5.535,1095.355,0.47083,38.70,11.780,2401.901"
"5.553,1095.324,0.45665,43.00,11.420,2401.834"
"5.570,1095.109,0.44824,47.30,11.206,2401.362"
"5.588,1094.976,0.44502,50.10,11.124,2401.069"
"5.589,1095.010,0.44499,50.20,11.124,2401.145"