File: input/preprocessor_samples/mts_3cycle.txt
"MTS Start (HH:MM:SS) 09:32:03
"Test Method","3Point_Bending.msm"
"Sample I. D.","Sample34.mss"
"Specimen Number","1"

"Time (s)","Load (N)","Extension (mm)","_COM1 (C)","FlexureStress (MPa)","FlexureStrain (mm/mm)"

0.400,-1.761,-0.003,104.100,-0.132,****
1.000,-2.898,-0.009,104.100,-0.217,****
1.600,-3.838,-0.015,104.100,-0.288,****
2.200,-4.318,-0.021,104.100,-0.324,****
2.800,-5.031,-0.027,104.100,-0.377,****
3.400,-5.525,-0.033,104.100,-0.414,****
4.000,-5.814,-0.039,104.100,-0.436,****
4.600,-6.362,-0.045,104.100,-0.477,****
5.200,-7.196,-0.051,104.100,-0.540,****
5.800,-6.936,-0.057,104.100,-0.520,****
6.400,-7.434,-0.063,104.100,-0.558,****
7.000,-7.681,-0.069,104.100,-0.576,****
7.600,-7.994,-0.075,104.100,-0.600,****
8.200,-8.266,-0.081,104.200,-0.620,****
8.800,-8.198,-0.087,104.200,-0.615,****
9.400,-8.558,-0.093,104.200,-0.642,****
10.000,-8.692,-0.099,104.200,-0.652,****
10.600,-8.715,-0.105,104.200,-0.654,****
11.200,-9.165,-0.111,104.200,-0.687,****
11.800,-8.956,-0.117,104.200,-0.672,****
12.400,-9.010,-0.123,104.200,-0.676,****
13.000,-8.970,-0.129,104.200,-0.673,****
13.600,-9.203,-0.135,104.200,-0.690,****
14.200,-9.328,-0.141,104.200,-0.700,****
14.800,-9.022,-0.147,104.200,-0.677,****
15.400,-9.206,-0.153,104.200,-0.690,****
16.000,-9.238,-0.159,104.200,-0.693,****
16.600,-9.270,-0.165,104.200,-0.695,****
17.200,-9.306,-0.171,104.200,-0.698,****
17.800,-9.730,-0.177,104.200,-0.730,****
18.400,-9.661,-0.183,104.200,-0.725,****
19.000,-9.735,-0.189,104.200,-0.730,****
19.600,-9.926,-0.195,104.200,-0.744,****
20.200,-10.283,-0.201,104.200,-0.771,****
20.800,-10.211,-0.207,104.200,-0.766,****
21.400,-10.103,-0.213,104.200,-0.758,****
22.000,-10.452,-0.219,104.200,-0.784,****
22.600,-10.550,-0.225,104.200,-0.791,****
23.200,-10.948,-0.231,104.200,-0.821,****
23.800,-13.582,-0.237,104.200,-1.019,****
24.400,-18.153,-0.243,104.200,-1.361,****
25.000,-21.297,-0.249,104.200,-1.597,****
25.600,-25.043,-0.255,104.200,-1.878,****
26.200,-32.875,-0.261,104.200,-2.466,****
26.800,-42.333,-0.267,104.200,-3.175,****
27.400,-52.203,-0.273,104.200,-3.915,****
28.000,-62.292,-0.279,104.200,-4.672,****
28.600,-72.564,-0.285,104.200,-5.442,****
29.200,-82.741,-0.291,104.200,-6.206,****
29.800,-93.259,-0.297,104.200,-6.994,****
30.400,-104.126,-0.303,104.200,-7.809,****
31.000,-114.851,-0.309,104.300,-8.614,****
31.600,-125.797,-0.315,104.300,-9.435,****
32.200,-136.910,-0.321,104.300,-10.268,****
32.800,-148.016,-0.327,104.300,-11.101,****
33.400,-158.934,-0.333,104.300,-11.920,****
34.000,-170.438,-0.339,104.300,-12.783,****
34.600,-182.077,-0.345,104.300,-13.656,****
35.200,-193.926,-0.351,104.300,-14.544,****
35.800,-206.058,-0.357,104.300,-15.454,****
36.400,-218.030,-0.363,104.300,-16.352,****
37.000,-230.153,-0.369,104.300,-17.261,****
37.600,-242.977,-0.375,104.300,-18.223,****
38.200,-255.503,-0.381,104.300,-19.163,****
38.800,-268.330,-0.387,104.300,-20.125,****
39.400,-281.601,-0.393,104.300,-21.120,****
40.000,-294.423,-0.399,104.300,-22.082,****
40.600,-307.525,-0.405,104.300,-23.064,****
41.200,-320.778,-0.411,104.300,-24.058,****
41.800,-333.771,-0.417,104.300,-25.033,****
42.400,-347.259,-0.423,104.300,-26.044,****
43.000,-359.974,-0.429,104.300,-26.998,****
43.600,-373.654,-0.435,104.300,-28.024,****
44.200,-387.490,-0.441,104.400,-29.062,****
44.800,-401.652,-0.447,104.400,-30.124,****
45.400,-415.894,-0.453,104.400,-31.192,****
46.000,-430.551,-0.459,104.400,-32.291,****
46.600,-444.948,-0.465,104.400,-33.371,****
47.200,-460.359,-0.471,104.400,-34.527,****
47.800,-475.839,-0.477,104.400,-35.688,****
48.400,-494.736,-0.483,104.400,-37.105,****
49.000,-514.759,-0.489,104.400,-38.607,****
49.600,-536.126,-0.495,104.400,-40.209,****
50.200,-557.533,-0.501,104.400,-41.815,****
50.800,-579.985,-0.507,104.400,-43.499,****
51.400,-602.436,-0.513,104.400,-45.183,****
52.000,-625.189,-0.519,104.400,-46.889,****
52.600,-648.179,-0.525,104.400,-48.613,****
53.050,-666.286,-0.529,104.400,-49.971,****
72.400,-665.529,-0.528,104.500,-49.915,****
91.600,-665.825,-0.527,104.600,-49.937,****
110.800,-666.364,-0.525,104.600,-49.977,****
130.000,-666.006,-0.524,104.100,-49.950,****
149.200,-665.852,-0.522,103.200,-49.939,****
168.400,-665.852,-0.521,102.200,-49.939,****
187.600,-665.895,-0.521,101.200,-49.942,****
206.800,-666.251,-0.521,100.000,-49.969,****
226.000,-665.772,-0.520,98.500,-49.933,****
245.200,-666.134,-0.521,97.300,-49.960,****
264.400,-665.922,-0.521,96.000,-49.944,****
283.600,-665.725,-0.522,94.700,-49.929,****
302.800,-666.297,-0.523,93.400,-49.972,****
322.000,-665.949,-0.524,92.200,-49.946,****
341.200,-665.905,-0.525,90.900,-49.943,****
360.400,-666.592,-0.526,89.500,-49.994,****
379.600,-666.188,-0.528,88.300,-49.964,****
398.800,-665.779,-0.529,87.100,-49.933,****
418.000,-666.133,-0.531,85.500,-49.960,****
437.200,-666.104,-0.533,84.100,-49.958,****
456.400,-666.417,-0.535,83.100,-49.981,****
475.600,-665.902,-0.537,82.100,-49.943,****
494.800,-665.931,-0.540,80.900,-49.945,****
514.000,-666.361,-0.543,78.400,-49.977,****
533.200,-665.813,-0.545,77.900,-49.936,****
552.400,-666.074,-0.548,76.200,-49.956,****
571.600,-666.334,-0.551,75.700,-49.975,****
590.800,-665.684,-0.554,73.300,-49.926,****
610.000,-666.021,-0.557,73.300,-49.952,****
629.200,-665.810,-0.560,71.500,-49.936,****
648.400,-666.709,-0.564,70.100,-50.003,****
667.600,-665.274,-0.567,68.900,-49.896,****
686.800,-666.539,-0.571,68.100,-49.990,****
706.000,-666.046,-0.576,65.600,-49.953,****
725.200,-666.488,-0.580,65.600,-49.987,****
744.400,-665.778,-0.584,64.100,-49.933,****
763.600,-665.843,-0.588,61.900,-49.938,****
782.800,-666.141,-0.593,61.400,-49.961,****
802.000,-665.601,-0.598,60.400,-49.920,****
821.200,-665.940,-0.603,58.700,-49.945,****
840.400,-666.020,-0.608,56.500,-49.951,****
859.600,-665.495,-0.614,55.300,-49.912,****
878.800,-666.716,-0.619,55.300,-50.004,****
898.000,-666.649,-0.625,53.700,-49.999,****
917.200,-665.823,-0.630,52.200,-49.937,****
936.400,-666.467,-0.635,51.400,-49.985,****
955.600,-666.737,-0.642,49.200,-50.005,****
974.800,-665.771,-0.648,47.900,-49.933,****
994.000,-665.828,-0.654,46.300,-49.937,****
1013.200,-666.281,-0.660,45.800,-49.971,****
1032.400,-665.116,-0.666,45.200,-49.884,****
1051.600,-665.140,-0.673,43.700,-49.885,****
1070.800,-665.620,-0.679,41.900,-49.921,****
1090.000,-666.581,-0.686,41.100,-49.994,****
1109.200,-665.376,-0.693,38.900,-49.903,****
1128.400,-665.751,-0.699,38.500,-49.931,****
1147.600,-665.870,-0.707,36.400,-49.940,****
1166.800,-666.424,-0.714,36.000,-49.982,****
1186.000,-665.910,-0.722,34.800,-49.943,****
1205.200,-665.625,-0.728,33.400,-49.922,****
1224.400,-666.439,-0.736,30.700,-49.983,****
1243.600,-665.639,-0.744,30.000,-49.923,****
1262.800,-665.882,-0.752,29.900,-49.941,****
1282.000,-667.144,-0.760,28.400,-50.036,****
1301.200,-666.893,-0.769,26.300,-50.017,****
1320.400,-666.001,-0.778,24.900,-49.950,****
1339.600,-665.951,-0.787,24.800,-49.946,****
1358.800,-665.522,-0.795,23.100,-49.914,****
1378.000,-666.412,-0.805,21.500,-49.981,****
1397.200,-666.177,-0.814,19.700,-49.963,****
1416.400,-665.177,-0.823,20.000,-49.888,****
1435.600,-665.565,-0.833,18.300,-49.917,****
1454.800,-666.402,-0.846,15.400,-49.980,****
1474.000,-665.721,-0.858,14.500,-49.929,****
1493.200,-665.371,-0.871,13.000,-49.903,****
1512.400,-665.624,-0.884,13.000,-49.922,****
1531.600,-664.054,-0.899,10.600,-49.804,****
1550.800,-665.318,-0.913,10.100,-49.899,****
1570.000,-666.394,-0.930,8.100,-49.980,****
1589.200,-665.024,-0.946,8.300,-49.877,****
1608.400,-667.999,-0.972,5.900,-50.100,****
1627.600,-687.639,-0.990,4.700,-51.573,****
1646.800,-652.821,-1.004,3.800,-48.962,****
1666.000,-671.191,-1.037,1.400,-50.339,****
1685.200,-685.409,-1.059,1.300,-51.406,****
1704.400,-664.215,-1.078,-0.300,-49.816,****
1723.600,-653.634,-1.111,-1.100,-49.023,****
1742.800,-682.288,-1.140,-2.600,-51.172,****
1762.000,-659.383,-1.158,-4.400,-49.454,****
1781.200,-653.325,-1.188,-5.100,-48.999,****
1800.400,-688.953,-1.212,0.000,-51.671,****
1819.600,-654.765,-1.228,-7.800,-49.107,****
1838.800,-641.162,-1.252,-9.500,-48.087,****
1858.000,-673.456,-1.278,-9.700,-50.509,****
1877.200,-687.870,-1.293,-11.800,-51.590,****
1896.400,-640.708,-1.312,-12.900,-48.053,****
1915.600,-671.402,-1.330,-15.300,-50.355,****
1934.800,-682.858,-1.355,-15.600,-51.214,****
1954.000,-662.102,-1.374,-16.700,-49.658,****
1973.200,-646.283,-1.391,-17.400,-48.471,****
1992.400,-639.371,-1.408,-18.400,-47.953,****
2011.600,-677.364,-1.436,-21.500,-50.802,****
2030.800,-655.524,-1.449,-21.800,-49.164,****
2050.000,-683.912,-1.478,-22.100,-51.293,****
2069.200,-644.521,-1.493,-23.700,-48.339,****
2088.400,-669.682,-1.522,-26.600,-50.226,****
2107.600,-649.366,-1.533,-26.600,-48.702,****
2126.800,-693.333,-1.559,-28.000,-52.000,****
2146.000,-704.089,-1.584,-29.700,-52.807,****
2165.200,-670.947,-1.603,-30.000,-50.321,****
2184.400,-689.969,-1.616,-31.000,-51.748,****
2203.600,-705.809,-1.638,-30.300,-52.936,****
2222.800,-638.339,-1.652,-29.500,-47.875,****
2242.000,-692.886,-1.669,-29.500,-51.966,****
2261.200,-657.896,-1.687,-31.200,-49.342,****
2280.400,-658.957,-1.695,-30.800,-49.422,****
2299.600,-704.819,-1.715,-29.500,-52.861,****
2318.800,-660.409,-1.728,-30.100,-49.531,****
2338.000,-648.974,-1.734,-29.700,-48.673,****
2357.200,-690.500,-1.754,-31.200,-51.787,****
2376.400,-655.776,-1.768,-29.700,-49.183,****
2395.600,-648.852,-1.772,-30.700,-48.664,****
2414.800,-706.542,-1.793,-30.300,-52.991,****
2434.000,-668.364,-1.804,-29.600,-50.127,****
2453.200,-649.659,-1.813,-29.800,-48.724,****
2472.400,-644.676,-1.824,-30.100,-48.351,****
2491.600,-623.493,-1.832,-31.100,-46.762,****
2510.800,-626.740,-1.840,-29.800,-47.006,****
2530.000,-649.737,-1.849,-29.400,-48.730,****
2549.200,-690.556,-1.865,-30.000,-51.792,****
2568.400,-707.547,-1.879,-31.100,-53.066,****
2587.600,-633.482,-1.879,-30.900,-47.511,****
2606.800,-649.006,-1.888,-29.400,-48.675,****
2626.000,-652.656,-1.898,-29.600,-48.949,****
2645.200,-656.065,-1.908,-30.300,-49.205,****
2664.400,-669.965,-1.919,-31.200,-50.247,****
2683.600,-677.415,-1.928,-29.800,-50.806,****
2702.800,-685.047,-1.938,-31.100,-51.379,****
2722.000,-685.482,-1.946,-31.200,-51.411,****
2741.200,-680.080,-1.953,-30.300,-51.006,****
2760.400,-683.058,-1.961,-29.900,-51.229,****
2779.600,-687.237,-1.968,-28.600,-51.543,****
2798.800,-693.535,-1.974,-27.800,-52.015,****
2818.000,-709.176,-1.981,-26.800,-53.188,****
2837.200,-707.349,-1.985,-25.000,-53.051,****
2856.400,-706.463,-1.989,-23.500,-52.985,****
2875.600,-709.385,-1.991,-22.400,-53.204,****
2894.800,-704.168,-1.994,-20.800,-52.813,****
2914.000,-699.179,-1.996,-19.700,-52.438,****
2933.200,-709.657,-1.995,-18.700,-53.224,****
2952.400,-701.861,-1.994,-17.900,-52.640,****
2971.600,-679.959,-1.992,-16.300,-50.997,****
2990.800,-678.581,-1.991,-14.600,-50.894,****
3010.000,-677.048,-1.990,-12.800,-50.779,****
3029.200,-680.630,-1.990,-12.200,-51.047,****
3048.400,-703.305,-1.992,-10.400,-52.748,****
3067.600,-675.967,-1.993,-9.000,-50.698,****
3086.800,-625.252,-1.983,-8.000,-46.894,****
3106.000,-659.081,-1.981,-6.800,-49.431,****
3125.200,-707.989,-1.986,-5.500,-53.099,****
3144.400,-650.899,-1.982,-4.500,-48.817,****
3163.600,-625.187,-1.974,-3.400,-46.889,****
3182.800,-694.143,-1.976,-2.300,-52.061,****
3202.000,-701.018,-1.978,-1.200,-52.576,****
3221.200,-649.608,-1.970,-0.100,-48.721,****
3240.400,-626.214,-1.963,1.000,-46.966,****
3259.600,-683.665,-1.960,2.000,-51.275,****
3278.800,-702.723,-1.959,3.200,-52.704,****
3298.000,-691.356,-1.953,4.300,-51.852,****
3317.200,-703.256,-1.951,5.500,-52.744,****
3336.400,-706.907,-1.947,6.700,-53.018,****
3355.600,-707.851,-1.943,8.000,-53.089,****
3374.800,-685.129,-1.940,9.300,-51.385,****
3394.000,-644.129,-1.929,10.400,-48.310,****
3413.200,-641.304,-1.918,11.700,-48.098,****
3432.400,-680.331,-1.917,13.100,-51.025,****
3451.600,-699.694,-1.914,14.300,-52.477,****
3470.800,-700.784,-1.912,15.600,-52.559,****
3490.000,-684.904,-1.906,16.900,-51.368,****
3509.200,-657.293,-1.897,18.100,-49.297,****
3528.400,-630.078,-1.886,19.400,-47.256,****
3547.600,-631.464,-1.877,20.700,-47.360,****
3566.800,-637.058,-1.870,22.100,-47.779,****
3586.000,-658.431,-1.866,23.300,-49.382,****
3605.200,-694.714,-1.864,24.600,-52.104,****
3624.400,-705.448,-1.861,26.000,-52.909,****
3643.600,-691.795,-1.855,27.200,-51.885,****
3662.800,-686.290,-1.848,28.400,-51.472,****
3682.000,-665.723,-1.838,29.800,-49.929,****
3701.200,-651.044,-1.828,31.000,-48.828,****
3720.400,-638.901,-1.819,32.300,-47.918,****
3739.600,-628.593,-1.807,33.600,-47.144,****
3758.800,-654.627,-1.798,34.800,-49.097,****
3778.000,-684.260,-1.793,36.200,-51.320,****
3797.200,-691.432,-1.791,37.500,-51.857,****
3816.400,-642.285,-1.776,38.700,-48.171,****
3835.600,-641.903,-1.761,40.000,-48.143,****
3854.800,-683.533,-1.756,41.300,-51.265,****
3874.000,-702.991,-1.749,42.600,-52.724,****
3893.200,-701.990,-1.740,43.800,-52.649,****
3912.400,-683.587,-1.729,45.100,-51.269,****
3931.600,-657.862,-1.713,46.400,-49.340,****
3950.800,-630.859,-1.695,47.700,-47.314,****
3970.000,-640.373,-1.677,49.000,-48.028,****
3989.200,-651.204,-1.662,50.300,-48.840,****
4008.400,-672.217,-1.648,51.500,-50.416,****
4027.600,-681.314,-1.632,52.800,-51.099,****
4046.800,-674.834,-1.611,54.100,-50.613,****
4066.000,-635.351,-1.586,55.300,-47.651,****
4085.200,-676.227,-1.572,56.600,-50.717,****
4104.400,-642.865,-1.536,57.900,-48.215,****
4123.600,-694.941,-1.518,59.200,-52.121,****
4142.800,-635.963,-1.479,60.500,-47.697,****
4162.000,-688.748,-1.447,61.800,-51.656,****
4181.200,-639.796,-1.409,63.100,-47.985,****
4200.400,-698.040,-1.375,64.300,-52.353,****
4219.600,-685.269,-1.331,65.600,-51.395,****
4238.800,-695.961,-1.297,66.900,-52.197,****
4258.000,-637.916,-1.252,68.100,-47.844,****
4277.200,-696.626,-1.225,69.400,-52.247,****
4296.400,-647.503,-1.183,70.700,-48.563,****
4315.600,-675.824,-1.166,72.000,-50.687,****
4334.800,-683.796,-1.138,73.200,-51.285,****
4354.000,-652.468,-1.112,74.600,-48.935,****
4373.200,-639.079,-1.097,75.800,-47.931,****
4392.400,-641.349,-1.084,77.100,-48.101,****
4411.600,-640.618,-1.071,78.400,-48.046,****
4430.800,-639.027,-1.057,79.700,-47.927,****
4450.000,-638.992,-1.044,81.000,-47.924,****
4469.200,-693.979,-1.042,82.300,-52.048,****
4488.400,-681.964,-1.032,83.600,-51.147,****
4507.600,-678.747,-1.021,84.800,-50.906,****
4526.800,-675.725,-1.011,86.100,-50.679,****
4546.000,-672.990,-1.000,87.400,-50.474,****
4565.200,-673.373,-0.990,88.600,-50.503,****
4584.400,-674.297,-0.980,89.900,-50.572,****
4603.600,-672.983,-0.970,91.200,-50.474,****
4622.800,-676.882,-0.961,92.400,-50.766,****
4642.000,-676.134,-0.951,93.800,-50.710,****
4661.200,-690.190,-0.941,95.100,-51.764,****
4680.400,-694.602,-0.930,96.200,-52.095,****
4699.600,-689.433,-0.918,97.700,-51.708,****
4718.800,-657.052,-0.902,98.900,-49.279,****
4738.000,-641.658,-0.896,100.100,-48.124,****
4757.200,-663.361,-0.891,101.400,-49.752,****
4776.400,-660.972,-0.881,102.700,-49.573,****
4795.600,-672.895,-0.874,104.000,-50.467,****
4814.800,-691.952,-0.865,104.800,-51.896,****
4834.000,-692.222,-0.853,105.200,-51.917,****
4853.200,-683.999,-0.843,105.400,-51.300,****
4872.400,-662.470,-0.830,105.600,-49.685,****
4891.600,-638.757,-0.822,105.600,-47.907,****
4910.800,-666.705,-0.822,105.600,-50.003,****
4930.000,-681.912,-0.816,105.600,-51.143,****
4949.200,-693.917,-0.807,105.500,-52.044,****
4968.400,-693.116,-0.801,105.400,-51.984,****
4987.600,-694.191,-0.792,105.300,-52.064,****
5006.800,-678.992,-0.788,105.300,-50.924,****
5026.000,-687.017,-0.781,105.200,-51.526,****
5045.200,-694.459,-0.772,105.200,-52.084,****
5064.400,-691.147,-0.764,105.200,-51.836,****
5083.600,-679.203,-0.755,105.100,-50.940,****
5102.800,-690.676,-0.751,105.100,-51.801,****
5122.000,-693.789,-0.746,105.100,-52.034,****
5141.200,-692.116,-0.742,105.100,-51.909,****
5160.400,-694.306,-0.735,105.000,-52.073,****
5172.600,-669.874,-0.729,105.000,-50.241,****
5173.200,-697.402,-0.734,105.000,-52.305,****
5173.800,-727.626,-0.740,105.000,-54.572,****
5174.400,-756.555,-0.746,105.000,-56.742,****
5175.000,-786.071,-0.752,105.000,-58.955,****
5175.600,-814.415,-0.758,105.000,-61.081,****
5176.200,-843.564,-0.764,105.000,-63.267,****
5176.800,-872.497,-0.770,105.000,-65.437,****
5177.400,-901.692,-0.776,105.100,-67.627,****
5178.000,-930.758,-0.782,105.100,-69.807,****
5178.600,-959.935,-0.788,105.100,-71.995,****
5179.200,-989.088,-0.794,105.100,-74.182,****
5179.800,-1019.197,-0.800,105.100,-76.440,****
5180.400,-1049.524,-0.806,105.000,-78.714,****
5181.000,-1079.346,-0.812,105.000,-80.951,****
5181.600,-1110.288,-0.818,105.100,-83.272,****
5182.200,-1141.743,-0.824,105.100,-85.631,****
5182.800,-1173.203,-0.830,105.100,-87.990,****
5183.400,-1205.337,-0.836,105.100,-90.400,****
5184.000,-1237.923,-0.842,105.100,-92.844,****
5184.600,-1271.510,-0.848,105.100,-95.363,****
5185.200,-1305.831,-0.854,105.100,-97.937,****
5185.630,-1330.129,-0.858,105.100,-99.760,****
5205.000,-1359.646,-0.856,105.100,-101.973,****
5224.200,-1344.514,-0.855,105.100,-100.839,****
5243.400,-1303.863,-0.844,105.100,-97.790,****
5262.600,-1293.418,-0.835,105.100,-97.006,****
5281.800,-1323.468,-0.830,105.100,-99.260,****
5301.000,-1368.606,-0.832,105.100,-102.645,****
5320.200,-1361.039,-0.830,105.100,-102.078,****
5339.400,-1319.942,-0.822,105.100,-98.996,****
5358.600,-1298.496,-0.810,105.000,-97.387,****
5377.800,-1312.939,-0.805,105.100,-98.470,****
5397.000,-1312.934,-0.801,104.500,-98.470,****
5416.200,-1314.911,-0.797,103.000,-98.618,****
5435.400,-1324.692,-0.796,101.600,-99.352,****
5454.600,-1355.705,-0.797,100.000,-101.678,****
5473.800,-1350.276,-0.794,98.700,-101.271,****
5493.000,-1357.738,-0.793,97.600,-101.830,****
5512.200,-1365.409,-0.796,96.200,-102.406,****
5531.400,-1346.911,-0.795,94.900,-101.018,****
5550.600,-1325.890,-0.790,93.700,-99.442,****
5569.800,-1293.109,-0.784,92.400,-96.983,****
5589.000,-1358.322,-0.791,91.100,-101.874,****
5608.200,-1337.761,-0.790,89.800,-100.332,****
5627.400,-1327.604,-0.788,88.500,-99.570,****
5646.600,-1326.896,-0.787,87.200,-99.517,****
5665.800,-1307.334,-0.779,86.000,-98.050,****
5685.000,-1311.154,-0.779,84.500,-98.337,****
5704.200,-1328.399,-0.781,83.500,-99.630,****
5723.400,-1347.017,-0.785,81.800,-101.026,****
5742.600,-1368.265,-0.789,80.500,-102.620,****
5761.800,-1368.686,-0.790,78.900,-102.651,****
5781.000,-1353.186,-0.789,77.900,-101.489,****
5800.200,-1321.964,-0.785,77.100,-99.147,****
5819.400,-1309.596,-0.786,75.500,-98.220,****
5838.600,-1320.282,-0.788,74.400,-99.021,****
5857.800,-1307.999,-0.789,72.900,-98.100,****
5877.000,-1292.443,-0.793,71.400,-96.933,****
5896.200,-1301.883,-0.793,70.900,-97.641,****
5915.400,-1317.448,-0.796,68.900,-98.809,****
5934.600,-1341.461,-0.801,68.300,-100.610,****
5953.800,-1344.847,-0.805,66.900,-100.863,****
5973.000,-1322.133,-0.804,65.300,-99.160,****
5992.200,-1337.576,-0.810,63.100,-100.318,****
6011.400,-1322.153,-0.811,61.900,-99.162,****
6030.600,-1336.235,-0.816,60.800,-100.218,****
6049.800,-1333.032,-0.819,60.600,-99.977,****
6069.000,-1344.076,-0.825,59.100,-100.806,****
6088.200,-1337.411,-0.828,56.500,-100.306,****
6107.400,-1360.444,-0.835,55.300,-102.033,****
6126.600,-1298.440,-0.837,54.600,-97.383,****
6145.800,-1297.107,-0.841,54.300,-97.283,****
6165.000,-1292.963,-0.843,51.700,-96.972,****
6184.200,-1312.155,-0.847,50.000,-98.412,****
6203.400,-1317.983,-0.852,49.600,-98.849,****
6222.600,-1368.727,-0.865,48.600,-102.655,****
6241.800,-1337.881,-0.871,47.700,-100.341,****
6261.000,-1337.265,-0.877,46.500,-100.295,****
6280.200,-1318.067,-0.880,44.400,-98.855,****
6299.400,-1292.416,-0.880,42.800,-96.931,****
6318.600,-1328.188,-0.886,41.400,-99.614,****
6337.800,-1337.446,-0.893,41.100,-100.308,****
6357.000,-1329.671,-0.898,40.200,-99.725,****
6376.200,-1313.855,-0.902,39.000,-98.539,****
6395.400,-1294.503,-0.910,36.100,-97.088,****
6414.600,-1309.439,-0.921,35.000,-98.208,****
6433.800,-1320.975,-0.929,35.200,-99.073,****
6453.000,-1330.824,-0.938,32.700,-99.812,****
6472.200,-1332.284,-0.945,31.900,-99.921,****
6491.400,-1335.889,-0.952,31.500,-100.192,****
6510.600,-1327.709,-0.958,30.000,-99.578,****
6529.800,-1295.017,-0.962,27.000,-97.126,****
6549.000,-1329.734,-0.968,25.900,-99.730,****
6568.200,-1368.050,-0.982,25.100,-102.604,****
6587.400,-1346.123,-0.992,24.800,-100.959,****
6606.600,-1337.774,-1.001,23.700,-100.333,****
6625.800,-1306.608,-1.005,21.600,-97.996,****
6645.000,-1294.680,-1.013,19.400,-97.101,****
6664.200,-1334.939,-1.022,18.200,-100.120,****
6683.400,-1363.244,-1.040,18.300,-102.243,****
6702.600,-1343.681,-1.052,17.400,-100.776,****
6721.800,-1327.606,-1.065,15.700,-99.570,****
6741.000,-1307.615,-1.075,13.200,-98.071,****
6760.200,-1294.057,-1.087,13.600,-97.054,****
6779.400,-1339.103,-1.103,11.800,-100.433,****
6798.600,-1357.389,-1.132,9.100,-101.804,****
6817.800,-1327.092,-1.148,9.100,-99.532,****
6837.000,-1304.913,-1.164,8.600,-97.868,****
6856.200,-1320.734,-1.196,7.100,-99.055,****
6875.400,-1345.823,-1.226,4.100,-100.937,****
6894.600,-1316.986,-1.248,4.700,-98.774,****
6913.800,-1330.120,-1.283,3.200,-99.759,****
6933.000,-1315.607,-1.313,0.400,-98.671,****
6952.200,-1359.244,-1.352,0.600,-101.943,****
6971.400,-1337.990,-1.382,-1.100,-100.349,****
6990.600,-1327.599,-1.428,-2.500,-99.570,****
7009.800,-1346.311,-1.457,0.000,-100.973,****
7029.000,-1298.972,-1.480,-4.800,-97.423,****
7048.200,-1366.011,-1.518,-6.600,-102.451,****
7067.400,-1315.662,-1.537,-7.500,-98.675,****
7086.600,-1301.147,-1.567,-8.400,-97.586,****
7105.800,-1326.922,-1.601,-11.000,-99.519,****
7125.000,-1303.823,-1.624,-11.800,-97.787,****
7144.200,-1323.953,-1.650,-12.000,-99.296,****
7163.400,-1355.098,-1.680,-13.800,-101.632,****
7182.600,-1307.597,-1.705,-14.900,-98.070,****
7201.800,-1358.593,-1.733,-16.600,-101.894,****
7221.000,-1369.214,-1.765,-18.700,-102.691,****
7240.200,-1343.414,-1.789,-18.600,-100.756,****
7259.400,-1335.148,-1.823,-20.300,-100.136,****
7278.600,-1287.860,-1.849,-21.300,-96.590,****
7297.800,-1341.907,-1.887,-23.400,-100.643,****
7317.000,-1314.926,-1.924,-24.200,-98.619,****
7336.200,-1365.803,-1.955,-26.400,-102.435,****
7355.400,-1286.362,-1.980,-27.600,-96.477,****
7374.600,-1323.981,-2.017,-27.200,-99.299,****
7393.800,-1306.910,-2.039,-29.900,-98.018,****
7413.000,-1335.608,-2.078,-29.500,-100.171,****
7432.200,-1305.874,-2.098,-30.000,-97.941,****
7451.400,-1355.794,-2.135,-29.600,-101.685,****
7470.600,-1327.542,-2.150,-30.400,-99.566,****
7489.800,-1322.479,-2.178,-30.700,-99.186,****
7509.000,-1372.397,-2.199,-29.400,-102.930,****
7528.200,-1329.489,-2.215,-30.500,-99.712,****
7547.400,-1286.909,-2.237,-29.600,-96.518,****
7566.600,-1284.420,-2.259,-31.000,-96.331,****
7585.800,-1286.418,-2.275,-29.700,-96.481,****
7605.000,-1286.613,-2.296,-31.100,-96.496,****
7624.200,-1310.232,-2.314,-30.100,-98.267,****
7643.400,-1315.737,-2.336,-29.600,-98.680,****
7662.600,-1287.664,-2.353,-29.900,-96.575,****
7681.800,-1287.746,-2.371,-31.000,-96.581,****
7701.000,-1286.769,-2.387,-30.700,-96.508,****
7720.200,-1289.554,-2.402,-29.600,-96.717,****
7739.400,-1337.521,-2.424,-30.000,-100.314,****
7758.600,-1372.169,-2.435,-30.200,-102.913,****
7777.800,-1299.000,-2.442,-31.200,-97.425,****
7797.000,-1340.790,-2.467,-30.600,-100.559,****
7816.200,-1323.451,-2.471,-29.500,-99.259,****
7835.400,-1352.308,-2.492,-29.500,-101.423,****
7854.600,-1289.031,-2.495,-29.900,-96.677,****
7873.800,-1373.255,-2.516,-31.100,-102.994,****
7893.000,-1310.784,-2.527,-31.000,-98.309,****
7912.200,-1300.495,-2.531,-29.500,-97.537,****
7931.400,-1331.693,-2.546,-29.700,-99.877,****
7950.600,-1370.945,-2.566,-30.500,-102.821,****
7969.800,-1337.743,-2.581,-31.100,-100.331,****
7989.000,-1285.786,-2.583,-29.700,-96.434,****
8008.200,-1333.792,-2.595,-30.500,-100.034,****
8027.400,-1359.876,-2.613,-29.400,-101.991,****
8046.600,-1293.860,-2.614,-28.000,-97.040,****
8065.800,-1326.895,-2.618,-26.600,-99.517,****
8085.000,-1363.840,-2.632,-24.900,-102.288,****
8104.200,-1286.024,-2.627,-24.200,-96.452,****
8123.400,-1367.628,-2.634,-22.600,-102.572,****
8142.600,-1296.323,-2.633,-20.800,-97.224,****
8161.800,-1371.132,-2.638,-20.000,-102.835,****
8181.000,-1300.282,-2.637,-18.700,-97.521,****
8200.200,-1338.566,-2.635,-17.100,-100.392,****
8219.400,-1373.207,-2.640,-15.700,-102.991,****
8238.600,-1340.433,-2.641,-14.700,-100.533,****
8257.800,-1287.934,-2.633,-13.300,-96.595,****
8277.000,-1347.714,-2.633,-12.100,-101.079,****
8296.200,-1372.710,-2.635,-10.600,-102.953,****
8315.400,-1355.844,-2.637,-9.400,-101.688,****
8334.600,-1294.637,-2.627,-8.300,-97.098,****
8353.800,-1318.429,-2.622,0.000,-98.882,****
8373.000,-1352.761,-2.623,0.000,-101.457,****
8392.200,-1352.329,-2.627,-5.100,-101.425,****
8411.400,-1318.262,-2.620,-4.000,-98.870,****
8430.600,-1287.118,-2.611,-2.900,-96.534,****
8449.800,-1292.820,-2.606,-1.900,-96.961,****
8469.000,-1318.700,-2.602,-0.800,-98.903,****
8488.200,-1347.875,-2.601,0.400,-101.091,****
8507.400,-1361.244,-2.599,1.500,-102.093,****
8526.600,-1372.331,-2.597,2.800,-102.925,****
8545.800,-1347.188,-2.594,3.900,-101.039,****
8565.000,-1340.310,-2.588,5.200,-100.523,****
8584.200,-1326.956,-2.581,6.400,-99.522,****
8603.400,-1327.713,-2.575,7.700,-99.579,****
8622.600,-1306.007,-2.566,9.000,-97.950,****
8641.800,-1293.288,-2.555,10.200,-96.997,****
8661.000,-1320.365,-2.549,11.500,-99.027,****
8680.200,-1361.609,-2.548,12.900,-102.121,****
8699.400,-1366.022,-2.541,14.100,-102.452,****
8718.600,-1365.669,-2.534,15.400,-102.425,****
8737.800,-1371.557,-2.528,16.700,-102.867,****
8757.000,-1341.610,-2.524,17.900,-100.621,****
8776.200,-1296.032,-2.506,19.200,-97.202,****
8795.400,-1343.435,-2.503,20.600,-100.758,****
8814.600,-1350.338,-2.503,21.800,-101.275,****
8833.800,-1292.366,-2.485,23.100,-96.927,****
8853.000,-1364.514,-2.484,24.400,-102.339,****
8872.200,-1302.208,-2.475,25.800,-97.666,****
8891.400,-1357.802,-2.468,27.000,-101.835,****
8910.600,-1295.595,-2.457,28.300,-97.170,****
8929.800,-1370.863,-2.452,29.600,-102.815,****
8949.000,-1295.500,-2.435,30.800,-97.162,****
8968.200,-1361.580,-2.436,32.100,-102.119,****
8987.400,-1307.964,-2.415,33.400,-98.097,****
9006.600,-1352.774,-2.416,34.700,-101.458,****
9025.800,-1299.329,-2.394,36.000,-97.450,****
9045.000,-1340.202,-2.394,37.200,-100.515,****
9064.200,-1349.051,-2.377,38.500,-101.179,****
9083.400,-1295.402,-2.364,39.800,-97.155,****
9102.600,-1368.778,-2.355,41.100,-102.658,****
9121.800,-1313.582,-2.341,42.400,-98.519,****
9141.000,-1334.201,-2.323,43.700,-100.065,****
9160.200,-1353.536,-2.317,44.900,-101.515,****
9179.400,-1316.487,-2.297,46.200,-98.737,****
9198.600,-1292.814,-2.275,47.400,-96.961,****
9217.800,-1304.163,-2.254,48.800,-97.812,****
9237.000,-1320.974,-2.234,50.100,-99.073,****
9256.200,-1329.359,-2.212,51.300,-99.702,****
9275.400,-1328.067,-2.187,52.600,-99.605,****
9294.600,-1315.608,-2.158,53.900,-98.671,****
9313.800,-1294.914,-2.130,55.100,-97.119,****
9333.000,-1341.924,-2.105,56.500,-100.644,****
9352.200,-1357.364,-2.065,57.700,-101.802,****
9371.400,-1302.900,-2.018,59.000,-97.717,****
9390.600,-1332.481,-1.984,60.200,-99.936,****
9409.800,-1346.256,-1.931,61.600,-100.969,****
9429.000,-1308.085,-1.879,62.900,-98.106,****
9448.200,-1334.214,-1.822,64.100,-100.066,****
9467.400,-1320.215,-1.767,65.400,-99.016,****
9486.600,-1346.117,-1.701,66.700,-100.959,****
9505.800,-1298.579,-1.636,67.900,-97.393,****
9525.000,-1314.417,-1.569,69.200,-98.581,****
9544.200,-1336.173,-1.510,70.500,-100.213,****
9563.400,-1350.946,-1.456,71.800,-101.321,****
9582.600,-1354.314,-1.412,73.100,-101.574,****
9601.800,-1311.517,-1.359,74.400,-98.364,****
9621.000,-1347.695,-1.335,75.600,-101.077,****
9640.200,-1319.818,-1.294,76.900,-98.986,****
9659.400,-1310.844,-1.275,78.200,-98.313,****
9678.600,-1368.157,-1.257,79.400,-102.612,****
9697.800,-1331.012,-1.234,80.800,-99.826,****
9717.000,-1299.846,-1.217,82.000,-97.488,****
9736.200,-1293.167,-1.205,83.400,-96.988,****
9755.400,-1303.739,-1.194,84.600,-97.780,****
9774.600,-1333.772,-1.186,85.900,-100.033,****
9793.800,-1353.212,-1.176,87.200,-101.491,****
9813.000,-1363.251,-1.163,88.400,-102.244,****
9832.200,-1366.055,-1.151,89.700,-102.454,****
9851.400,-1366.597,-1.140,91.000,-102.495,****
9870.600,-1356.656,-1.130,92.300,-101.749,****
9889.800,-1340.368,-1.119,93.600,-100.528,****
9909.000,-1339.496,-1.108,94.800,-100.462,****
9928.200,-1337.782,-1.098,96.000,-100.334,****
9947.400,-1339.901,-1.088,97.400,-100.493,****
9966.600,-1351.601,-1.078,98.700,-101.370,****
9985.800,-1356.595,-1.068,100.000,-101.745,****
10005.000,-1352.749,-1.052,101.200,-101.456,****
10024.200,-1303.700,-1.037,102.600,-97.778,****
10043.400,-1316.294,-1.033,103.800,-98.722,****
10062.600,-1365.435,-1.027,104.800,-102.408,****
10081.800,-1329.102,-1.010,105.200,-99.683,****
10101.000,-1296.741,-1.003,105.400,-97.256,****
10120.200,-1358.978,-1.001,105.500,-101.923,****
10139.400,-1326.431,-0.983,105.600,-99.482,****
10151.800,-1367.477,-0.986,105.600,-102.561,****
10152.600,-1391.159,-0.991,105.600,-104.337,****
10153.200,-1432.666,-0.997,105.600,-107.450,****
10153.800,-1473.805,-1.003,105.600,-110.535,****
10154.400,-1514.347,-1.009,105.600,-113.576,****
10155.000,-1555.030,-1.015,105.600,-116.627,****
10155.600,-1595.430,-1.020,105.600,-119.657,****
10156.200,-1636.440,-1.026,105.600,-122.733,****
10156.800,-1677.065,-1.032,105.600,-125.780,****
10157.400,-1717.985,-1.038,105.600,-128.849,****
10158.000,-1758.950,-1.044,105.600,-131.921,****
10158.600,-1800.603,-1.050,105.600,-135.045,****
10159.200,-1841.342,-1.056,105.600,-138.101,****
10159.800,-1882.890,-1.062,105.600,-141.217,****
10160.400,-1922.916,-1.068,105.600,-144.219,****
10161.000,-1964.066,-1.074,105.600,-147.305,****
10161.600,-2005.294,-1.080,105.600,-150.397,****
10162.200,-2046.033,-1.086,105.600,-153.453,****
10162.800,-2087.327,-1.092,105.600,-156.550,****
10163.400,-2128.241,-1.098,105.600,-159.618,****
10164.000,-2168.430,-1.104,105.600,-162.632,****
10164.600,-2209.015,-1.110,105.600,-165.676,****
10165.200,-2251.046,-1.116,105.600,-168.828,****
10165.800,-2293.040,-1.122,105.600,-171.978,****
10166.400,-2334.771,-1.128,105.600,-175.108,****
10167.000,-2376.347,-1.134,105.600,-178.226,****
10167.600,-2418.382,-1.140,105.600,-181.379,****
10168.200,-2460.070,-1.146,105.600,-184.505,****
10168.800,-2502.262,-1.152,105.600,-187.670,****
10169.400,-2544.069,-1.158,105.600,-190.805,****
10170.000,-2586.784,-1.164,105.600,-194.009,****
10170.600,-2628.249,-1.170,105.600,-197.119,****
10171.190,-2670.275,-1.176,105.600,-200.271,****
10190.400,-2679.202,-1.169,105.500,-200.940,****
10209.600,-2631.155,-1.159,105.400,-197.337,****
10228.800,-2646.484,-1.152,105.400,-198.486,****
10248.000,-2663.096,-1.146,105.300,-199.732,****
10267.200,-2714.952,-1.146,105.200,-203.621,****
10286.400,-2674.699,-1.141,105.200,-200.602,****
10305.600,-2625.007,-1.128,105.200,-196.875,****
10324.800,-2668.304,-1.121,105.100,-200.123,****
10344.000,-2714.460,-1.121,105.100,-203.584,****
10363.200,-2680.949,-1.117,105.100,-201.071,****
10382.400,-2651.506,-1.108,105.100,-198.863,****
10401.600,-2628.040,-1.098,105.100,-197.103,****
10420.800,-2663.864,-1.097,105.100,-199.790,****
10440.000,-2711.916,-1.093,105.000,-203.394,****
10459.200,-2711.787,-1.085,105.100,-203.384,****
10478.400,-2652.232,-1.072,105.100,-198.917,****
10497.600,-2624.779,-1.069,105.000,-196.858,****
10516.800,-2692.359,-1.073,105.100,-201.927,****
10536.000,-2626.979,-1.058,105.100,-197.023,****
10555.200,-2712.935,-1.061,105.100,-203.470,****
10574.400,-2639.280,-1.052,105.100,-197.946,****
10593.600,-2631.091,-1.046,105.100,-197.332,****
10612.800,-2663.378,-1.038,105.100,-199.753,****
10632.000,-2702.461,-1.043,105.100,-202.685,****
10651.200,-2637.202,-1.033,104.300,-197.790,****
10670.400,-2660.000,-1.025,102.800,-199.500,****
10689.600,-2700.609,-1.027,101.300,-202.546,****
10708.800,-2701.052,-1.030,99.800,-202.579,****
10728.000,-2696.594,-1.028,98.400,-202.245,****
10747.200,-2630.437,-1.018,97.100,-197.283,****
10766.400,-2653.380,-1.012,95.900,-199.004,****
10785.600,-2673.967,-1.013,94.600,-200.548,****
10804.800,-2714.785,-1.018,93.300,-203.609,****
10824.000,-2631.284,-1.009,92.100,-197.346,****
10843.200,-2675.341,-1.010,90.800,-200.651,****
10862.400,-2712.450,-1.014,89.500,-203.434,****
10881.600,-2707.231,-1.017,88.400,-203.042,****
10900.800,-2694.404,-1.018,87.000,-202.080,****
10920.000,-2696.760,-1.018,85.700,-202.257,****
10939.200,-2693.726,-1.018,84.300,-202.029,****
10958.400,-2669.708,-1.016,82.900,-200.228,****
10977.600,-2627.700,-1.011,81.900,-197.078,****
10996.800,-2657.462,-1.010,80.500,-199.310,****
11016.000,-2709.544,-1.017,78.500,-203.216,****
11035.200,-2705.106,-1.022,77.900,-202.883,****
11054.400,-2694.819,-1.024,76.000,-202.111,****
11073.600,-2637.799,-1.014,75.400,-197.835,****
11092.800,-2690.575,-1.027,74.400,-201.793,****
11112.000,-2627.145,-1.020,72.600,-197.036,****
11131.200,-2686.626,-1.024,71.700,-201.497,****
11150.400,-2658.040,-1.030,69.900,-199.353,****
11169.600,-2636.119,-1.025,69.300,-197.709,****
11188.800,-2692.791,-1.032,67.200,-201.959,****
11208.000,-2644.576,-1.036,66.200,-198.343,****
11227.200,-2668.086,-1.034,65.600,-200.106,****
11246.400,-2669.317,-1.045,63.100,-200.199,****
11265.600,-2657.584,-1.040,62.700,-199.319,****
11284.800,-2690.928,-1.055,61.100,-201.820,****
11304.000,-2626.954,-1.051,58.600,-197.022,****
11323.200,-2670.526,-1.054,57.500,-200.289,****
11342.400,-2683.364,-1.066,57.100,-201.252,****
11361.600,-2636.313,-1.060,55.800,-197.723,****
11380.800,-2679.962,-1.074,54.300,-200.997,****
11400.000,-2672.760,-1.071,52.900,-200.457,****
11419.200,-2642.692,-1.079,51.700,-198.202,****
11438.400,-2713.997,-1.086,50.400,-203.550,****
11457.600,-2625.632,-1.086,49.900,-196.922,****
11476.800,-2691.689,-1.100,48.700,-201.877,****
11496.000,-2672.186,-1.096,46.000,-200.414,****
11515.200,-2633.208,-1.104,45.100,-197.491,****
11534.400,-2714.058,-1.113,44.900,-203.554,****
11553.600,-2646.811,-1.110,43.800,-198.511,****
11572.800,-2635.005,-1.121,42.300,-197.625,****
11592.000,-2643.731,-1.129,39.400,-198.280,****
11611.200,-2656.892,-1.137,39.000,-199.267,****
11630.400,-2686.261,-1.147,38.600,-201.470,****
11649.600,-2688.231,-1.154,35.800,-201.617,****
11668.800,-2712.973,-1.159,35.700,-203.473,****
11688.000,-2693.906,-1.162,35.000,-202.043,****
11707.200,-2645.965,-1.163,32.700,-198.447,****
11726.400,-2639.441,-1.176,32.300,-197.958,****
11745.600,-2671.473,-1.188,30.400,-200.360,****
11764.800,-2693.560,-1.199,28.700,-202.017,****
11784.000,-2666.653,-1.197,28.600,-199.999,****
11803.200,-2639.020,-1.203,26.800,-197.927,****
11822.400,-2650.212,-1.220,24.300,-198.766,****
11841.600,-2700.485,-1.234,24.200,-202.536,****
11860.800,-2672.234,-1.234,23.400,-200.418,****
11880.000,-2646.520,-1.248,22.000,-198.489,****
11899.200,-2678.802,-1.257,19.100,-200.910,****
11918.400,-2677.064,-1.276,18.900,-200.780,****
11937.600,-2647.802,-1.279,17.000,-198.585,****
11956.800,-2679.147,-1.301,16.900,-200.936,****
11976.000,-2633.523,-1.310,13.900,-197.514,****
11995.200,-2668.393,-1.333,13.900,-200.129,****
12014.400,-2674.354,-1.350,11.500,-200.577,****
12033.600,-2690.673,-1.381,11.500,-201.800,****
12052.800,-2708.995,-1.398,10.300,-203.175,****
12072.000,-2695.714,-1.422,9.200,-202.179,****
12091.200,-2709.156,-1.456,6.800,-203.187,****
12110.400,-2630.436,-1.485,6.500,-197.283,****
12129.600,-2647.168,-1.522,5.000,-198.538,****
12148.800,-2642.482,-1.571,2.800,-198.186,****
12168.000,-2671.551,-1.610,2.700,-200.366,****
12187.200,-2674.691,-1.650,1.700,-200.602,****
12206.400,-2667.190,-1.695,0.000,-200.039,****
12225.600,-2638.156,-1.736,-2.400,-197.862,****
12244.800,-2685.740,-1.787,-2.500,-201.430,****
12264.000,-2684.841,-1.828,-3.300,-201.363,****
12283.200,-2708.056,-1.878,-6.200,-203.104,****
12302.400,-2675.342,-1.918,-6.700,-200.651,****
12321.600,-2638.550,-1.955,-7.300,-197.891,****
12340.800,-2673.170,-2.006,-8.500,-200.488,****
12360.000,-2677.710,-2.048,-11.300,-200.828,****
12379.200,-2712.429,-2.095,-10.800,-203.432,****
12398.400,-2703.910,-2.151,-13.900,-202.793,****
12417.600,-2625.345,-2.204,-13.600,-196.901,****
12436.800,-2706.152,-2.271,-15.700,-202.961,****
12456.000,-2659.669,-2.316,-16.300,-199.475,****
12475.200,-2643.069,-2.381,-18.700,-198.230,****
12494.400,-2631.585,-2.435,-18.800,-197.369,****
12513.600,-2640.575,-2.496,-21.300,-198.043,****
12532.800,-2636.234,-2.565,-21.300,-197.718,****
12552.000,-2634.128,-2.640,-24.000,-197.560,****
12571.200,-2659.304,-2.709,-24.100,-199.448,****
12590.400,-2697.071,-2.798,-26.400,-202.280,****
12609.600,-2629.901,-2.861,-27.400,-197.243,****
12628.800,-2671.937,-2.938,-29.000,-200.395,****
12648.000,-2661.350,-3.003,-29.200,-199.601,****
12667.200,-2640.712,-3.086,-30.700,-198.053,****
12686.400,-2710.292,-3.147,-30.500,-203.272,****
12705.600,-2651.456,-3.205,-30.200,-198.859,****
12724.800,-2687.006,-3.253,-30.500,-201.525,****
12744.000,-2665.927,-3.308,-30.200,-199.944,****
12763.200,-2648.981,-3.351,-31.000,-198.674,****
12782.400,-2673.134,-3.405,-30.000,-200.485,****
12801.600,-2637.160,-3.445,-29.700,-197.787,****
12820.800,-2653.546,-3.483,-29.700,-199.016,****
12840.000,-2646.458,-3.516,-30.100,-198.484,****
12859.200,-2629.189,-3.545,-31.100,-197.189,****
12878.400,-2623.981,-3.581,-30.200,-196.799,****
12897.600,-2631.482,-3.617,-30.800,-197.361,****
12916.800,-2624.310,-3.648,-30.800,-196.823,****
12936.000,-2635.494,-3.685,-29.600,-197.662,****
12955.200,-2666.921,-3.717,-30.400,-200.019,****
12974.400,-2714.642,-3.742,-30.700,-203.598,****
12993.600,-2651.677,-3.762,-30.600,-198.876,****
13012.800,-2628.381,-3.791,-29.600,-197.129,****
13032.000,-2643.273,-3.817,-30.900,-198.245,****
13051.200,-2674.917,-3.841,-30.600,-200.619,****
13070.400,-2709.870,-3.861,-30.800,-203.240,****
13089.600,-2666.088,-3.872,-30.000,-199.957,****
13108.800,-2630.467,-3.893,-29.700,-197.285,****
13128.000,-2660.083,-3.921,-30.500,-199.506,****
13147.200,-2628.320,-3.935,-30.200,-197.124,****
13166.400,-2623.852,-3.957,-31.100,-196.789,****
13185.600,-2627.044,-3.978,-30.700,-197.028,****
13204.800,-2625.860,-3.994,-29.600,-196.940,****
13224.000,-2660.729,-4.013,-29.500,-199.555,****
13243.200,-2672.688,-4.036,-29.800,-200.452,****
13262.400,-2714.836,-4.062,-30.700,-203.613,****
13281.600,-2648.291,-4.074,-29.000,-198.622,****
13300.800,-2707.994,-4.086,-27.700,-203.100,****
13320.000,-2648.521,-4.094,-25.500,-198.639,****
13339.200,-2638.622,-4.097,-25.300,-197.897,****
13358.400,-2701.269,-4.110,-23.100,-202.595,****
13377.600,-2691.555,-4.119,-21.700,-201.867,****
13396.800,-2647.889,-4.119,-20.600,-198.592,****
13416.000,-2654.157,-4.115,-19.300,-199.062,****
13435.200,-2716.735,-4.125,-18.200,-203.755,****
13454.400,-2682.923,-4.127,-17.100,-201.219,****
13473.600,-2645.016,-4.124,-16.200,-198.376,****
13492.800,-2625.689,-4.119,-14.200,-196.927,****
13512.000,-2678.830,-4.118,-13.000,-200.912,****
13531.200,-2700.452,-4.125,-12.000,-202.534,****
13550.400,-2713.282,-4.121,-10.600,-203.496,****
13569.600,-2700.340,-4.121,-9.300,-202.526,****
13588.800,-2662.182,-4.115,-7.800,-199.664,****
13608.000,-2625.047,-4.107,-6.900,-196.879,****
13627.200,-2660.844,-4.102,-5.900,-199.563,****
13646.400,-2665.107,-4.099,-4.700,-199.883,****
13665.600,-2676.133,-4.097,-3.800,-200.710,****
13684.800,-2676.682,-4.093,-2.800,-200.751,****
13704.000,-2654.440,-4.086,-1.600,-199.083,****
13723.200,-2642.091,-4.081,-0.600,-198.157,****
13742.400,-2627.959,-4.080,0.600,-197.097,****
13761.600,-2629.797,-4.075,1.800,-197.235,****
13780.800,-2627.124,-4.068,2.900,-197.034,****
13800.000,-2627.632,-4.061,4.200,-197.072,****
13819.200,-2635.563,-4.058,5.400,-197.667,****
13838.400,-2634.343,-4.049,6.600,-197.576,****
13857.600,-2637.792,-4.045,7.900,-197.834,****
13876.800,-2653.634,-4.040,9.200,-199.023,****
13896.000,-2691.981,-4.038,10.500,-201.899,****
13915.200,-2691.481,-4.024,11.800,-201.861,****
13934.400,-2643.834,-4.011,13.100,-198.288,****
13953.600,-2713.848,-4.013,14.400,-203.539,****
13972.800,-2649.415,-4.002,15.600,-198.706,****
13992.000,-2638.191,-3.987,16.900,-197.864,****
14011.200,-2661.496,-3.980,18.200,-199.612,****
14030.400,-2671.538,-3.972,19.500,-200.365,****
14049.600,-2669.768,-3.971,20.800,-200.233,****
14068.800,-2686.101,-3.957,22.100,-201.458,****
14088.000,-2701.874,-3.951,23.300,-202.641,****
14107.200,-2670.465,-3.938,24.600,-200.285,****
14126.400,-2642.728,-3.927,25.900,-198.205,****
14145.600,-2627.372,-3.920,27.200,-197.053,****
14164.800,-2683.544,-3.919,28.400,-201.266,****
14184.000,-2700.286,-3.908,29.800,-202.521,****
14203.200,-2632.651,-3.887,31.100,-197.449,****
14222.400,-2704.114,-3.885,32.300,-202.809,****
14241.600,-2678.968,-3.865,33.700,-200.923,****
14260.800,-2658.434,-3.857,34.900,-199.383,****
14280.000,-2707.883,-3.844,36.100,-203.091,****
14299.200,-2628.604,-3.825,37.500,-197.145,****
14318.400,-2671.144,-3.811,38.800,-200.336,****
14337.600,-2697.854,-3.800,40.000,-202.339,****
14356.800,-2698.620,-3.790,41.300,-202.396,****
14376.000,-2698.531,-3.773,42.600,-202.390,****
14395.200,-2678.826,-3.754,43.800,-200.912,****
14414.400,-2675.036,-3.735,45.100,-200.628,****
14433.600,-2727.413,-3.720,46.500,-204.556,****
14452.800,-2653.705,-3.684,47.700,-199.028,****
14472.000,-2691.132,-3.664,49.000,-201.835,****
14491.200,-2688.174,-3.643,50.300,-201.613,****
14510.400,-2706.112,-3.614,51.600,-202.958,****
14529.600,-2710.984,-3.580,52.800,-203.324,****
14548.800,-2687.759,-3.548,54.100,-201.582,****
14568.000,-2658.902,-3.507,55.400,-199.418,****
14587.200,-2700.943,-3.461,56.700,-202.571,****
14606.400,-2635.382,-3.411,58.000,-197.654,****
14625.600,-2644.414,-3.360,59.300,-198.331,****
14644.800,-2655.192,-3.295,60.500,-199.139,****
14664.000,-2669.136,-3.228,61.800,-200.185,****
14683.200,-2698.891,-3.163,63.100,-202.417,****
14702.400,-2642.273,-3.075,64.300,-198.171,****
14721.600,-2673.346,-2.988,65.600,-200.501,****
14740.800,-2638.410,-2.882,66.900,-197.881,****
14760.000,-2666.414,-2.771,68.200,-199.981,****
14779.200,-2640.475,-2.652,69.500,-198.036,****
14798.400,-2685.337,-2.527,70.800,-201.400,****
14817.600,-2696.099,-2.401,72.100,-202.207,****
14836.800,-2665.754,-2.256,73.200,-199.932,****
14856.000,-2695.804,-2.124,74.600,-202.185,****
14875.200,-2665.891,-1.990,75.900,-199.942,****
14894.400,-2685.263,-1.875,77.100,-201.395,****
14913.600,-2658.634,-1.771,78.400,-199.398,****
14932.800,-2713.062,-1.693,79.800,-203.480,****
14952.000,-2708.445,-1.628,80.900,-203.133,****
14971.200,-2669.070,-1.574,82.300,-200.180,****
14990.400,-2663.025,-1.543,83.600,-199.727,****
15009.600,-2674.819,-1.509,84.800,-200.611,****
15028.800,-2691.739,-1.486,86.100,-201.880,****
15048.000,-2642.648,-1.461,87.500,-198.199,****
15067.200,-2707.372,-1.447,88.700,-203.053,****
15086.400,-2677.600,-1.433,90.000,-200.820,****
15105.600,-2635.693,-1.409,91.300,-197.677,****
15124.800,-2707.343,-1.399,92.600,-203.051,****
15144.000,-2637.687,-1.378,93.800,-197.827,****
15163.200,-2664.857,-1.364,95.100,-199.864,****
15182.400,-2713.986,-1.358,96.400,-203.549,****
15201.600,-2637.862,-1.342,97.700,-197.840,****
15220.800,-2701.801,-1.334,98.900,-202.635,****
15240.000,-2668.362,-1.314,100.200,-200.127,****
15259.200,-2642.925,-1.306,101.500,-198.219,****
15278.400,-2703.737,-1.295,102.800,-202.780,****
15297.600,-2642.535,-1.282,104.000,-198.190,****
15316.800,-2703.654,-1.275,104.800,-202.774,****
15336.000,-2645.667,-1.261,105.300,-198.425,****
15355.200,-2654.892,-1.246,105.500,-199.117,****
15374.400,-2645.876,-1.242,105.600,-198.441,****
15393.600,-2641.281,-1.227,105.600,-198.096,****
15412.800,-2680.506,-1.228,105.600,-201.038,****
15432.000,-2665.907,-1.218,105.500,-199.943,****
15451.200,-2641.682,-1.203,105.500,-198.126,****
15470.400,-2704.286,-1.200,105.400,-202.821,****
15489.600,-2635.349,-1.190,105.300,-197.651,****
15508.800,-2682.228,-1.182,105.300,-201.167,****
15528.000,-2688.816,-1.181,105.200,-201.661,****
15547.200,-2649.838,-1.164,105.200,-198.738,****
15566.400,-2711.466,-1.165,105.200,-203.360,****
15585.600,-2632.619,-1.154,105.100,-197.446,****
15604.800,-2675.240,-1.153,105.100,-200.643,****
15624.000,-2706.133,-1.144,105.100,-202.960,****
15643.200,-2635.133,-1.135,105.100,-197.635,****
15662.400,-2703.457,-1.133,105.100,-202.759,****
15681.600,-2681.444,-1.122,105.100,-201.108,****
15700.800,-2645.531,-1.114,105.000,-198.415,****
15720.000,-2634.335,-1.111,105.000,-197.575,****
15739.200,-2689.813,-1.111,105.100,-201.736,****
15758.400,-2697.101,-1.101,105.000,-202.283,****
15777.600,-2653.491,-1.091,105.000,-199.012,****
15780.700,-2653.056,-1.090,105.100,-198.979,****